package magicbook.gtlitecore.common.metatileentities.multi.electric;

import gregtech.api.capability.impl.MultiblockRecipeLogic;
import gregtech.api.metatileentity.MetaTileEntity;
import gregtech.api.metatileentity.interfaces.IGregTechTileEntity;
import gregtech.api.metatileentity.multiblock.IMultiblockPart;
import gregtech.api.metatileentity.multiblock.MultiMapMultiblockController;
import gregtech.api.metatileentity.multiblock.RecipeMapMultiblockController;
import gregtech.api.pattern.BlockPattern;
import gregtech.api.pattern.FactoryBlockPattern;
import gregtech.api.pattern.MultiblockShapeInfo;
import gregtech.api.pattern.PatternMatchContext;
import gregtech.api.recipes.RecipeMap;
import gregtech.client.renderer.ICubeRenderer;
import gregtech.client.renderer.texture.Textures;
import gregtech.common.blocks.BlockComputerCasing;
import gregtech.common.blocks.MetaBlocks;
import gregtech.common.metatileentities.MetaTileEntities;
import magicbook.gtlitecore.api.GTLiteAPI;
import magicbook.gtlitecore.api.block.impl.WrappedIntTier;
import magicbook.gtlitecore.api.recipe.GTLiteRecipeMaps;
import magicbook.gtlitecore.api.utils.GTLiteUtils;
import magicbook.gtlitecore.client.renderer.texture.GTLiteTextures;
import magicbook.gtlitecore.common.blocks.BlockScienceCasing;
import magicbook.gtlitecore.common.blocks.GTLiteMetaBlocks;
import magicbook.gtlitecore.common.metatileentities.GTLiteMetaTileEntities;
import net.minecraft.block.state.IBlockState;
import net.minecraft.client.resources.I18n;
import net.minecraft.item.ItemStack;
import net.minecraft.util.EnumFacing;
import net.minecraft.util.ResourceLocation;
import net.minecraft.world.World;
import net.minecraftforge.fml.relauncher.Side;
import net.minecraftforge.fml.relauncher.SideOnly;
import org.lwjgl.input.Keyboard;

import javax.annotation.Nonnull;
import javax.annotation.Nullable;
import java.util.ArrayList;
import java.util.Comparator;
import java.util.List;

import static gregtech.api.GTValues.MAX;
import static magicbook.gtlitecore.api.pattern.GTLiteTraceabilityPredicate.fusionCoils;
import static magicbook.gtlitecore.api.utils.AnimatedTooltipHandler.*;

public class MetaTileEntitySuprachronalNeutroniumForge extends MultiMapMultiblockController {

    private int casingTier;

    public MetaTileEntitySuprachronalNeutroniumForge(ResourceLocation metaTileEntityId) {
        super(metaTileEntityId, new RecipeMap[]{
                GTLiteRecipeMaps.PLASMA_TRANSMUTATION_RECIPES,
                GTLiteRecipeMaps.PLASMA_FUSION_RECIPES,
                GTLiteRecipeMaps.PLASMA_COLLISION_RECIPES
        });
        this.recipeMapWorkable = new DTNFRecipeLogic(this);
    }

    @Override
    public MetaTileEntity createMetaTileEntity(IGregTechTileEntity tileEntity) {
        return new MetaTileEntitySuprachronalNeutroniumForge(metaTileEntityId);
    }

    @Override
    protected void formStructure(PatternMatchContext context) {
        super.formStructure(context);
        Object type = context.get("FusionCoilTieredStats");
        this.casingTier = GTLiteUtils.getOrDefault(() -> type instanceof WrappedIntTier,
                () -> ((WrappedIntTier) type).getIntTier(), 0);
    }

    @Override
    public void invalidateStructure() {
        super.invalidateStructure();
        this.casingTier = 0;
    }

    @Nonnull
    @Override
    protected BlockPattern createStructurePattern() {
        return FactoryBlockPattern.start()
                .aisle("                                                                     " ,"                                                                     " ,"                                                                     " ,"                                                                     " ,"                                                                     " ,"                                                                     " ,"                                                                     " ,"                                                                     " ,"                                                                     " ,"                                                                     " ,"                                                                     " ,"                                                                     " ,"                                                                     " ,"                                                                     " ,"                                                                     " ,"                                                                     " ,"                                                                     " ,"                                                                     " ,"                                                                     " ,"                                                                     " ,"                                                                     " ,"                                                                     " ,"                                                                     " ,"                                                                     " ,"                                                                     " ,"                                                                     " ,"                                                                     " ,"                                                                     " ,"                                                                     " ,"                                                                     " ,"                                                                     " ,"                                                                     " ,"                                                                     " ,"                                                                     " ,"                                                                     " ,"                                                                     " ,"                             CCC                                     " ,"                              CCCC                                   " ,"                                CC                                   " ,"                                                                     " ,"                                                                     " ,"                                                                     " ,"                                                                     " ,"                                                                     " ,"                                                                     " ,"                                                                     " ,"                                                                     " ,"                                                                     " ,"                                                                     " ,"                                                                     " ,"                                                                     " ,"                                                                     " ,"                                                                     " ,"                                                                     " ,"                                                                     " ,"                                                                     " ,"                                                                     " ,"                                                                     " ,"                                                                     " ,"                                                                     " ,"                                                                     " ,"                                                                     " ,"                                                                     " ,"                                                                     " ,"                                                                     ")
                .aisle("                                                                     " ,"                                                                     " ,"                                                                     " ,"                                                                     " ,"                                                                     " ,"                                                                     " ,"                                                                     " ,"                                                                     " ,"                                                                     " ,"                                                                     " ,"                                                                     " ,"                                                                     " ,"                                                                     " ,"                                                                     " ,"                                                                     " ,"                                                                     " ,"                                                                     " ,"                                                                     " ,"                                                                     " ,"                                                                     " ,"                                                                     " ,"                                                                     " ,"                                                                     " ,"                                                                     " ,"                                                                     " ,"                                                                     " ,"                                                                     " ,"                                                                     " ,"                                                                     " ,"                                                                     " ,"                                                                     " ,"                                                                     " ,"                                                                     " ,"                         CCCC                                        " ,"                         CCCCCC                                      " ,"                          CCCCCCC                                    " ,"                           CCDDDCCC                                  " ,"                            CCDDD CC                                 " ,"                             CCCDDCCC                                " ,"                               CCCCCCC                               " ,"                                CCCCCC                               " ,"                                    C                                " ,"                                                                     " ,"                                                                     " ,"                                                                     " ,"                                                                     " ,"                                                                     " ,"                                                                     " ,"                                                                     " ,"                                                                     " ,"                                                                     " ,"                                                                     " ,"                                                                     " ,"                                                                     " ,"                                                                     " ,"                                                                     " ,"                                                                     " ,"                                                                     " ,"                                                                     " ,"                                                                     " ,"                                                                     " ,"                                                                     " ,"                                                                     " ,"                                                                     " ,"                                                                     ")
                .aisle("                                                                     " ,"                                                                     " ,"                                                                     " ,"                                                                     " ,"                                                                     " ,"                                                                     " ,"                                                                     " ,"                                                                     " ,"                                                                     " ,"                                                                     " ,"                                                                     " ,"                                                                     " ,"                                                                     " ,"                                                                     " ,"                                                                     " ,"                                                                     " ,"                                                                     " ,"                                                                     " ,"                                                                     " ,"                                                                     " ,"                                                                     " ,"                                                                     " ,"                                                                     " ,"                                                                     " ,"                                                                     " ,"                                                                     " ,"                                                                     " ,"                                                                     " ,"                                                                     " ,"                                                                     " ,"                                                                     " ,"                        CC                                           " ,"                       CCCCCC                                        " ,"                       CC DD CC                                      " ,"                        C DDDD C                                     " ,"                        CCDDDDDDCC                                   " ,"                         CCDDDDDDDCC                                 " ,"                           CDDDDDDD C                                " ,"                            CCDDDDDDDCC                              " ,"                              C DDDDDDCC                             " ,"                               CC DDDDCCC                            " ,"                                 CCC CCCC                            " ,"                                    CCCC                             " ,"                                                                     " ,"                                                                     " ,"                                                                     " ,"                                                                     " ,"                                                                     " ,"                                                                     " ,"                                                                     " ,"                                                                     " ,"                                                                     " ,"                                                                     " ,"                                                                     " ,"                                                                     " ,"                                                                     " ,"                                                                     " ,"                                                                     " ,"                                                                     " ,"                                                                     " ,"                                                                     " ,"                                                                     " ,"                                                                     " ,"                                                                     " ,"                                                                     ")
                .aisle("                                                                     " ,"                                                                     " ,"                                                                     " ,"                                                                     " ,"                                                                     " ,"                                                                     " ,"                                         CCCC                        " ,"                                         CCCCCCC                     " ,"                                          CCCCCCC                    " ,"                                            CCCCCCC                  " ,"                                             CCCCCCC                 " ,"                                               CCCCCC                " ,"                                                 CCCC                " ,"                                                   CCC               " ,"                                                                     " ,"                                                                     " ,"                                                                     " ,"                                                                     " ,"                                                                     " ,"                                                                     " ,"                                                                     " ,"                                                                     " ,"                                                                     " ,"                                                                     " ,"                                                                     " ,"                                                                     " ,"                                                                     " ,"                                                                     " ,"                                                                     " ,"                                                                     " ,"                      CCCC                                           " ,"                      CC  CC                                         " ,"                      CDDDD C                                        " ,"                      C DDDDDCC                                      " ,"                       CDDDDDDDCC                                    " ,"                        CDDDDDDD C                                   " ,"                         CDDDDDDDDCC                                 " ,"                          CCDDDDDDDDCC                               " ,"                            C DDDDDDDDCC                             " ,"                             CCDDDDDDDD C                            " ,"                               CCDDDDDDD C                           " ,"                                 CCDDDDD CC                          " ,"                                   CCC  CC                           " ,"                                      CCC                            " ,"                                                                     " ,"                                                                     " ,"                                                                     " ,"                                                                     " ,"                                                                     " ,"                                                                     " ,"                                                                     " ,"                                                                     " ,"                                                                     " ,"                                                                     " ,"                                                                     " ,"                                                                     " ,"                                                                     " ,"                                                                     " ,"                                                                     " ,"                                                                     " ,"                                                                     " ,"                                                                     " ,"                                                                     " ,"                                                                     " ,"                                                                     ")
                .aisle("                                                                     " ,"                                                                     " ,"                                                                     " ,"                                                                     " ,"                                   CCCCCCCCC                         " ,"                                   CCCCCCCCCCCC                      " ,"                                   CCCCCCDDD CCCC                    " ,"                                    CCCCCDDDDDD CCC                  " ,"                                      CCCCDDDDDDDCCC                 " ,"                                        CCCCDDDDDD CC                " ,"                                          CCC DDDDDDCC               " ,"                                            CCCDDDDDDCC              " ,"                                              CCCDDDDCCC             " ,"                                               CCCCDDDCCC            " ,"                                                 CCCCCCCC            " ,"                                                  CCCCCCCC           " ,"                                                    CCCCCC           " ,"                                                      CCCC           " ,"                                                       CCC           " ,"                                                                     " ,"                                                                     " ,"                                                                     " ,"                                                                     " ,"                                                                     " ,"                                                                     " ,"                                                                     " ,"                                                                     " ,"                                                                     " ,"                                                                     " ,"                     CCCC                                            " ,"                    CCDD CC                                          " ,"                    CCDDDD C                                         " ,"                     CDDDDDDC                                        " ,"                     C DDDDDDCC                                      " ,"                      C DDDDDD C                                     " ,"                       CCDDDDDDDCC                                   " ,"                         C DDDDDD CC                                 " ,"                          CCDDDDDDDDCC                               " ,"                            CCDDDDDDDDCC                             " ,"                              C DDDDDDDDCC                           " ,"                               CC DDDDDDDDC                          " ,"                                 CCDDDDDDD C                         " ,"                                   CCDDDDDCC                         " ,"                                     CCCCCCC                         " ,"                                                                     " ,"                                                                     " ,"                                                                     " ,"                                                                     " ,"                                                                     " ,"                                                                     " ,"                                                                     " ,"                                                                     " ,"                                                                     " ,"                                                                     " ,"                                                                     " ,"                                                                     " ,"                                                                     " ,"                                                                     " ,"                                                                     " ,"                                                                     " ,"                                                                     " ,"                                                                     " ,"                                                                     " ,"                                                                     " ,"                                                                     ")
                .aisle("                                                                     " ,"                                                                     " ,"                                   CCCCC                             " ,"                                CCCCCCCCCCCC                         " ,"                               CCCC DDDDDDD CCC                      " ,"                               CCCCDDDDDDDDDDD CC                    " ,"                               CCCCDDDDDDDDDDDDD CC                  " ,"                                 CCC DDDDDDDDDDDDD C                 " ,"                                   CCC DDDDDDDDDDDD C                " ,"                                     CCC DDDDDDDDDDDDCC              " ,"                                        CC DDDDDDDDDDDCC             " ,"                                          CC DDDDDDDDDDCC            " ,"                                            CCDDDDDDDDDDC            " ,"                                              C DDDDDDDD C           " ,"                                               CC DDDDDDDCC          " ,"                                                 C DDDDDDDCC         " ,"                                                  CC DDDDDCC         " ,"                                                    CCDDDDCC         " ,"                                                     CC DDCCC        " ,"                                                      CCCCCCC        " ,"                                                       CCCCCC        " ,"                                                         CCCC        " ,"                                                           C         " ,"                                                                     " ,"                                                                     " ,"                                                                     " ,"                                                                     " ,"                                                                     " ,"                    CCCC                                             " ,"                   CCDD C                                            " ,"                   C DDDDCC                                          " ,"                    CDDDDD C                                         " ,"                    CDDDDDD C                                        " ,"                     CDDDDDDCC                                       " ,"                      C DDDDDCC                                      " ,"                       CC DDD CC                                     " ,"                         CCCCCCCCC                                   " ,"                           CCCCCCCCCC                                " ,"                             CCCCCDD CCCC                            " ,"                               CCCDDDDDD CC                          " ,"                                 CCDDDDDDD C                         " ,"                                  CCDDDDDDD C                        " ,"                                    C DDDDDDC                        " ,"                                     CCCDDD C                        " ,"                                        CCCC                         " ,"                                                                     " ,"                                                                     " ,"                                                                     " ,"                                                                     " ,"                                                                     " ,"                                                                     " ,"                                                                     " ,"                                                                     " ,"                                                                     " ,"                                                                     " ,"                                                                     " ,"                                                                     " ,"                                                                     " ,"                                                                     " ,"                                                                     " ,"                                                                     " ,"                                                                     " ,"                                                                     " ,"                                                                     " ,"                                                                     ")
                .aisle("                                                                     " ,"                                   CC                                " ,"                              CCCCC  CCCCCC                          " ,"                            CCCCDDDDDDDDDD CCC                       " ,"                           CCCCDDDDDDDDDDDDDD CC                     " ,"                           CCCCDDDDDDDDDDDDDDDDDCC                   " ,"                            CCCDDDDDDDDDDDDDDDDDD C                  " ,"                             CCCCDDDDDDDDDDDDDDDDDDCC                " ,"                               CCCC DDDDDDDDDDDDDDDD C               " ,"                                   CCC DDDDDDDDDDDDDDDC              " ,"                                      CCCDDDDDDDDDDDDDDCC            " ,"                                         CCDDDDDDDDDDDDDC            " ,"                                           CCDDDDDDDDDDDDC           " ,"                                             C DDDDDDDDDDDC          " ,"                                              CCDDDDDDDDDD C         " ,"                                                C DDDDDDDDD C        " ,"                                                 CCDDDDDDDDDC        " ,"                                                   CDDDDDDDDCC       " ,"                                                    C DDDDDD C       " ,"                                                     C DDDDDDC       " ,"                                                      C DDDDDCC      " ,"                                                       CCDDDDCC      " ,"                                                        CCC CCC      " ,"                                                         CCCCCC      " ,"                                                          CCCCC      " ,"                                                            C        " ,"                                                                     " ,"                   CCCC                                              " ,"                  CCDD C                                             " ,"                  C DDDDC                                            " ,"                   CDDDDDC                                           " ,"                   CDDDDDDC                                          " ,"                    CDDDDDCC                                         " ,"                     C DDDCC                                         " ,"                      CC CCCC                                        " ,"                        CCCCCC                                       " ,"                                                                     " ,"                                                                     " ,"                                  CCCCC                              " ,"                                  CCCC CCCC                          " ,"                                   CCDDDDDDCC                        " ,"                                    C DDDDDD C                       " ,"                                     C DDDDDDC                       " ,"                                      CCDDDDDC                       " ,"                                        CCCCCC                       " ,"                                                                     " ,"                                                                     " ,"                                                                     " ,"                                                                     " ,"                                                                     " ,"                                                                     " ,"                                                                     " ,"                                                                     " ,"                                                                     " ,"                                                                     " ,"                                                                     " ,"                                                                     " ,"                                                                     " ,"                                                                     " ,"                                                                     " ,"                                                                     " ,"                                                                     " ,"                                                                     " ,"                                                                     " ,"                                                                     ")
                .aisle("                                                                     " ,"                             CCCCCCCCCCC                             " ,"                           CCC DDDDDDDDDCCCC                         " ,"                         CCC DDDDDDDDDDDDDDDCC                       " ,"                        CCCDDDDDDDDDDDDDDDDDDDCC                     " ,"                        CCCDDDDDDDDDDDDDDDDDDDDDCC                   " ,"                        CCCCDDDDDDDDDDDDDDDDDDDDDDCC                 " ,"                         CCCC DDDDDDDDDDDDDDDDDDDDDDC                " ,"                            CCCC DDDDDDDDDDDDDDDDDDDDCC              " ,"                                CCCCCDDDDDDDDDDDDDDDDD C             " ,"                                     CCCDDDDDDDDDDDDDDD C            " ,"                                        CCDDDDDDDDDDDDDDDC           " ,"                                          CC DDDDDDDDDDDD C          " ,"                                            CCDDDDDDDDDDDD C         " ,"                                              CCDDDDDDDDDDDC         " ,"                                                CDDDDDDDDDDDC        " ,"                                                 C DDDDDDDDD C       " ,"                                                  C DDDDDDDDDC       " ,"                                                   C DDDDDDDDDC      " ,"                                                    C DDDDDDDDC      " ,"                                                     C DDDDDDD C     " ,"                                                      C DDDDDD C     " ,"                                                       C DDDDDDC     " ,"                                                        C DDDDDC     " ,"                                                         C DDD C     " ,"                                                          CC CCC     " ,"                   CC                                      CCCCC     " ,"                  C DCC                                     CCCC     " ,"                  CDDDDC                                             " ,"                  CDDDDDC                                            " ,"                  CDDDDD C                                           " ,"                   CDDDDDC                                           " ,"                    CDDD C                                           " ,"                     CCCCC                                           " ,"                        C                                            " ,"                                                                     " ,"                                                                     " ,"                                                                     " ,"                                                                     " ,"                                      CCCCC                          " ,"                                     CCC DDCCC                       " ,"                                     CC DDDDD C                      " ,"                                      C DDDDDDC                      " ,"                                       C DDDDDCC                     " ,"                                        CC DD C                      " ,"                                          CCCC                       " ,"                                                                     " ,"                                                                     " ,"                                                                     " ,"                                                                     " ,"                                                                     " ,"                                                                     " ,"                                                                     " ,"                                                                     " ,"                                                                     " ,"                                                                     " ,"                                                                     " ,"                                                                     " ,"                                                                     " ,"                                                                     " ,"                                                                     " ,"                                                                     " ,"                                                                     " ,"                                                                     " ,"                                                                     ")
                .aisle("                                 C                                   " ,"                           CCCCCC CCCCCCC                            " ,"                         CC DDDDDDDDDDDDDCCC                         " ,"                       CC DDDDDDDDDDDDDDDDDDCC                       " ,"                      CC DDDDDDDDDDDDDDDDDDDDDCCC                    " ,"                      CCDDDDDDDDDDDDDDDDDDDDDDDD C                   " ,"                     CCCDDDDDDDDDDDDDDDDDDDDDDDDDDCC                 " ,"                      CCC DDDDDDDDDDDDDDDDDDDDDDDDDDC                " ,"                       CCCCC  DDDDDDDDDDDDDDDDDDDDDDDCC              " ,"                            CCCCCCCCDDDDDDDDDDDDDDDDDD C             " ,"                                    CCC DDDDDDDDDDDDDDDDC            " ,"                                       CCCDDDDDDDDDDDDDDDC           " ,"                                          CCDDDDDDDDDDDDDDC          " ,"                                            CCDDDDDDDDDDDDDC         " ,"                                              C DDDDDDDDDDDDC        " ,"                                               CCDDDDDDDDDDD C       " ,"                                                 CDDDDDDDDDDDC       " ,"                                                  CDDDDDDDDDDDC      " ,"                                                   CDDDDDDDDDDC      " ,"                                                    CDDDDDDDDDDC     " ,"                                                     CDDDDDDDDDC     " ,"                                                      CDDDDDDDD C    " ,"                                                       CDDDDDDDDC    " ,"                                                       C DDDDDDDC    " ,"                                                        C DDDDDDC    " ,"                                                         CDDDDDDC    " ,"                 CCCCC                                    CDDDDDC    " ,"                 CDDDDC                                   CCDDD C    " ,"                 CDDDDDC                                   CCCCCC    " ,"                 CDDDDDC                                    CCCCC    " ,"                  CDDDD C                                    CCC     " ,"                   CDDDCC                                            " ,"                    CCCCC                                            " ,"                                                                     " ,"                                                                     " ,"                                                                     " ,"                                                                     " ,"                                                                     " ,"                                                                     " ,"                                                                     " ,"                                        CCCCCC                       " ,"                                       CCDDDDDCC                     " ,"                                       CCDDDDDDC                     " ,"                                        C DDDDDC                     " ,"                                         CCDDD C                     " ,"                                           CCCC                      " ,"                                                                     " ,"                                                                     " ,"                                                                     " ,"                                                                     " ,"                                                                     " ,"                                                                     " ,"                                                                     " ,"                                                                     " ,"                                                                     " ,"                                                                     " ,"                                                                     " ,"                                                                     " ,"                                                                     " ,"                                                                     " ,"                                                                     " ,"                                                                     " ,"                                                                     " ,"                                                                     " ,"                                                                     ")
                .aisle("                             CCCCCCC                                 " ,"                         CCCCDDDDDDDCCCCC                            " ,"                       CC DDDDDDDDDDDDDD CCC                         " ,"                     CC DDDDDDDDDDDDDDDDDDD CC                       " ,"                    CC DDDDDDDDDDDDDDDDDDDDDDDCC                     " ,"                    CCDDDDDDDDDDDDDDDDDDDDDDDDDDCC                   " ,"                   CC DDDDDDDDDDDDDDDDDDDDDDDDDDDDCC                 " ,"                   CCCDDDDDDDDDDDDDDDDDDDDDDDDDDDDD C                " ,"                    CCC  DDDDDDDDDDDDDDDDDDDDDDDDDDDDCC              " ,"                      CCCCCCCCCCCCCDDDDDDDDDDDDDDDDDDD C             " ,"                                   CCCCCDDDDDDDDDDDDDDD C            " ,"                                        CCCDDDDDDDDDDDDDDC           " ,"                                           CCDDDDDDDDDDDDDC          " ,"                                             C DDDDDDDDDDDDC         " ,"                                              CCDDDDDDDDDDDDC        " ,"                                                CDDDDDDDDDDD C       " ,"                                                 C DDDDDDDDDDC       " ,"                                                  C DDDDDDDDDDC      " ,"                                                   CDDDDDDDDDD C     " ,"                                                    CDDDDDDDDDDC     " ,"                                                     CDDDDDDDDD C    " ,"                                                      CDDDDDDDDDC    " ,"                                                      C DDDDDDDDC    " ,"                                                       CDDDDDDDDDC   " ,"                BB                                      CDDDDDDDDC   " ,"                BCCCC                                   C DDDDDDDC   " ,"                BCDDDC                                   CDDDDDDDC   " ,"                CDDDDDC                                   CDDDDDDC   " ,"                C DDDDC                                   C DDDDDC   " ,"                 CDDDD C                                   C DDD C   " ,"                  CDDDCC                                    C DDCC   " ,"                   CCCC                                     CCCCCC   " ,"                                                             CCCC    " ,"                                                                     " ,"                                                                     " ,"                                                                     " ,"                                                                     " ,"                                                                     " ,"                                                                     " ,"                                                                     " ,"                                          CCCCC                      " ,"                                         CCDDDDC                     " ,"                                         CDDDDDDC                    " ,"                                         C DDDDDC                    " ,"                                          CDDDDDC                    " ,"                                           CCCCC                     " ,"                                                                     " ,"                                                                     " ,"                                                                     " ,"                                                                     " ,"                                                                     " ,"                                                                     " ,"                                                                     " ,"                                                                     " ,"                                                                     " ,"                                                                     " ,"                                                                     " ,"                                                                     " ,"                                                                     " ,"                                                                     " ,"                                                                     " ,"                                                                     " ,"                                                                     " ,"                                                                     " ,"                                                                     ")
                .aisle("                           CCCCCCCC                                  " ,"                        CCC DDDDDDDCCCCC                             " ,"                     CCCDDDDDDDDDDDDDDD CCC                          " ,"                    C DDDDDDDDDDDDDDDDDDDD CC                        " ,"                   C DDDDDDDDDDDDDDDDDDDDDDDDCC                      " ,"                  CCDDDDDDDDDDDDDDDDDDDDDDDDDDDCC                    " ,"                 CCDDDDDDDDDDDDDDDDDDDDDDDDDDDDDDCC                  " ,"                 CCDDDDDDDDDDDDDDDDDDDDDDDDDDDDDDD C                 " ,"                 CCCDDDDDDDDDDDDDDDDDDDDDDDDDDDDDDDDCC               " ,"                  CCCC  CCCCCCCCCCCC DDDDDDDDDDDDDDDD C              " ,"                     CCC            CCCCCDDDDDDDDDDDDDDCC            " ,"                                         CCCDDDDDDDDDDDD C           " ,"                                            C DDDDDDDDDDD C          " ,"                                             CC DDDDDDDDDD C         " ,"                                               C DDDDDDDDDD C        " ,"                                                CCDDDDDDDDDD C       " ,"                                                  CDDDDDDDDDDC       " ,"                                                   CDDDDDDDDDDC      " ,"                                                   C DDDDDDDDDDC     " ,"                                                    C DDDDDDDDDC     " ,"                                                     CDDDDDDDDDDC    " ,"                                                      CDDDDDDDDDC    " ,"                                                      C DDDDDDDDDC   " ,"                                                       CDDDDDDDDDC   " ,"               BBCCC                                    CDDDDDDDDC   " ,"               BC D C                                   CDDDDDDDDDC  " ,"               BCDDDDC                                   CDDDDDDDDC  " ,"                CDDDDC                                   CDDDDDDDDC  " ,"                CDDDDDC                                   CDDDDDDDC  " ,"                 CDDD C                                   C DDDDDDC  " ,"                  CCCC                                     CDDDDDDC  " ,"                                                           C DDDD C  " ,"                                                            C DDDCC  " ,"                                                             CCCCC   " ,"                                                             CCCCC   " ,"                                                               C     " ,"                                                                     " ,"                                                                     " ,"                                                                     " ,"                                                                     " ,"                                            CCC                      " ,"                                           C DDCC                    " ,"                                          C DDDD C                   " ,"                                          C DDDDDCB                  " ,"                                           CDDDD CB                  " ,"                                            CCCCCBB                  " ,"                                                                     " ,"                                                                     " ,"                                                                     " ,"                                                                     " ,"                                                                     " ,"                                                                     " ,"                                                                     " ,"                                                                     " ,"                                                                     " ,"                                                                     " ,"                                                                     " ,"                                                                     " ,"                                                                     " ,"                                                                     " ,"                                                                     " ,"                                                                     " ,"                                                                     " ,"                                                                     " ,"                                                                     ")
                .aisle("                           CCCCCC                                    " ,"                       CCCCDDDDDDCCCCC                               " ,"                    CCCDDDDDDDDDDDDDD CCC                            " ,"                   C DDDDDDDDDDDDDDDDDDD CCC                         " ,"                 CCDDDDDDDDDDDDDDDDDDDDDDDDCCC                       " ,"                CCDDDDDDDDDDDDDDDDDDDDDDDDDDDCCC                     " ,"                C DDDDDDDDDDDDDDDDDDDDDDDDDDDD CC                    " ,"               CCDDDDDDDDDDDDDDDDDDDDDDDDDDDDDDD CC                  " ,"               CCDDDDDDDDDDDDDDDDDDDDDDDDDDDDDDDDDCCC                " ,"               CCCDDDDDDDDDCCCCCCCCCCCC  DDDDDDDDDDDCC               " ,"                CCCCCCCCCCC            CCCCCDDDDDDDDD CC             " ,"                                           CCC DDDDDDDDCC            " ,"                                             CCCDDDDDDDD C           " ,"                                               CCDDDDDDDD C          " ,"                                                CCDDDDDDDDDC         " ,"                                                 CCDDDDDDDDDC        " ,"                                                  CCDDDDDDDDDC       " ,"                                                   C DDDDDDDD C      " ,"                                                    C DDDDDDDD C     " ,"                                                     CDDDDDDDDDC     " ,"                                                     C DDDDDDDDDC    " ,"                                                      CDDDDDDDDDC    " ,"                                                       CDDDDDDDDDC   " ,"               B                                       CDDDDDDDDDC   " ,"              BBCCCC                                    CDDDDDDDDDC  " ,"               BCDDDC                                   CDDDDDDDDDC  " ,"               CDDDDDC                                   CDDDDDDDDC  " ,"                CDDDDC                                   CDDDDDDDDC  " ,"                CDDDDC                                   C DDDDDDDC  " ,"                 C D C                                    CDDDDDDD C " ,"                  CCC                                     CDDDDDDD C " ,"                                                           CDDDDDD C " ,"                                                           CDDDDDDC  " ,"                                                            CDDDDDC  " ,"                                                            C DDD C  " ,"                                                             CC CCC  " ,"                                                             CCCCC   " ,"                                                               CC    " ,"                                                                     " ,"                                                                     " ,"                                              C                      " ,"                                            CC CCC                   " ,"                                           C DDDDC                   " ,"                                           CDDDDDDC                  " ,"                                           C DDDD CB                 " ,"                                            CCCDCCBB                 " ,"                                               C  BB                 " ,"                                                                     " ,"                                                                     " ,"                                                                     " ,"                                                                     " ,"                                                                     " ,"                                                                     " ,"                                                                     " ,"                                                                     " ,"                                                                     " ,"                                                                     " ,"                                                                     " ,"                                                                     " ,"                                                                     " ,"                                                                     " ,"                                                                     " ,"                                                                     " ,"                                                                     " ,"                                                                     ")
                .aisle("                            CC                                       " ,"                      CCCCCC  CCCCCC                                 " ,"                    CCDDDDDDDDDDDDD CCC                              " ,"                  CCDDDDDDDDDDDDDDDDD CCC                            " ,"                CCDDDDDDDDDDDDDDDDDDDDD CCC                          " ,"               C DDDDDDDDDDDDDDDDDDDDDDDDCCCC                        " ,"               CDDDDDDDDDDDDDDDDDDDDDDDDDDCCCCC                      " ,"              C DDDDDDDDDDDDDDDDDDDDDDDDDCCCCCCCC                    " ,"              CDDDDDDDDDDDDDDDDDD  CCCCCCCCCCCCCCC                   " ,"             CCDDDDDDDDDDDDCCCCCCCC   CCCCCCCCCCCCCC                 " ,"             CCCDDDDDD CCCC                 CCCCCCCCCC               " ,"              CCCCCCCCC                       CCCCCCCCC              " ,"                                                CCCCCCCCC            " ,"                                                 CCCCD CCC           " ,"                                                  CCCDDDDCC          " ,"                                                   CCDDDDD C         " ,"                                                    CCDDDDD C        " ,"                                                    CCDDDDDDDC       " ,"                                                     C DDDDDDDC      " ,"                                                      CDDDDDDD C     " ,"                                                      C DDDDDDD C    " ,"                                                       CDDDDDDDDC    " ,"             BB                                        CDDDDDDDDDC   " ,"             BBBCCC                                     CDDDDDDDDC   " ,"              BC DDC                                    CDDDDDDDD C  " ,"               CDDDDC                                   CDDDDDDDDDC  " ,"               CDDDDC                                    CDDDDDDDDC  " ,"               CDDDD C                                   CDDDDDDDD C " ,"                CDDDC                                    CDDDDDDDDDC " ,"                 CCCC                                     CDDDDDDDDC " ,"                                                          CDDDDDDDDC " ,"                                                          CDDDDDDDDC " ,"                                                           CDDDDDDDC " ,"                                                           CDDDDDDDC " ,"                                                           C DDDDD C " ,"                                                            CDDDDDC  " ,"                                                            C DDD C  " ,"                                                             CCD CC  " ,"                                                             CCCCC   " ,"                                                              CCC    " ,"                                                                     " ,"                                             CCCCC                   " ,"                                            C DDDDC                  " ,"                                            CDDDDDC                  " ,"                                            C DDDDCB                 " ,"                                             CCDDCCBB                " ,"                                               CC  BB                " ,"                                                                     " ,"                                                                     " ,"                                                                     " ,"                                                                     " ,"                                                                     " ,"                                                                     " ,"                                                                     " ,"                                                                     " ,"                                                                     " ,"                                                                     " ,"                                                                     " ,"                                                                     " ,"                                                                     " ,"                                                                     " ,"                                                                     " ,"                                                                     " ,"                                                                     " ,"                                                                     ")
                .aisle("                                                                     " ,"                      CCCCCCCCCCC                                    " ,"                   CCCDDDDDDDDD CCCC                                 " ,"                 CCDDDDDDDDDDDDDDDCCCC                               " ,"                CDDDDDDDDDDDDDDDDDDCCCCC                             " ,"              CCDDDDDDDDDDDDDDDDDDDDCCCCC                            " ,"              CDDDDDDDDDDDDDDDDDDDDCCCCCCC                           " ,"             CDDDDDDDDDDDDDDDDDDDCCCCCCCC                            " ,"            CCDDDDDDDDDDDDDDDDCCCCC                                  " ,"            C DDDDDDDDDDDD CCC                                       " ,"            C DDDDDDDDDCCCC                                          " ,"            CCDDDDDDCCC                                              " ,"            CCCCCCCC                                                 " ,"              CC                                     CC              " ,"                                                     CCCC            " ,"                                                     CCCCCC          " ,"                                                      CCCCCC         " ,"                                                      CCCCCCC        " ,"                                                      CCCDDDCC       " ,"                                                       CCDDDD C      " ,"                                                       CCDDDDD C     " ,"             B                                         CCDDDDDD C    " ,"            BBB                                         CDDDDDDDC    " ,"             B CCCCC                                    CDDDDDDDDC   " ,"               CDDDC                                    C DDDDDDDC   " ,"               CDDDDC                                    CDDDDDDDDC  " ,"               CDDDDC                                    CDDDDDDDDC  " ,"               C DDDC                                    CDDDDDDDD C " ,"                CCCC                                      CDDDDDDDDC " ,"                                                          CDDDDDDDDC " ,"                                                          CDDDDDDDDC " ,"                                                          CDDDDDDDDC " ,"                                                          CDDDDDDDDC " ,"                                                           CDDDDDDDC " ,"                                                           CDDDDDDDC " ,"                                                           CDDDDDDDC " ,"                                                           C DDDDDDC " ,"                                                            CDDDDD C " ,"                                                            C DDD C  " ,"                                                            CC D CC  " ,"                                                             CCCCC   " ,"                                              CCCCC           CCC    " ,"                                             CDDDD C                 " ,"                                             CDDDDDC                 " ,"                                             CDDDDDC                 " ,"                                              C D CBBB               " ,"                                               CCC BBB               " ,"                                                    BB               " ,"                                                                     " ,"                                                                     " ,"                                                                     " ,"                                                                     " ,"                                                                     " ,"                                                                     " ,"                                                                     " ,"                                                                     " ,"                                                                     " ,"                                                                     " ,"                                                                     " ,"                                                                     " ,"                                                                     " ,"                                                                     " ,"                                                                     " ,"                                                                     " ,"                                                                     ")
                .aisle("                                                                     " ,"                       CCCCCC                                        " ,"                   CCCCDDDD  CCC                                     " ,"                 CCDDDDDDDDDDD CCC                                   " ,"               CCDDDDDDDDDDDDDD CCC                                  " ,"              CDDDDDDDDDDDDDDDDDCCCC                                 " ,"             CDDDDDDDDDDDDDDDDDCCCC                                  " ,"            CDDDDDDDDDDDDDDDD CCC                                    " ,"           C DDDDDDDDDDDDDDDCCC                                      " ,"           CDDDDDDDDDDDDD CC                                         " ,"          CCDDDDDDDDDDDCCC                                           " ,"          CCDDDDDDDDDCC                                              " ,"          CC DDDDDCCC                                                " ,"           CCC CCC                                                   " ,"            CCC                                                      " ,"                                                                     " ,"                                                                     " ,"                                                                     " ,"                                                         CCC         " ,"                                                         CCCCC       " ,"                                                         CCCCCC      " ,"            BB                                           CCDD CC     " ,"            BB  CCC                                      CCDDDDCC    " ,"            BB CDD C                                     C DDDDDC    " ,"               CDDDC                                     C DDDDDDC   " ,"               CDDDDC                                    C DDDDDDC   " ,"               CDDDDC                                     CDDDDDDDC  " ,"               CCDDC                                      CDDDDDDDC  " ,"                 CC                                       CDDDDDDDDC " ,"                                                          CDDDDDDDDC " ,"                                                          CDDDDDDDDC " ,"                                                          CDDDDDDDDC " ,"                                                          CDDDDDDDDC " ,"                                                           CDDDDDDDDC" ,"                                                           CDDDDDDD C" ,"                                                           CDDDDDDDC " ,"                                                           CDDDDDDDC " ,"                                                           CDDDDDDDC " ,"                                                           C DDDDDDC " ,"                                                            CDDDDDC  " ,"                                                            CDDDD C  " ,"                                               CCCC         CC D C   " ,"                                              CDDDDC         CCCC    " ,"                                              CDDDDC          CC     " ,"                                              CDDDDC                 " ,"                                              CCDDCC                 " ,"                                                CC   BBB             " ,"                                                     BB              " ,"                                                     B               " ,"                                                                     " ,"                                                                     " ,"                                                                     " ,"                                                                     " ,"                                                                     " ,"                                                                     " ,"                                                                     " ,"                                                                     " ,"                                                                     " ,"                                                                     " ,"                                                                     " ,"                                                                     " ,"                                                                     " ,"                                                                     " ,"                                                                     " ,"                                                                     ")
                .aisle("                                                                     " ,"                                                                     " ,"                   CCCCCCCCCC                                        " ,"                 CC DDDDDD CCCC                                      " ,"               CCDDDDDDDDDDDCCCC                                     " ,"             CCDDDDDDDDDDDDD CCC                                     " ,"            C DDDDDDDDDDDDDDCCC                                      " ,"           C DDDDDDDDDDDDDD CC                                       " ,"          C DDDDDDDDDDDDDD C                                         " ,"          CDDDDDDDDDDDDD CC                                          " ,"         C DDDDDDDDDDDDCC                                            " ,"         C DDDDDDDDDDCC                                              " ,"         C DDDDDDDDCC                                                " ,"         CCDDDDDDCC                                                  " ,"         CCC   CC                                                    " ,"          CCCCC                                                      " ,"                                                                     " ,"                                                                     " ,"                                                                     " ,"                                                                     " ,"           BB                                                        " ,"           BB                                              CCC       " ,"           BB  CCCC                                        CCCC      " ,"               CDDDC                                      CCCCCC     " ,"              CDDDDC                                      CC DDCC    " ,"              CDDDDC                                      CCDDDD C   " ,"               CDDDC                                      C DDDDDC   " ,"                CCCC                                      C DDDDDDC  " ,"                                                          C DDDDDDC  " ,"                                                          C DDDDDDDC " ,"                                                          C DDDDDDDC " ,"                                                          C DDDDDDDC " ,"                                                           CDDDDDDDC " ,"                                                           CDDDDDDDDC" ,"                                                           CDDDDDDDDC" ,"                                                           CDDDDDDDDC" ,"                                                           CDDDDDDDDC" ,"                                                           CDDDDDDDC " ,"                                                           CDDDDDDDC " ,"                                                           CDDDDDDDC " ,"                                                           CDDDDDD C " ,"                                               CCCCC       C DDDDDC  " ,"                                              C DDD C      CCDDDDCC  " ,"                                              CDDDDDC       CC  CC   " ,"                                              C DDDDC       CCCCC    " ,"                                               CCDCC          C      " ,"                                                 C   BBB             " ,"                                                     BBB             " ,"                                                     BB              " ,"                                                                     " ,"                                                                     " ,"                                                                     " ,"                                                                     " ,"                                                                     " ,"                                                                     " ,"                                                                     " ,"                                                                     " ,"                                                                     " ,"                                                                     " ,"                                                                     " ,"                                                                     " ,"                                                                     " ,"                                                                     " ,"                                                                     " ,"                                                                     ")
                .aisle("                                                                     " ,"                                                                     " ,"                                                                     " ,"                 CCCCCCCCCC                                          " ,"               CCDDDDDDDDCCC                                         " ,"             CCDDDDDDDDDDDCCC                                        " ,"            CDDDDDDDDDDDDDCC                                         " ,"           CDDDDDDDDDDDDDCCC                                         " ,"          CDDDDDDDDDDDDD CC                                          " ,"         C DDDDDDDDDDDD C                                            " ,"         CDDDDDDDDDDDDCC                                             " ,"        C DDDDDDDDDD C                                               " ,"        CDDDDDDDDDDCC                                                " ,"        CDDDDDDDD C                                                  " ,"        CDDDDDD CC                                                   " ,"        CCDDD CC                                                     " ,"        CCCCCC                                                       " ,"                                                                     " ,"                                                                     " ,"          BBB                                                        " ,"          BBB                                                        " ,"          BB    CC                                                   " ,"               CDDC                                                  " ,"              CDDDDC                                                 " ,"              CDDDDC                                        CCC      " ,"              CDDDDC                                        CCCCC    " ,"               CDD C                                       CCC CCC   " ,"                CCC                                        CCDDD C   " ,"                                                           C DDDD C  " ,"                                                           CDDDDDDC  " ,"                                                           CDDDDDD C " ,"                                                           CDDDDDDDC " ,"                                                           CDDDDDDDC " ,"                                                           CDDDDDDDC " ,"                                                           CDDDDDDDDC" ,"                                                           CDDDDDDDDC" ,"                                                           CDDDDDDDDC" ,"                                                           CDDDDDDDDC" ,"                                                           CDDDDDDDC " ,"                                                           CDDDDDDDC " ,"                                                           CDDDDDDDC " ,"                                                CCCCC      CDDDDDDDC " ,"                                               CDDDDC      CDDDDDDC  " ,"                                               CDDDDC      CDDDDD C  " ,"                                               CDDDDC      C DDD C   " ,"                                               CC  C       CCC CC    " ,"                                                 CC         CCCC     " ,"                                                     BBBB            " ,"                                                     BBBB            " ,"                                                      B              " ,"                                                                     " ,"                                                                     " ,"                                                                     " ,"                                                                     " ,"                                                                     " ,"                                                                     " ,"                                                                     " ,"                                                                     " ,"                                                                     " ,"                                                                     " ,"                                                                     " ,"                                                                     " ,"                                                                     " ,"                                                                     " ,"                                                                     ")
                .aisle("                                                                     " ,"                                                                     " ,"                                                                     " ,"                   CCCC                                              " ,"               CCCC  CCCC                                            " ,"             CC DDDDDDDCCC                                           " ,"            C DDDDDDDDDCCC                                           " ,"           CDDDDDDDDDDDCC                                            " ,"          CDDDDDDDDDDDDCC                                            " ,"         CDDDDDDDDDDDDCC                                             " ,"        CDDDDDDDDDDDD C                                              " ,"       C DDDDDDDDDDDCC                                               " ,"       CDDDDDDDDDDDC                                                 " ,"       CDDDDDDDDD C                                                  " ,"       CDDDDDDDDCC                                                   " ,"      CCDDDDDDDC                                                     " ,"       C DDDDCC                                                      " ,"       CCCCCC                                                        " ,"        CCCB                                                         " ,"         BBB                                                         " ,"         BBB                                                         " ,"          B    CCCC                                                  " ,"              C DD C                                                 " ,"              CDDDDC                                                 " ,"              CDDDDC                                                 " ,"              C DDDC                                                 " ,"               CCCC                                           C      " ,"                                                             CCCC    " ,"                                                            CCCCCC   " ,"                                                            CCDD C   " ,"                                                            CDDDD C  " ,"                                                           C DDDDDC  " ,"                                                           C DDDDDDC " ,"                                                           CDDDDDDDC " ,"                                                           CDDDDDDDC " ,"                                                           CDDDDDDDC " ,"                                                           CDDDDDDD C" ,"                                                           CDDDDDDDDC" ,"                       C                                  CDDDDDDDDC " ,"                       CCC                                CDDDDDDDDC " ,"                       CCCC                       C       CDDDDDDDDC " ,"                        CCCC                    CCDCC     CDDDDDDDDC " ,"                         CCCCC                 C DDD C    CDDDDDDDDC " ,"                          CCCCCC               CDDDDDC    CDDDDDDDC  " ,"                           CCCCCCCC            C DDDC     CDDDDDD C  " ,"                              CCCCCC            CCCCC     C DDDDDC   " ,"                                CCCCCC                    CCDDD C    " ,"                                                      BBB  CCCCC     " ,"                                                      BBB   CCC      " ,"                                                       BB            " ,"                                                        B            " ,"                                                                     " ,"                                                                     " ,"                                                                     " ,"                                                                     " ,"                                                                     " ,"                                                                     " ,"                                                                     " ,"                                                                     " ,"                                                                     " ,"                                                                     " ,"                                                                     " ,"                                                                     " ,"                                                                     " ,"                                                                     ")
                .aisle("                                                                     " ,"                                                                     " ,"                                                                     " ,"                                                                     " ,"                 CCCC                                                " ,"              CCC  CCCC                                              " ,"            CCDDDDDDDCC                                              " ,"          CCDDDDDDDDDCC                                              " ,"         C DDDDDDDDDDCC                                              " ,"        C DDDDDDDDDDDC                                               " ,"        CDDDDDDDDDDDCC                                               " ,"       CDDDDDDDDDDD C                                                " ,"      C DDDDDDDDDD C                                                 " ,"      CDDDDDDDDDD C                                                  " ,"      CDDDDDDDDD C                                                   " ,"      CDDDDDDDDCC                                                    " ,"     CCDDDDDDDC                                                      " ,"     CCDDDDD C                                                       " ,"      CCDD CC                                                        " ,"      CCCCCB                                                         " ,"        CBB                                                          " ,"               CCCC                                                  " ,"              CDDDDC                                                 " ,"              CDDDDC                                                 " ,"              CDDDDC                                                 " ,"              C DD C                                                 " ,"               CCCC                                                  " ,"                                                                     " ,"                                                                     " ,"                                                              CCC    " ,"                                                             CCCCC   " ,"                                                            CC D CC  " ,"                                                            C DDD C  " ,"                     CC                                     CDDDDD C " ,"                     CC                                    C DDDDDDC " ,"                     CCC                                   CDDDDDDDC " ,"                     CCC                                   CDDDDDDDC " ,"                     CCCC                                  CDDDDDDDC " ,"                     CCDCC                                CDDDDDDDDC " ,"                      CDD C                               CDDDDDDDDC " ,"                      C DD C                      CC      CDDDDDDDDC " ,"                       C DD C                   CCDDC     CDDDDDDDDC " ,"                        C DDDCC                 CDDDDC    CDDDDDDDDC " ,"                         C DDDDCCCCCCCCC        CDDDDC    CDDDDDDDC  " ,"                          CC DDDDD CCCCCC       CDDD C   C DDDDDDDC  " ,"                            CCCDDDD CCCC         CCCC    C DDDDDD C  " ,"                               CCFAAAC                   C DDDDDDC   " ,"                                                         CCDDDDDC    " ,"                                                        BBCCDD C     " ,"                                                        BBCCCCC      " ,"                                                        BB  C        " ,"                                                                     " ,"                                                                     " ,"                                                                     " ,"                                                                     " ,"                                                                     " ,"                                                                     " ,"                                                                     " ,"                                                                     " ,"                                                                     " ,"                                                                     " ,"                                                                     " ,"                                                                     " ,"                                                                     " ,"                                                                     ")
                .aisle("                                                                     " ,"                                                                     " ,"                                                                     " ,"                                                                     " ,"                                                                     " ,"               CCCC                                                  " ,"            CCC  CCCC                                                " ,"           C DDDDDDCC                                                " ,"         CCDDDDDDDDCC                                                " ,"        C DDDDDDDDDCC                                                " ,"       C DDDDDDDDDDC                                                 " ,"       CDDDDDDDDDD C                                                 " ,"      CDDDDDDDDDDDC                                                  " ,"      CDDDDDDDDDDC                                                   " ,"     CDDDDDDDDDDC                                                    " ,"     CDDDDDDDDDC                                                     " ,"     CDDDDDDDDC                                                      " ,"     CDDDDDDDCC                                                      " ,"     CDDDDDDC                                                        " ,"     C DDD C                                                         " ,"     CCC CC     CC                                                   " ,"      CCCC     CDDC                                                  " ,"              CDDDDC                                                 " ,"              CDDDDC                                                 " ,"              CDDDDC                                                 " ,"               C  C                                                  " ,"                CC                                                   " ,"                                                                     " ,"                                                                     " ,"                     CC                                              " ,"                    CCC                                              " ,"                    CCC                                       CCC    " ,"                    CCC                                      CCCCC   " ,"                    CD C                                     CC CCC  " ,"                    CDDC                                    C DDD C  " ,"                    CDDC                                    CDDDDDC  " ,"                    CDDDE                                  C DDDDD C " ,"                     CDDCE                                 CDDDDDDDC " ,"                     CDDDE                                 CDDDDDDDC " ,"                      CDD E                               CDDDDDDDDC " ,"                      C DD EE                     CCC     CDDDDDDDDC " ,"                       C DD EE            CC     CDD C    CDDDDDDDDC " ,"                        C DD EEEEE     CCCCC    CDDDDC   CDDDDDDDDDC " ,"                         CCDDDDCEEEECCC CCC     CDDDDC   CDDDDDDDDDC " ,"                           C DDDDDDDDDDD C      C DDDC   CDDDDDDDDC  " ,"                            CCCDDDDDDDDCC        CCCC    CDDDDDDDDC  " ,"                               CCAAAACC                  CDDDDDDDC   " ,"                                                        C DDDDDDDC   " ,"                                                        CCDDDDDDC    " ,"                                                        BCDDDD C     " ,"                                                        BCCC CC      " ,"                                                          CCCC       " ,"                                                                     " ,"                                                                     " ,"                                                                     " ,"                                                                     " ,"                                                                     " ,"                                                                     " ,"                                                                     " ,"                                                                     " ,"                                                                     " ,"                                                                     " ,"                                                                     " ,"                                                                     " ,"                                                                     ")
