package magicbook.gtlitecore.common.metatileentities.multi.electric;

import gregtech.api.capability.impl.MultiblockRecipeLogic;
import gregtech.api.metatileentity.MetaTileEntity;
import gregtech.api.metatileentity.interfaces.IGregTechTileEntity;
import gregtech.api.metatileentity.multiblock.IMultiblockPart;
import gregtech.api.metatileentity.multiblock.MultiMapMultiblockController;
import gregtech.api.metatileentity.multiblock.RecipeMapMultiblockController;
import gregtech.api.pattern.BlockPattern;
import gregtech.api.pattern.FactoryBlockPattern;
import gregtech.api.pattern.PatternMatchContext;
import gregtech.api.recipes.RecipeMap;
import gregtech.api.util.RelativeDirection;
import gregtech.client.renderer.ICubeRenderer;
import gregtech.client.renderer.texture.Textures;
import gregtech.common.blocks.BlockComputerCasing;
import gregtech.common.blocks.MetaBlocks;
import magicbook.gtlitecore.api.block.impl.WrappedIntTier;
import magicbook.gtlitecore.api.pattern.GTLiteTraceabilityPredicate;
import magicbook.gtlitecore.api.recipe.GTLiteRecipeMaps;
import magicbook.gtlitecore.api.utils.GTLiteUtils;
import magicbook.gtlitecore.client.renderer.texture.GTLiteTextures;
import magicbook.gtlitecore.common.blocks.BlockScienceCasing;
import magicbook.gtlitecore.common.blocks.GTLiteMetaBlocks;
import net.minecraft.block.state.IBlockState;
import net.minecraft.client.resources.I18n;
import net.minecraft.item.ItemStack;
import net.minecraft.util.ResourceLocation;
import net.minecraft.world.World;
import net.minecraftforge.fml.relauncher.Side;
import net.minecraftforge.fml.relauncher.SideOnly;
import org.lwjgl.input.Keyboard;

import javax.annotation.Nonnull;
import javax.annotation.Nullable;
import java.util.List;

public class MetaTileEntityDimensionallyTranscendentNeutroniumForge extends MultiMapMultiblockController {

    private int casingTier;

    public MetaTileEntityDimensionallyTranscendentNeutroniumForge(ResourceLocation metaTileEntityId) {
        super(metaTileEntityId, new RecipeMap[]{
                GTLiteRecipeMaps.PLASMA_TRANSMUTATION_RECIPES,
                GTLiteRecipeMaps.PLASMA_FUSION_RECIPES,
                GTLiteRecipeMaps.PLASMA_COLLISION_RECIPES
        });
        this.recipeMapWorkable = new DTNFRecipeLogic(this);
    }

    @Override
    public MetaTileEntity createMetaTileEntity(IGregTechTileEntity tileEntity) {
        return new MetaTileEntityDimensionallyTranscendentNeutroniumForge(metaTileEntityId);
    }

    @Override
    protected void formStructure(PatternMatchContext context) {
        super.formStructure(context);
        Object type = context.get("FusionCoilTieredStats");
        this.casingTier = GTLiteUtils.getOrDefault(() -> type instanceof WrappedIntTier,
                () -> ((WrappedIntTier) type).getIntTier(), 0);
    }

    @Override
    public void invalidateStructure() {
        super.invalidateStructure();
        this.casingTier = 0;
    }

    @Nonnull
    @Override
    protected BlockPattern createStructurePattern() {
        return FactoryBlockPattern.start(RelativeDirection.RIGHT, RelativeDirection.DOWN, RelativeDirection.FRONT)
                .aisle("                                                                     ", "                                                                     ", "                                                                     ", "                                                                     ", "                                                                     ", "                                                                     ", "                                                                     ", "                                                                     ", "                                                                     ", "                                                                     ", "                                                                     ", "                                                                     ", "                                                                     ", "                                                                     ", "                                                                     ", "                                                                     ", "                                                                     ", "                                                                     ", "                                                                     ", "                                                                     ", "                                                                     ", "                                                                     ", "                                                                     ", "                                                                     ", "                                                                     ", "                                                                     ", "                                   CC                                ", "                                   CCCC                              ", "                                     CCC                             ", "                                                                     ", "                                                                     ", "                                                                     ", "                                                                     ", "                                                                     ", "                                                                     ", "                                                                     ", "                                                                     ", "                                                                     ", "                                                                     ", "                                                                     ", "                                                                     ", "                                                                     ", "                                                                     ", "                                                                     ", "                                                                     ", "                                                                     ", "                                                                     ", "                                                                     ", "                                                                     ", "                                                                     ", "                                                                     ", "                                                                     ", "                                                                     ", "                                                                     ", "                                                                     ", "                                                                     ", "                                                                     ", "                                                                     ", "                                                                     ", "                                                                     ", "                                                                     ", "                                                                     ", "                                                                     ", "                                                                     ", "                                                                     ")
                .aisle("                                                                     ", "                                                                     ", "                                                                     ", "                                                                     ", "                                                                     ", "                                                                     ", "                                                                     ", "                                                                     ", "                                                                     ", "                                                                     ", "                                                                     ", "                                                                     ", "                                                                     ", "                                                                     ", "                                                                     ", "                                                                     ", "                                                                     ", "                                                                     ", "                                                                     ", "                                                                     ", "                                                                     ", "                                                                     ", "                                                                     ", "                                C                                    ", "                               CCCCCC                                ", "                               CCCCCCC                               ", "                                CCCDDCCC                             ", "                                 CC DDDCC                            ", "                                  CCCDDDCC                           ", "                                    CCCCCCC                          ", "                                      CCCCCC                         ", "                                        CCCC                         ", "                                                                     ", "                                                                     ", "                                                                     ", "                                                                     ", "                                                                     ", "                                                                     ", "                                                                     ", "                                                                     ", "                                                                     ", "                                                                     ", "                                                                     ", "                                                                     ", "                                                                     ", "                                                                     ", "                                                                     ", "                                                                     ", "                                                                     ", "                                                                     ", "                                                                     ", "                                                                     ", "                                                                     ", "                                                                     ", "                                                                     ", "                                                                     ", "                                                                     ", "                                                                     ", "                                                                     ", "                                                                     ", "                                                                     ", "                                                                     ", "                                                                     ", "                                                                     ", "                                                                     ")
                .aisle("                                                                     ", "                                                                     ", "                                                                     ", "                                                                     ", "                                                                     ", "                                                                     ", "                                                                     ", "                                                                     ", "                                                                     ", "                                                                     ", "                                                                     ", "                                                                     ", "                                                                     ", "                                                                     ", "                                                                     ", "                                                                     ", "                                                                     ", "                                                                     ", "                                                                     ", "                                                                     ", "                                                                     ", "                                                                     ", "                             CCCC                                    ", "                            CCCC CCC                                 ", "                            CCCDDDD CC                               ", "                             CCDDDDDD C                              ", "                              CCDDDDDDDCC                            ", "                                C DDDDDDDC                           ", "                                 CCDDDDDDDCC                         ", "                                   CCDDDDDDCC                        ", "                                     C DDDD C                        ", "                                      CC DD CC                       ", "                                        CCCCCC                       ", "                                           CC                        ", "                                                                     ", "                                                                     ", "                                                                     ", "                                                                     ", "                                                                     ", "                                                                     ", "                                                                     ", "                                                                     ", "                                                                     ", "                                                                     ", "                                                                     ", "                                                                     ", "                                                                     ", "                                                                     ", "                                                                     ", "                                                                     ", "                                                                     ", "                                                                     ", "                                                                     ", "                                                                     ", "                                                                     ", "                                                                     ", "                                                                     ", "                                                                     ", "                                                                     ", "                                                                     ", "                                                                     ", "                                                                     ", "                                                                     ", "                                                                     ", "                                                                     ")
                .aisle("                                                                     ", "                                                                     ", "                                                                     ", "                                                                     ", "                                                                     ", "                                                                     ", "                                                                     ", "                                                                     ", "                                                                     ", "                                                                     ", "                                                                     ", "                                                                     ", "                                                                     ", "                                                                     ", "                                                                     ", "                                                                     ", "                                                                     ", "                                                                     ", "                                                                     ", "                                                                     ", "                                                                     ", "                            CCC                                      ", "                           CC  CCC                                   ", "                          CC DDDDDCC                                 ", "                           C DDDDDDDCC                               ", "                            C DDDDDDDDCC                             ", "                             CCDDDDDDDD C                            ", "                               CCDDDDDDDDCC                          ", "                                 CCDDDDDDDDC                         ", "                                   C DDDDDDDC                        ", "                                    CCDDDDDDDC                       ", "                                      CCDDDDD C                      ", "                                        C DDDDC                      ", "                                         CC  CC                      ", "                                           CCCC                      ", "                                                                     ", "                                                                     ", "                                                                     ", "                                                                     ", "                                                                     ", "                                                                     ", "                                                                     ", "                                                                     ", "                                                                     ", "                                                                     ", "                                                                     ", "                                                                     ", "                                                                     ", "                                                                     ", "                                                                     ", "                                                                     ", "               CCC                                                   ", "                CCCC                                                 ", "                CCCCCC                                               ", "                 CCCCCCC                                             ", "                  CCCCCCC                                            ", "                    CCCCCCC                                          ", "                     CCCCCCC                                         ", "                        CCCC                                         ", "                                                                     ", "                                                                     ", "                                                                     ", "                                                                     ", "                                                                     ", "                                                                     ")
                .aisle("                                                                     ", "                                                                     ", "                                                                     ", "                                                                     ", "                                                                     ", "                                                                     ", "                                                                     ", "                                                                     ", "                                                                     ", "                                                                     ", "                                                                     ", "                                                                     ", "                                                                     ", "                                                                     ", "                                                                     ", "                                                                     ", "                                                                     ", "                                                                     ", "                                                                     ", "                                                                     ", "                                                                     ", "                         CCCCCCC                                     ", "                         CCDDDDDCC                                   ", "                         C DDDDDDDCC                                 ", "                          CDDDDDDDD CC                               ", "                           CCDDDDDDDD C                              ", "                             CCDDDDDDDDCC                            ", "                               CCDDDDDDDDCC                          ", "                                 CC DDDDDD C                         ", "                                   CCDDDDDDDCC                       ", "                                     C DDDDDD C                      ", "                                      CCDDDDDD C                     ", "                                        CDDDDDDC                     ", "                                         C DDDDCC                    ", "                                          CC DDCC                    ", "                                            CCCC                     ", "                                                                     ", "                                                                     ", "                                                                     ", "                                                                     ", "                                                                     ", "                                                                     ", "                                                                     ", "                                                                     ", "                                                                     ", "                                                                     ", "           CCC                                                       ", "           CCCC                                                      ", "           CCCCCC                                                    ", "           CCCCCCCC                                                  ", "            CCCCCCCC                                                 ", "            CCCDDDCCCC                                               ", "             CCCDDDDCCC                                              ", "              CCDDDDDDCCC                                            ", "               CCDDDDDD CCC                                          ", "                CC DDDDDDCCCC                                        ", "                 CCCDDDDDDDCCCC                                      ", "                  CCC DDDDDDCCCCC                                    ", "                    CCCC DDDCCCCCC                                   ", "                      CCCCCCCCCCCC                                   ", "                         CCCCCCCCC                                   ", "                                                                     ", "                                                                     ", "                                                                     ", "                                                                     ")
                .aisle("                                                                     ", "                                                                     ", "                                                                     ", "                                                                     ", "                                                                     ", "                                                                     ", "                                                                     ", "                                                                     ", "                                                                     ", "                                                                     ", "                                                                     ", "                                                                     ", "                                                                     ", "                                                                     ", "                                                                     ", "                                                                     ", "                                                                     ", "                                                                     ", "                                                                     ", "                                                                     ", "                         CCCC                                        ", "                        C DDDCCC                                     ", "                        CDDDDDD C                                    ", "                        C DDDDDDDCC                                  ", "                         C DDDDDDDCC                                 ", "                          CC DDDDDDCCC                               ", "                            CCCC DDCCCCC                             ", "                                CCCCCCCCCC                           ", "                                   CCCCCCCCC                         ", "                                     CC DDD CC                       ", "                                      CCDDDDD C                      ", "                                       CCDDDDDDC                     ", "                                        C DDDDDDC                    ", "                                         C DDDDDC                    ", "                                          CCDDDD C                   ", "                                            C DDCC                   ", "                                             CCCC                    ", "                                                                     ", "                                                                     ", "                                                                     ", "                                                                     ", "                                                                     ", "         C                                                           ", "        CCCC                                                         ", "        CCCCCC                                                       ", "        CCCCCCC                                                      ", "        CCCDD CC                                                     ", "         CCDDDDCC                                                    ", "         CCDDDDD CC                                                  ", "         CCDDDDDDD C                                                 ", "          CCDDDDDDD CC                                               ", "           C DDDDDDDD C                                              ", "            CDDDDDDDDDDCC                                            ", "            CCDDDDDDDDDD CC                                          ", "             CCDDDDDDDDDDD CC                                        ", "              CCDDDDDDDDDDDD CCC                                     ", "                C DDDDDDDDDDDD CCC                                   ", "                 C DDDDDDDDDDDDD CCC                                 ", "                  CC DDDDDDDDDDDDDCCCC                               ", "                    CC DDDDDDDDDDDCCCC                               ", "                      CCC DDDDDDD CCCC                               ", "                         CCCCCCCCCCCC                                ", "                             CCCCC                                   ", "                                                                     ", "                                                                     ")
                .aisle("                                                                     ", "                                                                     ", "                                                                     ", "                                                                     ", "                                                                     ", "                                                                     ", "                                                                     ", "                                                                     ", "                                                                     ", "                                                                     ", "                                                                     ", "                                                                     ", "                                                                     ", "                                                                     ", "                                                                     ", "                                                                     ", "                                                                     ", "                                                                     ", "                                                                     ", "                                                                     ", "                       CCCCCC                                        ", "                       CDDDDDCC                                      ", "                       CDDDDDD C                                     ", "                       C DDDDDD C                                    ", "                        CCDDDDDDCC                                   ", "                          CCCC CCCC                                  ", "                              CCCCC                                  ", "                                                                     ", "                                                                     ", "                                       CCCCCC                        ", "                                        CCCC CC                      ", "                                         CCDDD C                     ", "                                         CCDDDDDC                    ", "                                          CDDDDDDC                   ", "                                           CDDDDDC                   ", "                                            CDDDD C                  ", "                                             C DDCC                  ", "                                              CCCC                   ", "                                                                     ", "        C                                                            ", "      CCCCC                                                          ", "      CCCCCC                                                         ", "      CCC CCC                                                        ", "      CCDDDDCC                                                       ", "      CCDDDDD C                                                      ", "       CDDDDDD C                                                     ", "       C DDDDDD C                                                    ", "       CCDDDDDDDDC                                                   ", "        CDDDDDDDDDCC                                                 ", "        C DDDDDDDDD C                                                ", "         C DDDDDDDDDDCC                                              ", "          CDDDDDDDDDDD C                                             ", "           CDDDDDDDDDDDDCC                                           ", "            CDDDDDDDDDDDDDCC                                         ", "            CCDDDDDDDDDDDDDDCCC                                      ", "              CDDDDDDDDDDDDDDD CCC                                   ", "               C DDDDDDDDDDDDDDDD CCCC                               ", "                CCDDDDDDDDDDDDDDDDDDCCCC                             ", "                  C DDDDDDDDDDDDDDDDDDCCC                            ", "                   CCDDDDDDDDDDDDDDDDDCCCC                           ", "                     CC DDDDDDDDDDDDDDCCCC                           ", "                       CCC DDDDDDDDDDCCCC                            ", "                          CCCCCC  CCCCC                              ", "                                CC                                   ", "                                                                     ")
                .aisle("                                                                     ", "                                                                     ", "                                                                     ", "                                                                     ", "                                                                     ", "                                                                     ", "                                                                     ", "                                                                     ", "                                                                     ", "                                                                     ", "                                                                     ", "                                                                     ", "                                                                     ", "                                                                     ", "                                                                     ", "                                                                     ", "                                                                     ", "                                                                     ", "                                                                     ", "                       CCCC                                          ", "                      C DD CC                                        ", "                     CCDDDDD C                                       ", "                      CDDDDDD C                                      ", "                      C DDDDD CC                                     ", "                       CCCDD CCC                                     ", "                          CCCCC                                      ", "                                                                     ", "                                                                     ", "                                                                     ", "                                                                     ", "                                            C                        ", "                                           CCCCC                     ", "                                           C DDDC                    ", "                                           CDDDDDC                   ", "                                           C DDDDDC                  ", "                                            CDDDDDC                  ", "                                             CDDDDC                  ", "     CCCC                                     CCD C                  ", "     CCCCC                                      CC                   ", "     CCC CC                                                          ", "     C DDD C                                                         ", "     CDDDDD C                                                        ", "     CDDDDDD C                                                       ", "     C DDDDDD C                                                      ", "     C DDDDDDD C                                                     ", "      CDDDDDDDD C                                                    ", "      CDDDDDDDDD C                                                   ", "       CDDDDDDDDD C                                                  ", "       C DDDDDDDDD C                                                 ", "        CDDDDDDDDDDDC                                                ", "         CDDDDDDDDDDDCC                                              ", "         C DDDDDDDDDDDDCC                                            ", "          C DDDDDDDDDDDD CC                                          ", "           CDDDDDDDDDDDDDDDCC                                        ", "            C DDDDDDDDDDDDDDDCCC                                     ", "             C DDDDDDDDDDDDDDDDDCCCCC                                ", "              CCDDDDDDDDDDDDDDDDDDDD CCCC                            ", "                CDDDDDDDDDDDDDDDDDDDDDD CCCC                         ", "                 CCDDDDDDDDDDDDDDDDDDDDDDCCCC                        ", "                   CCDDDDDDDDDDDDDDDDDDDDDCCC                        ", "                     CCDDDDDDDDDDDDDDDDDDDCCC                        ", "                       CCDDDDDDDDDDDDDDD CCC                         ", "                         CCCCDDDDDDDDD CCC                           ", "                             CCCCCCCCCCC                             ", "                                                                     ")
                .aisle("                                                                     ", "                                                                     ", "                                                                     ", "                                                                     ", "                                                                     ", "                                                                     ", "                                                                     ", "                                                                     ", "                                                                     ", "                                                                     ", "                                                                     ", "                                                                     ", "                                                                     ", "                                                                     ", "                                                                     ", "                                                                     ", "                                                                     ", "                                                                     ", "                                                                     ", "                      CCCC                                           ", "                     C DDDCC                                         ", "                     CDDDDD C                                        ", "                     CDDDDDDCC                                       ", "                     CCDDDDDCC                                       ", "                       CCCCCC                                        ", "                                                                     ", "                                                                     ", "                                                                     ", "                                                                     ", "                                                                     ", "                                                                     ", "                                                                     ", "                                            CCCCC                    ", "                                            CCDDDC                   ", "     CCC                                    C DDDDC                  ", "    CCCCC                                    CDDDDDC                 ", "    CCCCCC                                   CDDDDDC                 ", "    C DDDCC                                   CDDDDC                 ", "    CDDDDDC                                    CCCCC                 ", "    CDDDDDDC                                                         ", "    CDDDDDD C                                                        ", "    CDDDDDDD C                                                       ", "    CDDDDDDDDC                                                       ", "    C DDDDDDDDC                                                      ", "     CDDDDDDDDDC                                                     ", "     CDDDDDDDDDDC                                                    ", "      CDDDDDDDDDDC                                                   ", "      CDDDDDDDDDDDC                                                  ", "       CDDDDDDDDDDDC                                                 ", "       C DDDDDDDDDDDCC                                               ", "        CDDDDDDDDDDDD C                                              ", "         CDDDDDDDDDDDDDCC                                            ", "          CDDDDDDDDDDDDDDCC                                          ", "           CDDDDDDDDDDDDDDDCCC                                       ", "            CDDDDDDDDDDDDDDDD CCC                                    ", "             C DDDDDDDDDDDDDDDDDDCCCCCCCC                            ", "              CCDDDDDDDDDDDDDDDDDDDDDDD  CCCCC                       ", "                CDDDDDDDDDDDDDDDDDDDDDDDDDD CCC                      ", "                 CCDDDDDDDDDDDDDDDDDDDDDDDDDDCCC                     ", "                   C DDDDDDDDDDDDDDDDDDDDDDDDCC                      ", "                    CCCDDDDDDDDDDDDDDDDDDDDD CC                      ", "                       CCDDDDDDDDDDDDDDDDDD CC                       ", "                         CCCDDDDDDDDDDDDD CC                         ", "                            CCCCCCC CCCCCC                           ", "                                   C                                 ")
                .aisle("                                                                     ", "                                                                     ", "                                                                     ", "                                                                     ", "                                                                     ", "                                                                     ", "                                                                     ", "                                                                     ", "                                                                     ", "                                                                     ", "                                                                     ", "                                                                     ", "                                                                     ", "                                                                     ", "                                                                     ", "                                                                     ", "                                                                     ", "                                                                     ", "                                                                     ", "                     CCCCC                                           ", "                    CDDDDDC                                          ", "                    CDDDDD C                                         ", "                    CDDDDDDC                                         ", "                     CDDDDCC                                         ", "                      CCCCC                                          ", "                                                                     ", "                                                                     ", "                                                                     ", "                                                                     ", "                                                                     ", "                                                                     ", "                                                                     ", "    CCCC                                                             ", "   CCCCCC                                     CCCC                   ", "   CCDD C                                    CCDDDC                  ", "   C DDD C                                   C DDDDC                 ", "   CDDDDD C                                   CDDDD C                ", "   CDDDDDDC                                   CDDDDDC                ", "   CDDDDDDDC                                   CDDDCB                ", "   CDDDDDDD C                                   CCCCB                ", "   CDDDDDDDDC                                      BB                ", "   CDDDDDDDDDC                                                       ", "    CDDDDDDDD C                                                      ", "    CDDDDDDDDDC                                                      ", "    C DDDDDDDDDC                                                     ", "     CDDDDDDDDDDC                                                    ", "     C DDDDDDDDDDC                                                   ", "      CDDDDDDDDDD C                                                  ", "       CDDDDDDDDDD C                                                 ", "       C DDDDDDDDDDDC                                                ", "        CDDDDDDDDDDDDCC                                              ", "         CDDDDDDDDDDDD C                                             ", "          CDDDDDDDDDDDDDCC                                           ", "           CDDDDDDDDDDDDDDCCC                                        ", "            C DDDDDDDDDDDDDDDCCCCC                                   ", "             C DDDDDDDDDDDDDDDDDDDCCCCCCCCCCCCC                      ", "              CCDDDDDDDDDDDDDDDDDDDDDDDDDDDD  CCC                    ", "                C DDDDDDDDDDDDDDDDDDDDDDDDDDDDDCCC                   ", "                 CCDDDDDDDDDDDDDDDDDDDDDDDDDDDD CC                   ", "                   CCDDDDDDDDDDDDDDDDDDDDDDDDDDCC                    ", "                     CCDDDDDDDDDDDDDDDDDDDDDDD CC                    ", "                       CC DDDDDDDDDDDDDDDDDDD CC                     ", "                         CCC DDDDDDDDDDDDDD CC                       ", "                            CCCCCDDDDDDDCCCC                         ", "                                 CCCCCCC                             ")
                .aisle("                                                                     ", "                                                                     ", "                                                                     ", "                                                                     ", "                                                                     ", "                                                                     ", "                                                                     ", "                                                                     ", "                                                                     ", "                                                                     ", "                                                                     ", "                                                                     ", "                                                                     ", "                                                                     ", "                                                                     ", "                                                                     ", "                                                                     ", "                                                                     ", "                                                                     ", "                  BBCCCCC                                            ", "                  BC DDDDC                                           ", "                  BCDDDDD C                                          ", "                   C DDDD C                                          ", "                    CCDD C                                           ", "                      CCC                                            ", "                                                                     ", "                                                                     ", "                                                                     ", "                                                                     ", "     C                                                               ", "   CCCCC                                                             ", "   CCCCC                                                             ", "  CCDDD C                                                            ", "  C DDDD C                                                           ", "  CDDDDDDC                                     CCCC                  ", "  CDDDDDD C                                   C DDDC                 ", "  CDDDDDDDC                                   CDDDDDC                ", "  CDDDDDDDDC                                   CDDDDC                ", "  CDDDDDDDDC                                   CDDDDCB               ", "  CDDDDDDDDDC                                   C D CB               ", "   CDDDDDDDDC                                    CCCBB               ", "   CDDDDDDDDDC                                                       ", "   CDDDDDDDDD C                                                      ", "    CDDDDDDDDDC                                                      ", "    CDDDDDDDDDDC                                                     ", "     CDDDDDDDDD C                                                    ", "     CDDDDDDDDDD C                                                   ", "      CDDDDDDDDDDC                                                   ", "       CDDDDDDDDDDC                                                  ", "       C DDDDDDDDDDCC                                                ", "        C DDDDDDDDDD C                                               ", "         C DDDDDDDDDD CC                                             ", "          C DDDDDDDDDDD C                                            ", "           C DDDDDDDDDDDDCCC                                         ", "            CCDDDDDDDDDDDDDDCCCCC            CCC                     ", "              C DDDDDDDDDDDDDDDD CCCCCCCCCCCC  CCCC                  ", "               CCDDDDDDDDDDDDDDDDDDDDDDDDDDDDDDDDCCC                 ", "                 C DDDDDDDDDDDDDDDDDDDDDDDDDDDDDDDCC                 ", "                  CCDDDDDDDDDDDDDDDDDDDDDDDDDDDDDDCC                 ", "                    CCDDDDDDDDDDDDDDDDDDDDDDDDDDDCC                  ", "                      CCDDDDDDDDDDDDDDDDDDDDDDDD C                   ", "                        CC DDDDDDDDDDDDDDDDDDDD C                    ", "                          CCC DDDDDDDDDDDDDDDCCC                     ", "                             CCCCCDDDDDDD CCC                        ", "                                  CCCCCCCC                           ")
                .aisle("                                                                     ", "                                                                     ", "                                                                     ", "                                                                     ", "                                                                     ", "                                                                     ", "                                                                     ", "                                                                     ", "                                                                     ", "                                                                     ", "                                                                     ", "                                                                     ", "                                                                     ", "                                                                     ", "                                                                     ", "                                                                     ", "                                                                     ", "                                                                     ", "                 BB  C                                               ", "                 BBCCDCCC                                            ", "                 BC DDDD C                                           ", "                  CDDDDDDC                                           ", "                   CDDDD C                                           ", "                   CCC CC                                            ", "                      C                                              ", "                                                                     ", "                                                                     ", "    CC                                                               ", "   CCCCC                                                             ", "  CCC CC                                                             ", "  C DDD C                                                            ", "  CDDDDDC                                                            ", "  CDDDDDDC                                                           ", " C DDDDDDC                                                           ", " C DDDDDDDC                                     CCC                  ", " C DDDDDDDC                                    C D C                 ", "  CDDDDDDD C                                   CDDDDC                ", "  CDDDDDDDDC                                   CDDDDC                ", "  CDDDDDDDDC                                   CDDDDDC               ", "  CDDDDDDDDDC                                   CDDDCB               ", "  CDDDDDDDDDC                                    CCCCBB              ", "   CDDDDDDDDDC                                       B               ", "   CDDDDDDDDDC                                                       ", "    CDDDDDDDDDC                                                      ", "    CDDDDDDDDD C                                                     ", "     CDDDDDDDDDC                                                     ", "     C DDDDDDDD C                                                    ", "      C DDDDDDDD C                                                   ", "       CDDDDDDDDDCC                                                  ", "        CDDDDDDDDDCC                                                 ", "         CDDDDDDDDDCC                                                ", "          C DDDDDDDDCC                                               ", "           C DDDDDDDDCCC                                             ", "            CCDDDDDDDD CCC                                           ", "             CC DDDDDDDDDCCCCC            CCCCCCCCCCC                ", "               CCDDDDDDDDDDD  CCCCCCCCCCCCDDDDDDDDDCCC               ", "                CCCDDDDDDDDDDDDDDDDDDDDDDDDDDDDDDDDDCC               ", "                  CC DDDDDDDDDDDDDDDDDDDDDDDDDDDDDDDCC               ", "                    CC DDDDDDDDDDDDDDDDDDDDDDDDDDDD C                ", "                     CCCDDDDDDDDDDDDDDDDDDDDDDDDDDDCC                ", "                       CCCDDDDDDDDDDDDDDDDDDDDDDDDCC                 ", "                         CCC DDDDDDDDDDDDDDDDDDD C                   ", "                            CCC DDDDDDDDDDDDDDCCC                    ", "                               CCCCCDDDDDDCCCC                       ", "                                    CCCCCC                           ")
                .aisle("                                                                     ", "                                                                     ", "                                                                     ", "                                                                     ", "                                                                     ", "                                                                     ", "                                                                     ", "                                                                     ", "                                                                     ", "                                                                     ", "                                                                     ", "                                                                     ", "                                                                     ", "                                                                     ", "                                                                     ", "                                                                     ", "                                                                     ", "                                                                     ", "                BB  CC                                               ", "                BBCCDDCC                                             ", "                 BCDDDD C                                            ", "                  CDDDDDC                                            ", "                  CDDDD C                                            ", "                   CCCCC                                             ", "                                                                     ", "    CCC                                                              ", "   CCCCC                                                             ", "  CC DCC                                                             ", "  C DDD C                                                            ", "  CDDDDDC                                                            ", " C DDDDD C                                                           ", " CDDDDDDDC                                                           ", " CDDDDDDDC                                                           ", " CDDDDDDDDC                                                          ", " CDDDDDDDDC                                                          ", " CDDDDDDDDC                                     CCCC                 ", " CDDDDDDDDDC                                    CDDDC                ", " C DDDDDDDDC                                   C DDDDC               ", "  CDDDDDDDDC                                    CDDDDC               ", "  CDDDDDDDDDC                                   CDDDDC               ", "  C DDDDDDDDC                                    CDD CB              ", "   CDDDDDDDDC                                     CCCBBB             ", "   CDDDDDDDDDC                                        BB             ", "    CDDDDDDDDC                                                       ", "    C DDDDDDD C                                                      ", "     C DDDDDDDC                                                      ", "      CDDDDDDD C                                                     ", "       CDDDDDDDCC                                                    ", "        C DDDDDCC                                                    ", "         C DDDDDCC                                                   ", "          CCDDDDCCC                                                  ", "           CCC DCCCC                                                 ", "            CCCCCCCCC                                                ", "              CCCCCCCCC                       CCCCCCCCC              ", "               CCCCCCCCCC                 CCCC DDDDDDCCC             ", "                 CCCCCCCCCCCCCC   CCCCCCCCDDDDDDDDDDDDCC             ", "                   CCCCCCCCCCCCCCC  DDDDDDDDDDDDDDDDDDC              ", "                    CCCCCCCCDDDDDDDDDDDDDDDDDDDDDDDDD C              ", "                      CCCCCDDDDDDDDDDDDDDDDDDDDDDDDDDC               ", "                        CCCCDDDDDDDDDDDDDDDDDDDDDDDD C               ", "                          CCC DDDDDDDDDDDDDDDDDDDDDCC                ", "                            CCC DDDDDDDDDDDDDDDDDCC                  ", "                              CCC DDDDDDDDDDDDDCC                    ", "                                 CCCCCC  CCCCCC                      ", "                                       CC                            ")
                .aisle("                                                                     ", "                                                                     ", "                                                                     ", "                                                                     ", "                                                                     ", "                                                                     ", "                                                                     ", "                                                                     ", "                                                                     ", "                                                                     ", "                                                                     ", "                                                                     ", "                                                                     ", "                                                                     ", "                                                                     ", "                                                                     ", "                                                                     ", "               BB                                                    ", "               BBB CCC                                               ", "               BBBC D C                                              ", "                 CDDDDDC                                             ", "                 CDDDDDC                                             ", "                 C DDDDC                                             ", "    CCC           CCCCC                                              ", "   CCCCC                                                             ", "  CC D CC                                                            ", "  C DDD C                                                            ", " C DDDDDC                                                            ", " CDDDDDD C                                                           ", " CDDDDDDDC                                                           ", " CDDDDDDDC                                                           ", " CDDDDDDDC                                                           ", " CDDDDDDDDC                                                          ", " CDDDDDDDDC                                                          ", " CDDDDDDDDC                                                          ", " CDDDDDDDDC                                                          ", " CDDDDDDDDC                                      CCCC                ", " C DDDDDDDDC                                    CDDD C               ", "  CDDDDDDDDC                                    CDDDDC               ", "  CDDDDDDDDC                                    CDDDDC               ", "   CDDDDDDD C                                    CDDDC               ", "   CDDDDDDDDC                                    CCCCC B             ", "    CDDDDDDDC                                         BBB            ", "    C DDDDDDCC                                         B             ", "     C DDDDDCC                                                       ", "      C DDDDCC                                                       ", "       CCDDDCCC                                                      ", "        CCCCCCC                                                      ", "         CCCCCC                                                      ", "          CCCCCC                                                     ", "            CCCC                                                     ", "              CC                                     CC              ", "                                                 CCCCCCCC            ", "                                              CCCDDDDDDCC            ", "                                          CCCCDDDDDDDDD C            ", "                                       CCC DDDDDDDDDDDD C            ", "                                  CCCCCDDDDDDDDDDDDDDDDCC            ", "                            CCCCCCCCDDDDDDDDDDDDDDDDDDDC             ", "                           CCCCCCCDDDDDDDDDDDDDDDDDDDDC              ", "                            CCCCCDDDDDDDDDDDDDDDDDDDDCC              ", "                             CCCCCDDDDDDDDDDDDDDDDDDC                ", "                               CCCCDDDDDDDDDDDDDDDCC                 ", "                                 CCCC DDDDDDDDDCCC                   ", "                                    CCCCCCCCCCC                      ", "                                                                     ")
                .aisle("                                                                     ", "                                                                     ", "                                                                     ", "                                                                     ", "                                                                     ", "                                                                     ", "                                                                     ", "                                                                     ", "                                                                     ", "                                                                     ", "                                                                     ", "                                                                     ", "                                                                     ", "                                                                     ", "                                                                     ", "                                                                     ", "               B                                                     ", "              BB                                                     ", "             BBB   CC                                                ", "                 CCDDCC                                              ", "                 CDDDDC                                              ", "     CC          CDDDDC                                              ", "    CCCC         CDDDDC                                              ", "   C D CC         CCCC                                               ", "  C DDDDC                                                            ", "  CDDDDDC                                                            ", " CDDDDDD C                                                           ", " CDDDDDDDC                                                           ", " CDDDDDDDC                                                           ", " CDDDDDDDC                                                           ", "C DDDDDDDC                                                           ", "CDDDDDDDDC                                                           ", " CDDDDDDDDC                                                          ", " CDDDDDDDDC                                                          ", " CDDDDDDDDC                                                          ", " CDDDDDDDDC                                                          ", " CDDDDDDDDC                                       CC                 ", "  CDDDDDDDC                                      CDDCC               ", "  CDDDDDDDC                                     CDDDDC               ", "   CDDDDDD C                                    CDDDDC               ", "   CDDDDDD C                                     CDDDC               ", "    CDDDDD C                                     C DDC BB            ", "    CCDDDDCC                                      CCC  BB            ", "     CC DDCC                                           BB            ", "      CCCCCC                                                         ", "       CCCCC                                                         ", "         CCC                                                         ", "                                                                     ", "                                                                     ", "                                                                     ", "                                                      CCC            ", "                                                   CCC CCC           ", "                                                CCCDDDDD CC          ", "                                              CCDDDDDDDDDCC          ", "                                           CCCDDDDDDDDDDDCC          ", "                                         CC DDDDDDDDDDDDDC           ", "                                      CCCDDDDDDDDDDDDDDD C           ", "                                    CCC DDDDDDDDDDDDDDDDC            ", "                                  CCCCDDDDDDDDDDDDDDDDDC             ", "                                 CCCCDDDDDDDDDDDDDDDDDC              ", "                                  CCC DDDDDDDDDDDDDDCC               ", "                                   CCC DDDDDDDDDDDCC                 ", "                                     CCC  DDDDCCCC                   ", "                                        CCCCCC                       ", "                                                                     ")
                .aisle("                                                                     ", "                                                                     ", "                                                                     ", "                                                                     ", "                                                                     ", "                                                                     ", "                                                                     ", "                                                                     ", "                                                                     ", "                                                                     ", "                                                                     ", "                                                                     ", "                                                                     ", "                                                                     ", "                                                                     ", "                                                                     ", "              BB                                                     ", "             BBB                                                     ", "             BBB   C                                                 ", "      C          CCDCC                                               ", "    CCCCC       CDDDD C                                              ", "   CC  CC       CDDDDDC                                              ", "  CCDDDDCC      C DDD C                                              ", "  CDDDDD C       CCCCC                                               ", " C DDDDDDC                                                           ", " CDDDDDDDC                                                           ", " CDDDDDDDC                                                           ", " CDDDDDDDC                                                           ", "CDDDDDDDDC                                                           ", "CDDDDDDDDC                                                           ", "CDDDDDDDDC                                                           ", "CDDDDDDDDC                                                           ", " CDDDDDDDC                                                           ", " CDDDDDDD C                                                          ", " CDDDDDDD C                                                          ", " CDDDDDDD C                                                          ", "  CDDDDDD C                                                          ", "  CDDDDDD C                                      CCCC                ", "   CDDDDD C                                      CDDDC               ", "   C DDDDCC                                      CDDDDC              ", "    CCDD CC                                      CDDDDC              ", "     CCCCCC                                      CDDDC               ", "      CCCC                                        CCCC  BB           ", "       CCC                                              BB           ", "                                                        BB           ", "                                                                     ", "                                                                     ", "                                                                     ", "                                                                     ", "                                                      CCCCC          ", "                                                    CC   CCC         ", "                                                  CCDDDDDDCC         ", "                                                CCDDDDDDDD C         ", "                                              CCDDDDDDDDDD C         ", "                                            CCDDDDDDDDDDDD C         ", "                                          CC DDDDDDDDDDDDDC          ", "                                         C DDDDDDDDDDDDDD C          ", "                                       CC DDDDDDDDDDDDDD C           ", "                                      CCCDDDDDDDDDDDDDD C            ", "                                     CCC DDDDDDDDDDDDDCC             ", "                                     CCCCDDDDDDDDDDDCC               ", "                                      CCCC DDDDDD CC                 ", "                                        CCCCCCCCCC                   ", "                                                                     ", "                                                                     ")
                .aisle("                                                                     ", "                                                                     ", "                                                                     ", "                                                                     ", "                                                                     ", "                                                                     ", "                                                                     ", "                                                                     ", "                                                                     ", "                                                                     ", "                                                                     ", "                                                                     ", "                                                                     ", "                                                                     ", "                                                                     ", "              B                                                      ", "            BBBB                                                     ", "            BBBB                                                     ", "     CCCC         CC                                                 ", "    CC CCC       C  CC                                               ", "   C DDD C      CDDDDC                                               ", "  C DDDDDC      CDDDDC                                               ", "  CDDDDDDC      CDDDDC                                               ", " CDDDDDDDC      CCCCC                                                ", " CDDDDDDDC                                                           ", " CDDDDDDDC                                                           ", " CDDDDDDDC                                                           ", "CDDDDDDDDC                                                           ", "CDDDDDDDDC                                                           ", "CDDDDDDDDC                                                           ", "CDDDDDDDDC                                                           ", " CDDDDDDDC                                                           ", " CDDDDDDDC                                                           ", " CDDDDDDDC                                                           ", " C DDDDDDC                                                           ", "  CDDDDDDC                                                           ", "  C DDDD C                                                           ", "   C DDDCC                                        CCC                ", "   CCC CCC                                       C DDC               ", "    CCCCC                                        CDDDDC              ", "      CCC                                        CDDDDC              ", "                                                 CDDDDC              ", "                                                  CDDC               ", "                                                   CC    BB          ", "                                                        BBB          ", "                                                        BBB          ", "                                                                     ", "                                                                     ", "                                                       CCCCCC        ", "                                                     CC DDDCC        ", "                                                   CC DDDDDDC        ", "                                                  C DDDDDDDDC        ", "                                                CCDDDDDDDDDDC        ", "                                               C DDDDDDDDDD C        ", "                                             CCDDDDDDDDDDDDC         ", "                                            C DDDDDDDDDDDD C         ", "                                          CC DDDDDDDDDDDDDC          ", "                                         CCCDDDDDDDDDDDDDC           ", "                                         CCDDDDDDDDDDDDDC            ", "                                        CCCDDDDDDDDDDDCC             ", "                                         CCCDDDDDDDDCC               ", "                                          CCCCCCCCCC                 ", "                                                                     ", "                                                                     ", "                                                                     ")
                .aisle("                                                                     ", "                                                                     ", "                                                                     ", "                                                                     ", "                                                                     ", "                                                                     ", "                                                                     ", "                                                                     ", "                                                                     ", "                                                                     ", "                                                                     ", "                                                                     ", "                                                                     ", "                                                                     ", "            B                                                        ", "            BB                                                       ", "      CCC   BBB                                                      ", "     CCCCC  BBB                                                      ", "    C DDDCC                    CCCCCC                                ", "   CDDDDD C     CCCCC            CCCCCC                              ", "  C DDDDDDC     CDDD C            CCCCCCCC                           ", "  CDDDDDDDC    CDDDDDC               CCCCCC                          ", " CDDDDDDDDC    C DDD C                 CCCCC                         ", " CDDDDDDDDC     CCDCC                    CCCC                        ", " CDDDDDDDDC       C                       CCCC                       ", " CDDDDDDDDC                                CCC                       ", " CDDDDDDDDC                                  C                       ", "CDDDDDDDDC                                                           ", "C DDDDDDDC                                                           ", " CDDDDDDDC                                                           ", " CDDDDDDDC                                                           ", " CDDDDDDDC                                                           ", " CDDDDDD C                                                           ", "  CDDDDD C                                                           ", "  C DDDDC                                                            ", "   C DDCC                                                            ", "   CCCCCC                                                            ", "    CCCC                                                             ", "      C                                           CCCC               ", "                                                 CDDD C              ", "                                                 CDDDDC              ", "                                                 CDDDDC              ", "                                                 C DD C              ", "                                                  CCCC    B          ", "                                                         BBB         ", "                                                         BBB         ", "                                                         BCCC        ", "                                                        CCCCCC       ", "                                                      CCDDDD C       ", "                                                     CDDDDDDDCC      ", "                                                   CCDDDDDDDDC       ", "                                                  C DDDDDDDDDC       ", "                                                 CDDDDDDDDDDDC       ", "                                               CCDDDDDDDDDDD C       ", "                                              C DDDDDDDDDDDDC        ", "                                             CCDDDDDDDDDDDDC         ", "                                            CCDDDDDDDDDDDDC          ", "                                            CCDDDDDDDDDDDC           ", "                                           CCCDDDDDDDDD C            ", "                                           CCCDDDDDDD CC             ", "                                            CCCC  CCCC               ", "                                              CCCC                   ", "                                                                     ", "                                                                     ", "                                                                     ")
                .aisle("                                                                     ", "                                                                     ", "                                                                     ", "                                                                     ", "                                                                     ", "                                                                     ", "                                                                     ", "                                                                     ", "                                                                     ", "                                                                     ", "                                                                     ", "                                                                     ", "                                                                     ", "                                                                     ", "        C  BB                                                        ", "      CCCCCBB                                                        ", "     C DDCCBB                                                        ", "    CDDDDDCC                                                         ", "   CDDDDDD C                   CAAAFCC                               ", "  C DDDDDD C    CCCC         CCCC DDDDCCC                            ", "  CDDDDDDD C   C DDDC       CCCCCC DDDDD CC                          ", "  CDDDDDDDC    CDDDDC        CCCCCCCCCDDDD C                         ", " CDDDDDDDDC    CDDDDC                 CCDDD C                        ", " CDDDDDDDDC     CDDCC                   C DD C                       ", " CDDDDDDDDC      CC                      C DD C                      ", " CDDDDDDDDC                               C DDC                      ", " CDDDDDDDDC                                CCDCC                     ", " CDDDDDDDC                                  CCCC                     ", " CDDDDDDDC                                   CCC                     ", " CDDDDDDDC                                   CCC                     ", " CDDDDDD C                                    CC                     ", " C DDDDDC                                     CC                     ", "  C DDD C                                                            ", "  CC D CC                                                            ", "   CCCCC                                                             ", "    CCC                                                              ", "                                                                     ", "                                                                     ", "                                                  CCCC               ", "                                                 C DD C              ", "                                                 CDDDDC              ", "                                                 CDDDDC              ", "                                                 CDDDDC              ", "                                                  CCCC               ", "                                                          BBC        ", "                                                         BCCCCC      ", "                                                        CC DDCC      ", "                                                       C DDDDDCC     ", "                                                      CDDDDDDDCC     ", "                                                    CCDDDDDDDDC      ", "                                                   C DDDDDDDDDC      ", "                                                  C DDDDDDDDDDC      ", "                                                 C DDDDDDDDDD C      ", "                                                C DDDDDDDDDDDC       ", "                                               CCDDDDDDDDDDDC        ", "                                               CDDDDDDDDDDD C        ", "                                              CCDDDDDDDDDD C         ", "                                              CCDDDDDDDDDCC          ", "                                              CCDDDDDDDCC            ", "                                              CCCC  CCC              ", "                                                CCCC                 ", "                                                                     ", "                                                                     ", "                                                                     ", "                                                                     ")
                .aisle("                                                                     ", "                                                                     ", "                                                                     ", "                                                                     ", "                                                                     ", "                                                                     ", "                                                                     ", "                                                                     ", "                                                                     ", "                                                                     ", "                                                                     ", "                                                                     ", "                                                                     ", "       CCCC                                                          ", "      CC CCCB                                                        ", "     C DDDDCB                                                        ", "    CDDDDDDCC                                                        ", "   CDDDDDDD C                                                        ", "   CDDDDDDDC                  CCAAAACC                               ", "  CDDDDDDDDC    CCCC        CCDDDDDDDDCCC                            ", "  CDDDDDDDDC   CDDD C      C DDDDDDDDDDD C                           ", " CDDDDDDDDDC   CDDDDC     CCC CCCEEEECDDDDCC                         ", " CDDDDDDDDDC   CDDDDC    CCCCC     EEEEE DD C                        ", " CDDDDDDDDC    C DDC     CC            EE DD C                       ", " CDDDDDDDDC     CCC                     EE DD C                      ", " CDDDDDDDDC                               E DDC                      ", " CDDDDDDDC                                 EDDDC                     ", " CDDDDDDDC                                 ECDDC                     ", " C DDDDD C                                  EDDDC                    ", "  CDDDDDC                                    CDDC                    ", "  C DDD C                                    CDDC                    ", "  CCC CC                                     C DC                    ", "   CCCCC                                      CCC                    ", "    CCC                                       CCC                    ", "                                              CCC                    ", "                                              CC                     ", "                                                                     ", "                                                                     ", "                                                   CC                ", "                                                  C  C               ", "                                                 CDDDDC              ", "                                                 CDDDDC              ", "                                                 CDDDDC              ", "                                                  CDDC     CCCC      ", "                                                   CC     CC CCC     ", "                                                         C DDD C     ", "                                                        CDDDDDDC     ", "                                                      CCDDDDDDDC     ", "                                                      CDDDDDDDDC     ", "                                                     CDDDDDDDDDC     ", "                                                    CDDDDDDDDDDC     ", "                                                   CDDDDDDDDDDC      ", "                                                  CDDDDDDDDDDDC      ", "                                                 C DDDDDDDDDDC       ", "                                                 CDDDDDDDDDD C       ", "                                                CCDDDDDDDDD C        ", "                                                CCDDDDDDDDCC         ", "                                                CCDDDDDD C           ", "                                                CCCC  CCC            ", "                                                  CCCC               ", "                                                                     ", "                                                                     ", "                                                                     ", "                                                                     ", "                                                                     ")
