package magicbook.gtlitecore.common.metatileentities.multi.electric;

import gregtech.api.capability.impl.MultiblockRecipeLogic;
import gregtech.api.gui.resources.TextureArea;
import gregtech.api.metatileentity.MetaTileEntity;
import gregtech.api.metatileentity.interfaces.IGregTechTileEntity;
import gregtech.api.metatileentity.multiblock.IMultiblockPart;
import gregtech.api.metatileentity.multiblock.MultiMapMultiblockController;
import gregtech.api.pattern.BlockPattern;
import gregtech.api.pattern.FactoryBlockPattern;
import gregtech.api.pattern.PatternMatchContext;
import gregtech.api.recipes.Recipe;
import gregtech.api.recipes.RecipeMap;
import gregtech.api.util.RelativeDirection;
import gregtech.client.renderer.ICubeRenderer;
import gregtech.common.blocks.MetaBlocks;
import magicbook.gtlitecore.api.block.impl.WrappedIntTier;
import magicbook.gtlitecore.api.gui.GTLiteGuiTextures;
import magicbook.gtlitecore.api.pattern.GTLiteTraceabilityPredicate;
import magicbook.gtlitecore.api.recipe.GTLiteRecipeMaps;
import magicbook.gtlitecore.api.recipe.properties.SpaceElevatorCasingTierProperty;
import magicbook.gtlitecore.api.unification.GTLiteMaterials;
import magicbook.gtlitecore.api.utils.GTLiteUtils;
import magicbook.gtlitecore.client.renderer.texture.GTLiteTextures;
import magicbook.gtlitecore.common.blocks.BlockSpaceElevatorCasing;
import magicbook.gtlitecore.common.blocks.GTLiteMetaBlocks;
import net.minecraft.block.state.IBlockState;
import net.minecraft.client.resources.I18n;
import net.minecraft.item.ItemStack;
import net.minecraft.util.ResourceLocation;
import net.minecraft.world.World;
import net.minecraftforge.fml.relauncher.Side;
import net.minecraftforge.fml.relauncher.SideOnly;

import javax.annotation.Nonnull;
import javax.annotation.Nullable;
import java.util.List;

/**
 * Space Elevator for GregTech CEu
 *
 * @author minecraft7771, Sampsa (original author)
 *
 * <p>
 *     Based on the same name work for GregTech 5 unofficial.
 *     Maybe redo this machine's logic in future (todo?).
 * </p>
 */
public class MetaTileEntitySpaceElevator extends MultiMapMultiblockController {

    private int casingTier;

    public MetaTileEntitySpaceElevator(ResourceLocation metaTileEntityId) {
        super(metaTileEntityId, new RecipeMap[]{
                GTLiteRecipeMaps.SPACE_ELEVATOR_DRILLING_MODULE,
                GTLiteRecipeMaps.SPACE_ELEVATOR_MINING_MODULE,
                GTLiteRecipeMaps.SPACE_ELEVATOR_ASSEMBLING_MODULE
        });
        this.recipeMapWorkable = new SpaceElevatorRecipeLogic(this);
    }

    @Override
    public MetaTileEntity createMetaTileEntity(IGregTechTileEntity tileEntity) {
        return new MetaTileEntitySpaceElevator(metaTileEntityId);
    }

    @Override
    protected void formStructure(PatternMatchContext context) {
        super.formStructure(context);
        Object type = context.get("SpaceElevatorMotorTieredStats");
        this.casingTier = GTLiteUtils.getOrDefault(() -> type instanceof WrappedIntTier,
                () -> ((WrappedIntTier) type).getIntTier(), 0);
    }

    @Override
    public void invalidateStructure() {
        super.invalidateStructure();
        this.casingTier = 0;
    }

    @Override
    public boolean checkRecipe(@Nonnull Recipe recipe,
                               boolean consumeIfSuccess) {
        return super.checkRecipe(recipe, consumeIfSuccess) && recipe.getProperty(SpaceElevatorCasingTierProperty.getInstance(), 0) <= casingTier;
    }

    @Nonnull
    @Override
    protected BlockPattern createStructurePattern() {
        return FactoryBlockPattern.start(RelativeDirection.RIGHT, RelativeDirection.DOWN, RelativeDirection.FRONT)
                .aisle("                                   ", "                                   ", "                                   ", "                                   ", "                                   ", "                                   ", "                                   ", "                                   ", "                                   ", "                                   ", "                                   ", "                                   ", "                                   ", "                                   ", "                                   ", "                                   ", "                                   ", "                                   ", "                                   ", "                                   ", "                                   ", "                                   ", "                                   ", "                                   ", "                                   ", "                                   ", "                                   ", "                                   ", "                                   ", "                                   ", "                                   ", "                                   ", "                                   ", "                                   ", "                                   ", "                                   ", "                                   ", "                                   ", "                                   ", "                                   ", "                                   ", "               FF FF               ", "               AAAAA               ")
                .aisle("                                   ", "                                   ", "                                   ", "                                   ", "                                   ", "                                   ", "                                   ", "                                   ", "                                   ", "                                   ", "                                   ", "                                   ", "                                   ", "                                   ", "                                   ", "                                   ", "                                   ", "                                   ", "                                   ", "                                   ", "                                   ", "                                   ", "                                   ", "                                   ", "                                   ", "                                   ", "                                   ", "                                   ", "                                   ", "                                   ", "                                   ", "                                   ", "                                   ", "                                   ", "                                   ", "                                   ", "                                   ", "                                   ", "                                   ", "                                   ", "               D   D               ", "            FFFFF FFFFF            ", "            AAAAAAAAAAA            ")
                .aisle("                                   ", "                                   ", "                                   ", "                                   ", "                                   ", "                                   ", "                                   ", "                                   ", "                                   ", "                                   ", "                                   ", "                                   ", "                                   ", "                                   ", "                                   ", "                                   ", "                                   ", "                                   ", "                                   ", "                                   ", "                                   ", "                                   ", "                                   ", "                                   ", "                                   ", "                                   ", "                                   ", "                                   ", "                                   ", "                                   ", "                                   ", "                                   ", "                                   ", "                                   ", "                                   ", "                                   ", "                                   ", "                                   ", "                                   ", "                                   ", "            DDDDE EDDDD            ", "          FFFFFFF FFFFFFF          ", "          AAAAAAAAAAAAAAA          ")
                .aisle("                                   ", "                                   ", "                                   ", "                                   ", "                                   ", "                                   ", "                                   ", "                                   ", "                                   ", "                                   ", "                                   ", "                                   ", "                                   ", "                                   ", "                                   ", "                                   ", "                                   ", "                                   ", "                                   ", "                                   ", "                                   ", "                                   ", "                                   ", "                                   ", "                                   ", "                                   ", "                                   ", "                                   ", "                                   ", "                                   ", "                                   ", "                                   ", "                                   ", "                                   ", "                                   ", "                                   ", "                                   ", "                                   ", "                                   ", "                E E                ", "          DD   DE ED   DD          ", "         FFFFFFD   DFFFFFF         ", "        AAAAAAAAAAAAAAAAAAA        ")
                .aisle("                                   ", "                                   ", "                                   ", "                                   ", "                                   ", "                                   ", "                                   ", "                                   ", "                                   ", "                                   ", "                                   ", "                                   ", "                                   ", "                                   ", "                                   ", "                                   ", "                                   ", "                                   ", "                                   ", "                                   ", "                                   ", "                                   ", "                                   ", "                                   ", "                                   ", "                                   ", "                                   ", "                                   ", "                                   ", "                                   ", "                                   ", "                                   ", "                                   ", "                                   ", "                                   ", "                                   ", "                                   ", "                                   ", "                E E                ", "               DE ED               ", "               D   D               ", "         FFF           FFF         ", "       AAAAAAAAAAAAAAAAAAAAA       ")
                .aisle("                                   ", "                                   ", "                                   ", "                                   ", "                                   ", "                                   ", "                                   ", "                                   ", "                                   ", "                                   ", "                                   ", "                                   ", "                                   ", "                                   ", "                                   ", "                                   ", "                                   ", "                                   ", "                                   ", "                                   ", "                                   ", "                                   ", "                                   ", "                                   ", "                                   ", "                                   ", "                                   ", "                                   ", "                                   ", "                                   ", "                                   ", "                                   ", "                                   ", "                                   ", "                                   ", "                                   ", "                                   ", "                E E                ", "               DE ED               ", "               DE ED               ", "                                   ", "                                   ", "      AAAAAAAAAAAAAAAAAAAAAAA      ")
                .aisle("                                   ", "                                   ", "                                   ", "                                   ", "                                   ", "                                   ", "                                   ", "                                   ", "                                   ", "                                   ", "                                   ", "                                   ", "                                   ", "                                   ", "                                   ", "                                   ", "                                   ", "                                   ", "                                   ", "                                   ", "                                   ", "                                   ", "                                   ", "                                   ", "                                   ", "                                   ", "                                   ", "                                   ", "                                   ", "                                   ", "                                   ", "                                   ", "                                   ", "                                   ", "                                   ", "                E E                ", "               DE ED               ", "               DE ED               ", "               DE ED               ", "                                   ", "                                   ", "                                   ", "     AAAAAAAAAAAAAAAAAAAAAAAAA     ")
                .aisle("                                   ", "                                   ", "                                   ", "                                   ", "                                   ", "                                   ", "                                   ", "                                   ", "                                   ", "                                   ", "                                   ", "                                   ", "                                   ", "                                   ", "                                   ", "                                   ", "                                   ", "                                   ", "                                   ", "                                   ", "                                   ", "                                   ", "                                   ", "                                   ", "                                   ", "                                   ", "                                   ", "                                   ", "                                   ", "                                   ", "                                   ", "                                   ", "                E E                ", "              HDE EDH              ", "               DE ED               ", "               DE ED               ", "               DE ED               ", "                                   ", "                                   ", "                                   ", "                                   ", "                                   ", "    AAAAAAAAAAAAAAAAAAAAAAAAAAA    ")
                .aisle("                                   ", "                                   ", "                                   ", "                                   ", "                                   ", "                                   ", "                                   ", "                                   ", "                                   ", "                                   ", "                                   ", "                                   ", "                                   ", "                                   ", "                                   ", "                                   ", "                                   ", "                                   ", "                                   ", "                                   ", "                                   ", "                                   ", "                                   ", "                                   ", "                                   ", "                                   ", "                                   ", "                                   ", "                                   ", "                E E                ", "               DE ED               ", "               DE ED               ", "               DE ED               ", "            HH DE ED HH            ", "                                   ", "                                   ", "                                   ", "                                   ", "               X X X               ", "               X X X               ", "               X X X               ", "               X X X               ", "   AAAAAAAAAAAAX X XAAAAAAAAAAAA   ")
                .aisle("                                   ", "                                   ", "                                   ", "                                   ", "                                   ", "                                   ", "                                   ", "                                   ", "                                   ", "                                   ", "                                   ", "                                   ", "                                   ", "                                   ", "                                   ", "                                   ", "                                   ", "                                   ", "                                   ", "                                   ", "                                   ", "                                   ", "                                   ", "                                   ", "                                   ", "                                   ", "                E E                ", "               DE ED               ", "               DE ED               ", "               DE ED               ", "               DE ED               ", "                                   ", "         E               E         ", "         EHH           HHE         ", "         E               E         ", "         E               E         ", "         E               E         ", "         E               E         ", "         E     X X X     E         ", "         E     I I I     E         ", "         E     X X X     E         ", "   FF    E     X X X     E    FF   ", "   AAAAAAAAAAAAX X XAAAAAAAAAAAA   ")
                .aisle("                                   ", "                                   ", "                                   ", "                                   ", "                                   ", "                                   ", "                                   ", "                                   ", "                                   ", "                                   ", "                                   ", "                                   ", "                                   ", "                                   ", "                                   ", "                                   ", "                                   ", "                                   ", "                                   ", "                                   ", "                                   ", "                                   ", "                E E                ", "               DE ED               ", "               DE ED               ", "               DE ED               ", "               DE ED               ", "               DE ED               ", "          E             E          ", "          E             E          ", "          E             E          ", "          E             E          ", "          E             E          ", "         HE             EH         ", "                                   ", "                                   ", "                                   ", "                                   ", "                                   ", "                                   ", "   D                           D   ", "  FFF          F F F          FFF  ", "  AAAAAAAAAAAAA     AAAAAAAAAAAAA  ")
                .aisle("                                   ", "                                   ", "                                   ", "                                   ", "                                   ", "                                   ", "                                   ", "                                   ", "                                   ", "                                   ", "                                   ", "                                   ", "                                   ", "                                   ", "                E E                ", "               DE ED               ", "               DE ED               ", "               DE ED               ", "               DE ED               ", "               DE ED               ", "               DE ED               ", "               DE ED               ", "               DE ED               ", "               DE ED               ", "                                   ", "                                   ", "           E           E           ", "           E           E           ", "           E           E           ", "           E           E           ", "           E           E           ", "                                   ", "                                   ", "         H               H         ", "                                   ", "                                   ", "                                   ", "                                   ", "                                   ", "                                   ", "   D                           D   ", "  FFF          F F F          FFF  ", "  AAAAAAAAAAAAA     AAAAAAAAAAAAA  ")
                .aisle("                                   ", "                                   ", "                                   ", "                                   ", "                                   ", "                                   ", "                                   ", "                E E                ", "               DE ED               ", "               DE ED               ", "               DE ED               ", "               DE ED               ", "               DE ED               ", "               DE ED               ", "               DE ED               ", "               DE ED               ", "                                   ", "                                   ", "                                   ", "                                   ", "                                   ", "             HH     HH             ", "            E         E            ", "            E         E            ", "            E         E            ", "            E         E            ", "            E         E            ", "            E         E            ", "                                   ", "                                   ", "                                   ", "                                   ", "                                   ", "        H                 H        ", "                                   ", "                                   ", "                                   ", "                                   ", "                                   ", "                                   ", "  D                             D  ", " FFF          FFFFFFF          FFF ", " AAAAAAAAAAAAAAAAAAAAAAAAAAAAAAAAA ")
                .aisle("                                   ", "                                   ", "                                   ", "                                   ", "                                   ", "                                   ", "                FFF                ", "                                   ", "                                   ", "                                   ", "                                   ", "                                   ", "                                   ", "                                   ", "             E       E             ", "             E       E             ", "             E       E             ", "             E       E             ", "             E       E             ", "             E       E             ", "             E       E             ", "            HE       EH            ", "             E       E             ", "             E       E             ", "                                   ", "                                   ", "                                   ", "                                   ", "                                   ", "                                   ", "                                   ", "                                   ", "                                   ", "        H                 H        ", "                                   ", "                                   ", "                                   ", "                                   ", "                                   ", "                                   ", "  D                             D  ", " FFF         FFFFFFFFF         FFF ", " AAAAAAAAAAAAAAAAAAAAAAAAAAAAAAAAA ")
                .aisle("                FFF                ", "                 E                 ", "                 E                 ", "                 E                 ", "                 E                 ", "                 E                 ", "               F   F               ", "              E     E              ", "              E     E              ", "              E     E              ", "              E     E              ", "              E     E              ", "              E     E              ", "              E     E              ", "              E     E              ", "              E     E              ", "                                   ", "                                   ", "                FFF                ", "                                   ", "                                   ", "            H         H            ", "                                   ", "                                   ", "                                   ", "                                   ", "                                   ", "                                   ", "                FFF                ", "                                   ", "                                   ", "                                   ", "                                   ", "       H                   H       ", "                                   ", "                                   ", "                                   ", "                                   ", "                XXX                ", "                X~X                ", "  D             XXX             D  ", " FFF        FFFFFFFFFFF        FFF ", " AAAAAAAAAAAAAAAAAAAAAAAAAAAAAAAAA ")
                .aisle("               F D F               ", "                 D                 ", "                 D                 ", "                 D                 ", "                 D                 ", "                 D                 ", "              F  D  F              ", "                 D                 ", "            D    D    D            ", "            D    D    D            ", "            D    D    D            ", "            D    D    D            ", "            D    D    D            ", "            D    D    D            ", "            D    D    D            ", "           DD    D    DD           ", "           D     D     D           ", "           D     D     D           ", "           D   F D F   D           ", "           D     C     D           ", "           D     C     D           ", "           D     C     D           ", "           D     C     D           ", "          DD     C     DD          ", "          D      C      D          ", "          D      C      D          ", "          D      C      D          ", "         DD      C      DD         ", "         D     FDCDF     D         ", "         D      DCD      D         ", "        DD      DCD      DD        ", "        D       DCD       D        ", "        D       DCD       D        ", "       DD      DDCDD      DD       ", "       D       D C D       D       ", "       D       D C D       D       ", "      DD       D C D       DD      ", "      D        D C D        D      ", "     DD XX     XDCDX     XX DD     ", "    DD  XI     XDCDX     IX  DD    ", " DDDD   XX     XDCDX     XX   DDDD ", "FFFD    XXFFFFFDDDDDFFFFFXX    DFFF", "AAAAAAAAXX  AAAXXXXXAAA  XXAAAAAAAA")
                .aisle("              F     F              ", "                                   ", "                                   ", "                                   ", "                                   ", "                                   ", "             F       F             ", "            E         E            ", "            E         E            ", "            E         E            ", "            E         E            ", "            E         E            ", "            E         E            ", "            E         E            ", "           EE         EE           ", "           EE         EE           ", "           E           E           ", "           E           E           ", "           E  F     F  E           ", "           E           E           ", "           E           E           ", "           E           E           ", "          EE           EE          ", "          EE           EE          ", "          E             E          ", "          E             E          ", "         EE             EE         ", "         EE             EE         ", "         E    FD   DF    E         ", "        EE     D   D     EE        ", "        EE     D   D     EE        ", "        E      D   D      E        ", "       EE      D   D      EE       ", "       EE      D   D      EE       ", "       E                   E       ", "      EE                   EE      ", "      EE                   EE      ", "     EE                     EE     ", "    EEE       XD   DX       EEE    ", "   EEE        XD   DX        EEE   ", "  EE          XD   DX          EE  ", "FFF         FFFDDDDDFFF         FFF", "AAAAAAAA    AAAXXXXXAAA    AAAAAAAA")
                .aisle("              FD   DF              ", "              ED   DE              ", "              ED   DE              ", "              ED   DE              ", "              ED   DE              ", "              ED   DE              ", "             F D   D F             ", "               D   D               ", "               D   D               ", "               D   D               ", "               D   D               ", "               D   D               ", "               D   D               ", "               D   D               ", "               D   D               ", "               D   D               ", "               D   D               ", "               D B D               ", "              FD - DF              ", "               C - C               ", "               C - C               ", "               C - C               ", "               C - C               ", "               C - C               ", "               C - C               ", "               C - C               ", "               C - C               ", "               C - C               ", "              FC - CF              ", "               C - C               ", "               C - C               ", "               C - C               ", "               C - C               ", "               C - C               ", "               C - C               ", "               C - C               ", "               C - C               ", "               C - C               ", "        XX    XC - CX    XX        ", "        XI    XC - CX    IX        ", "        XX    XC - CX    XX        ", "        XXFFFFFDDDDDFFFFFXX        ", "AAAAAAAAXX  AAAXXXXXAAA  XXAAAAAAAA")
                .aisle("              F     F              ", "                                   ", "                                   ", "                                   ", "                                   ", "                                   ", "             F       F             ", "            E         E            ", "            E         E            ", "            E         E            ", "            E         E            ", "            E         E            ", "            E         E            ", "            E         E            ", "           EE         EE           ", "           EE         EE           ", "           E           E           ", "           E           E           ", "           E  F     F  E           ", "           E           E           ", "           E           E           ", "           E           E           ", "          EE           EE          ", "          EE           EE          ", "          E             E          ", "          E             E          ", "         EE             EE         ", "         EE             EE         ", "         E    FD   DF    E         ", "        EE     D   D     EE        ", "        EE     D   D     EE        ", "        E      D   D      E        ", "       EE      D   D      EE       ", "       EE      D   D      EE       ", "       E                   E       ", "      EE                   EE      ", "      EE                   EE      ", "     EE                     EE     ", "    EEE       XD   DX       EEE    ", "   EEE        XD   DX        EEE   ", "  EE          XD   DX          EE  ", "FFF         FFFDDDDDFFF         FFF", "AAAAAAAA    AAAXXXXXAAA    AAAAAAAA")
                .aisle("               F D F               ", "                 D                 ", "                 D                 ", "                 D                 ", "                 D                 ", "                 D                 ", "              F  D  F              ", "                 D                 ", "            D    D    D            ", "            D    D    D            ", "            D    D    D            ", "            D    D    D            ", "            D    D    D            ", "            D    D    D            ", "            D    D    D            ", "           DD    D    DD           ", "           D     D     D           ", "           D     D     D           ", "           D   F D F   D           ", "           D     C     D           ", "           D     C     D           ", "           D     C     D           ", "           D     C     D           ", "          DD     C     DD          ", "          D      C      D          ", "          D      C      D          ", "          D      C      D          ", "         DD      C      DD         ", "         D     FDCDF     D         ", "         D      DCD      D         ", "        DD      DCD      DD        ", "        D       DCD       D        ", "        D       DCD       D        ", "       DD      DDCDD      DD       ", "       D       D C D       D       ", "       D       D C D       D       ", "      DD       D C D       DD      ", "      D        D C D        D      ", "     DD XX     XDCDX     XX DD     ", "    DD  XI     XDCDX     IX  DD    ", " DDDD   XX     XDCDX     XX   DDDD ", "FFFD    XXFFFFFDDDDDFFFFFXX    DFFF", "AAAAAAAAXX  AAAXXXXXAAA  XXAAAAAAAA")
                .aisle("                FFF                ", "                 E                 ", "                 E                 ", "                 E                 ", "                 E                 ", "                 E                 ", "               F   F               ", "              E     E              ", "              E     E              ", "              E     E              ", "              E     E              ", "              E     E              ", "              E     E              ", "              E     E              ", "              E     E              ", "              E     E              ", "                                   ", "                                   ", "                FFF                ", "                                   ", "                                   ", "            H         H            ", "                                   ", "                                   ", "                                   ", "                                   ", "                                   ", "                                   ", "                FFF                ", "                                   ", "                                   ", "                                   ", "                                   ", "       H                   H       ", "                                   ", "                                   ", "                                   ", "                                   ", "                XXX                ", "                XXX                ", "  D             XXX             D  ", " FFF        FFFFFFFFFFF        FFF ", " AAAAAAAAAAAAAAAAAAAAAAAAAAAAAAAAA ")
                .aisle("                                   ", "                                   ", "                                   ", "                                   ", "                                   ", "                                   ", "                FFF                ", "                                   ", "                                   ", "                                   ", "                                   ", "                                   ", "                                   ", "                                   ", "             E       E             ", "             E       E             ", "             E       E             ", "             E       E             ", "             E       E             ", "             E       E             ", "             E       E             ", "            HE       EH            ", "             E       E             ", "             E       E             ", "                                   ", "                                   ", "                                   ", "                                   ", "                                   ", "                                   ", "                                   ", "                                   ", "                                   ", "        H                 H        ", "                                   ", "                                   ", "                                   ", "                                   ", "                                   ", "                                   ", "  D                             D  ", " FFF         FFFFFFFFF         FFF ", " AAAAAAAAAAAAAAAAAAAAAAAAAAAAAAAAA ")
                .aisle("                                   ", "                                   ", "                                   ", "                                   ", "                                   ", "                                   ", "                                   ", "                E E                ", "               DE ED               ", "               DE ED               ", "               DE ED               ", "               DE ED               ", "               DE ED               ", "               DE ED               ", "               DE ED               ", "               DE ED               ", "                                   ", "                                   ", "                                   ", "                                   ", "                                   ", "             HH     HH             ", "            E         E            ", "            E         E            ", "            E         E            ", "            E         E            ", "            E         E            ", "            E         E            ", "                                   ", "                                   ", "                                   ", "                                   ", "                                   ", "        H                 H        ", "                                   ", "                                   ", "                                   ", "                                   ", "                                   ", "                                   ", "  D                             D  ", " FFF          FFFFFFF          FFF ", " AAAAAAAAAAAAAAAAAAAAAAAAAAAAAAAAA ")
                .aisle("                                   ", "                                   ", "                                   ", "                                   ", "                                   ", "                                   ", "                                   ", "                                   ", "                                   ", "                                   ", "                                   ", "                                   ", "                                   ", "                                   ", "                E E                ", "               DE ED               ", "               DE ED               ", "               DE ED               ", "               DE ED               ", "               DE ED               ", "               DE ED               ", "               DE ED               ", "               DE ED               ", "               DE ED               ", "                                   ", "                                   ", "           E           E           ", "           E           E           ", "           E           E           ", "           E           E           ", "           E           E           ", "                                   ", "                                   ", "         H               H         ", "                                   ", "                                   ", "                                   ", "                                   ", "                                   ", "                                   ", "   D                           D   ", "  FFF          F F F          FFF  ", "  AAAAAAAAAAAAA     AAAAAAAAAAAAA  ")
                .aisle("                                   ", "                                   ", "                                   ", "                                   ", "                                   ", "                                   ", "                                   ", "                                   ", "                                   ", "                                   ", "                                   ", "                                   ", "                                   ", "                                   ", "                                   ", "                                   ", "                                   ", "                                   ", "                                   ", "                                   ", "                                   ", "                                   ", "                E E                ", "               DE ED               ", "               DE ED               ", "               DE ED               ", "               DE ED               ", "               DE ED               ", "          E             E          ", "          E             E          ", "          E             E          ", "          E             E          ", "          E             E          ", "         HE             EH         ", "                                   ", "                                   ", "                                   ", "                                   ", "                                   ", "                                   ", "   D                           D   ", "  FFF          F F F          FFF  ", "  AAAAAAAAAAAAA     AAAAAAAAAAAAA  ")
                .aisle("                                   ", "                                   ", "                                   ", "                                   ", "                                   ", "                                   ", "                                   ", "                                   ", "                                   ", "                                   ", "                                   ", "                                   ", "                                   ", "                                   ", "                                   ", "                                   ", "                                   ", "                                   ", "                                   ", "                                   ", "                                   ", "                                   ", "                                   ", "                                   ", "                                   ", "                                   ", "                E E                ", "               DE ED               ", "               DE ED               ", "               DE ED               ", "               DE ED               ", "                                   ", "         E               E         ", "         EHH           HHE         ", "         E               E         ", "         E               E         ", "         E               E         ", "         E               E         ", "         E     X X X     E         ", "         E     I I I     E         ", "         E     X X X     E         ", "   FF    E     X X X     E    FF   ", "   AAAAAAAAAAAAX X XAAAAAAAAAAAA   ")
                .aisle("                                   ", "                                   ", "                                   ", "                                   ", "                                   ", "                                   ", "                                   ", "                                   ", "                                   ", "                                   ", "                                   ", "                                   ", "                                   ", "                                   ", "                                   ", "                                   ", "                                   ", "                                   ", "                                   ", "                                   ", "                                   ", "                                   ", "                                   ", "                                   ", "                                   ", "                                   ", "                                   ", "                                   ", "                                   ", "                E E                ", "               DE ED               ", "               DE ED               ", "               DE ED               ", "            HH DE ED HH            ", "                                   ", "                                   ", "                                   ", "                                   ", "               X X X               ", "               X X X               ", "               X X X               ", "               X X X               ", "   AAAAAAAAAAAAX X XAAAAAAAAAAAA   ")
                .aisle("                                   ", "                                   ", "                                   ", "                                   ", "                                   ", "                                   ", "                                   ", "                                   ", "                                   ", "                                   ", "                                   ", "                                   ", "                                   ", "                                   ", "                                   ", "                                   ", "                                   ", "                                   ", "                                   ", "                                   ", "                                   ", "                                   ", "                                   ", "                                   ", "                                   ", "                                   ", "                                   ", "                                   ", "                                   ", "                                   ", "                                   ", "                                   ", "                E E                ", "              HDE EDH              ", "               DE ED               ", "               DE ED               ", "               DE ED               ", "                                   ", "                                   ", "                                   ", "                                   ", "                                   ", "    AAAAAAAAAAAAAAAAAAAAAAAAAAA    ")
                .aisle("                                   ", "                                   ", "                                   ", "                                   ", "                                   ", "                                   ", "                                   ", "                                   ", "                                   ", "                                   ", "                                   ", "                                   ", "                                   ", "                                   ", "                                   ", "                                   ", "                                   ", "                                   ", "                                   ", "                                   ", "                                   ", "                                   ", "                                   ", "                                   ", "                                   ", "                                   ", "                                   ", "                                   ", "                                   ", "                                   ", "                                   ", "                                   ", "                                   ", "                                   ", "                                   ", "                E E                ", "               DE ED               ", "               DE ED               ", "               DE ED               ", "                                   ", "                                   ", "                                   ", "     AAAAAAAAAAAAAAAAAAAAAAAAA     ")
                .aisle("                                   ", "                                   ", "                                   ", "                                   ", "                                   ", "                                   ", "                                   ", "                                   ", "                                   ", "                                   ", "                                   ", "                                   ", "                                   ", "                                   ", "                                   ", "                                   ", "                                   ", "                                   ", "                                   ", "                                   ", "                                   ", "                                   ", "                                   ", "                                   ", "                                   ", "                                   ", "                                   ", "                                   ", "                                   ", "                                   ", "                                   ", "                                   ", "                                   ", "                                   ", "                                   ", "                                   ", "                                   ", "                E E                ", "               DE ED               ", "               DE ED               ", "                                   ", "                                   ", "      AAAAAAAAAAAAAAAAAAAAAAA      ")
                .aisle("                                   ", "                                   ", "                                   ", "                                   ", "                                   ", "                                   ", "                                   ", "                                   ", "                                   ", "                                   ", "                                   ", "                                   ", "                                   ", "                                   ", "                                   ", "                                   ", "                                   ", "                                   ", "                                   ", "                                   ", "                                   ", "                                   ", "                                   ", "                                   ", "                                   ", "                                   ", "                                   ", "                                   ", "                                   ", "                                   ", "                                   ", "                                   ", "                                   ", "                                   ", "                                   ", "                                   ", "                                   ", "                                   ", "                E E                ", "               DE ED               ", "               D   D               ", "         FFF           FFF         ", "       AAAAAAAAAAAAAAAAAAAAA       ")
                .aisle("                                   ", "                                   ", "                                   ", "                                   ", "                                   ", "                                   ", "                                   ", "                                   ", "                                   ", "                                   ", "                                   ", "                                   ", "                                   ", "                                   ", "                                   ", "                                   ", "                                   ", "                                   ", "                                   ", "                                   ", "                                   ", "                                   ", "                                   ", "                                   ", "                                   ", "                                   ", "                                   ", "                                   ", "                                   ", "                                   ", "                                   ", "                                   ", "                                   ", "                                   ", "                                   ", "                                   ", "                                   ", "                                   ", "                                   ", "                E E                ", "          DD   DE ED   DD          ", "         FFFFFFD   DFFFFFF         ", "        AAAAAAAAAAAAAAAAAAA        ")
                .aisle("                                   ", "                                   ", "                                   ", "                                   ", "                                   ", "                                   ", "                                   ", "                                   ", "                                   ", "                                   ", "                                   ", "                                   ", "                                   ", "                                   ", "                                   ", "                                   ", "                                   ", "                                   ", "                                   ", "                                   ", "                                   ", "                                   ", "                                   ", "                                   ", "                                   ", "                                   ", "                                   ", "                                   ", "                                   ", "                                   ", "                                   ", "                                   ", "                                   ", "                                   ", "                                   ", "                                   ", "                                   ", "                                   ", "                                   ", "                                   ", "            DDDDE EDDDD            ", "          FFFFFFF FFFFFFF          ", "          AAAAAAAAAAAAAAA          ")
                .aisle("                                   ", "                                   ", "                                   ", "                                   ", "                                   ", "                                   ", "                                   ", "                                   ", "                                   ", "                                   ", "                                   ", "                                   ", "                                   ", "                                   ", "                                   ", "                                   ", "                                   ", "                                   ", "                                   ", "                                   ", "                                   ", "                                   ", "                                   ", "                                   ", "                                   ", "                                   ", "                                   ", "                                   ", "                                   ", "                                   ", "                                   ", "                                   ", "                                   ", "                                   ", "                                   ", "                                   ", "                                   ", "                                   ", "                                   ", "                                   ", "               D   D               ", "            FFFFF FFFFF            ", "            AAAAAAAAAAA            ")
                .aisle("                                   ", "                                   ", "                                   ", "                                   ", "                                   ", "                                   ", "                                   ", "                                   ", "                                   ", "                                   ", "                                   ", "                                   ", "                                   ", "                                   ", "                                   ", "                                   ", "                                   ", "                                   ", "                                   ", "                                   ", "                                   ", "                                   ", "                                   ", "                                   ", "                                   ", "                                   ", "                                   ", "                                   ", "                                   ", "                                   ", "                                   ", "                                   ", "                                   ", "                                   ", "                                   ", "                                   ", "                                   ", "                                   ", "                                   ", "                                   ", "                                   ", "               FF FF               ", "               AAAAA               ")
                .where('~', this.selfPredicate())
                .where('E', states(getCasingState()))
                .where('B', states(getSecondCasingState()))
                .where('X', states(getThirdCasingState()))
                .where('H', states(getFrameState()))
                .where('F', states(getFourthCasingState()))
                .where('C', GTLiteTraceabilityPredicate.SPACE_ELEVATOR_MOTOR.get())
                .where('A', states(getFifthCasingState()))
                .where('D', states(getSixthCasingState()))
                .where('I', states(getSixthCasingState())
                        .or(autoAbilities()))
                .where('-', air())
                .where(' ', any())
                .build();
    }

    private static IBlockState getCasingState() {
        return GTLiteMetaBlocks.SPACE_ELEVATOR_CASING.getState(BlockSpaceElevatorCasing.ElevatorCasingType.SUPPORT_STRUCTURE);
    }

    private static IBlockState getSecondCasingState() {
        return GTLiteMetaBlocks.SPACE_ELEVATOR_CASING.getState(BlockSpaceElevatorCasing.ElevatorCasingType.CABLE_CASING);
    }

    private static IBlockState getThirdCasingState() {
        return GTLiteMetaBlocks.SPACE_ELEVATOR_CASING.getState(BlockSpaceElevatorCasing.ElevatorCasingType.SUPPORT_STRUCTURE);
    }

    private static IBlockState getFourthCasingState() {
        return GTLiteMetaBlocks.SPACE_ELEVATOR_CASING.getState(BlockSpaceElevatorCasing.ElevatorCasingType.INTERNAL_STRUCTURE);
    }

    private static IBlockState getFifthCasingState() {
        return GTLiteMetaBlocks.SPACE_ELEVATOR_CASING.getState(BlockSpaceElevatorCasing.ElevatorCasingType.FLOOR);
    }

    private static IBlockState getSixthCasingState() {
        return GTLiteMetaBlocks.SPACE_ELEVATOR_CASING.getState(BlockSpaceElevatorCasing.ElevatorCasingType.BASIC_CASING);
    }

    private static IBlockState getFrameState() {
        return MetaBlocks.FRAMES.get(GTLiteMaterials.MARM200Steel).getBlock(GTLiteMaterials.MARM200Steel);
    }

    @SideOnly(Side.CLIENT)
    @Override
    public ICubeRenderer getBaseTexture(IMultiblockPart iMultiblockPart) {
        return GTLiteTextures.SPACE_ELEVATOR_CASING;
    }

    @SideOnly(Side.CLIENT)
    @Nonnull
    @Override
    protected ICubeRenderer getFrontOverlay() {
        return GTLiteTextures.SPACE_ELEVATOR_OVERLAY;
    }

    @Override
    public void addInformation(ItemStack stack,
                               @Nullable World player,
                               @Nonnull List<String> tooltip,
                               boolean advanced) {
        super.addInformation(stack, player, tooltip, advanced);
        tooltip.add(I18n.format("gtlitecore.machine.space_elevator.tooltip.1"));
        tooltip.add(I18n.format("gtlitecore.machine.space_elevator.tooltip.2"));
        tooltip.add(I18n.format("gtlitecore.machine.space_elevator.tooltip.3"));
        tooltip.add(I18n.format("gtlitecore.machine.space_elevator.tooltip.4"));
        tooltip.add(I18n.format("gtlitecore.machine.space_elevator.tooltip.5"));
        tooltip.add(I18n.format("gtlitecore.machine.space_elevator.tooltip.6"));
        tooltip.add(I18n.format("gtlitecore.machine.space_elevator.tooltip.7"));
        tooltip.add(I18n.format("gtlitecore.machine.space_elevator.tooltip.8"));
        tooltip.add(I18n.format("gtlitecore.machine.space_elevator.tooltip.9"));
        tooltip.add(I18n.format("gtlitecore.machine.space_elevator.tooltip.10"));
        tooltip.add(I18n.format("gtlitecore.machine.space_elevator.tooltip.11"));
        tooltip.add(I18n.format("gtlitecore.machine.space_elevator.tooltip.12"));
        tooltip.add(I18n.format("gtlitecore.machine.space_elevator.tooltip.13"));
    }

    @Nonnull
    @Override
    protected TextureArea getLogo() {
        return GTLiteGuiTextures.SPACE_ELEVATOR_LOGO;
    }

    @Nonnull
    @Override
    protected TextureArea getWarningLogo() {
        return GTLiteGuiTextures.SPACE_ELEVATOR_LOGO_DARK;
    }

    @Nonnull
    @Override
    protected TextureArea getErrorLogo() {
        return GTLiteGuiTextures.SPACE_ELEVATOR_LOGO_DARK;
    }

    @Override
    public boolean canBeDistinct() {
        return true;
    }

    private class SpaceElevatorRecipeLogic extends MultiblockRecipeLogic {

        public SpaceElevatorRecipeLogic(MetaTileEntitySpaceElevator tileEntity) {
            super(tileEntity);
        }

        private boolean isDrillingModule() {
            return this.getRecipeMap() == GTLiteRecipeMaps.SPACE_ELEVATOR_DRILLING_MODULE;
        }

        private boolean isMiningModule() {
            return this.getRecipeMap() == GTLiteRecipeMaps.SPACE_ELEVATOR_MINING_MODULE;
        }

        private boolean isAssemblingModule() {
            return this.getRecipeMap() == GTLiteRecipeMaps.SPACE_ELEVATOR_ASSEMBLING_MODULE;
        }

        @Override
        public int getParallelLimit() {

            if (isDrillingModule()) {
                return switch (casingTier) {
                    default -> 1;
                    case 2 -> 4;
                    case 3 -> 8;
                    case 4 -> 16;
                    case 5 -> 32;
                };
            } else if (isMiningModule()) {
                return switch (casingTier) {
                    default -> 1;
                    case 2 -> 2;
                    case 3 -> 4;
                    case 4 -> 8;
                    case 5 -> 16;
                };
            } else {
                return switch (casingTier) {
                    default -> 1;
                    case 2 -> 4;
                    case 3 -> 8;
                    case 4 -> 16;
                    case 5 -> 32;
                };
            }
        }
    }
}