package magicbook.gtlitecore.common.metatileentities.multi.electric;

import gregtech.api.capability.impl.MultiblockRecipeLogic;
import gregtech.api.metatileentity.MetaTileEntity;
import gregtech.api.metatileentity.interfaces.IGregTechTileEntity;
import gregtech.api.metatileentity.multiblock.IMultiblockPart;
import gregtech.api.metatileentity.multiblock.MultiMapMultiblockController;
import gregtech.api.pattern.BlockPattern;
import gregtech.api.pattern.FactoryBlockPattern;
import gregtech.api.pattern.MultiblockShapeInfo;
import gregtech.api.pattern.PatternMatchContext;
import gregtech.api.recipes.Recipe;
import gregtech.api.recipes.RecipeMap;
import gregtech.client.renderer.ICubeRenderer;
import gregtech.common.ConfigHolder;
import gregtech.common.blocks.MetaBlocks;
import gregtech.common.metatileentities.MetaTileEntities;
import magicbook.gtlitecore.api.GTLiteAPI;
import magicbook.gtlitecore.api.block.impl.WrappedIntTier;
import magicbook.gtlitecore.api.pattern.GTLiteTraceabilityPredicate;
import magicbook.gtlitecore.api.recipe.GTLiteRecipeMaps;
import magicbook.gtlitecore.api.recipe.properties.GravitonCasingTierProperty;
import magicbook.gtlitecore.api.unification.GTLiteMaterials;
import magicbook.gtlitecore.api.utils.GTLiteUtils;
import magicbook.gtlitecore.client.renderer.texture.GTLiteTextures;
import magicbook.gtlitecore.common.blocks.BlockScienceCasing;
import magicbook.gtlitecore.common.blocks.BlockTransparentCasing;
import magicbook.gtlitecore.common.blocks.GTLiteMetaBlocks;
import magicbook.gtlitecore.common.metatileentities.GTLiteMetaTileEntities;
import net.minecraft.block.state.IBlockState;
import net.minecraft.client.resources.I18n;
import net.minecraft.item.ItemStack;
import net.minecraft.util.EnumFacing;
import net.minecraft.util.ResourceLocation;
import net.minecraft.world.World;
import net.minecraftforge.fml.relauncher.Side;
import net.minecraftforge.fml.relauncher.SideOnly;

import javax.annotation.Nonnull;
import javax.annotation.Nullable;
import java.util.ArrayList;
import java.util.Comparator;
import java.util.List;

import static gregtech.api.GTValues.OpV;

public class MetaTileEntityNicollDysonBeamer extends MultiMapMultiblockController {

    private int casingTier;

    public MetaTileEntityNicollDysonBeamer(ResourceLocation metaTileEntityId) {
        super(metaTileEntityId, new RecipeMap[]{
                GTLiteRecipeMaps.NICOLL_DYSON_BEAMER_BURNING_MODULE,
                GTLiteRecipeMaps.NICOLL_DYSON_BEAMER_FORGING_MODULE,
                GTLiteRecipeMaps.NICOLL_DYSON_BEAMER_OSCILLATING_MODULE});
        this.recipeMapWorkable = new MultiblockRecipeLogic(this, true);
    }

    @Override
    public MetaTileEntity createMetaTileEntity(IGregTechTileEntity tileEntity) {
        return new MetaTileEntityNicollDysonBeamer(metaTileEntityId);
    }

    @Override
    protected void formStructure(PatternMatchContext context) {
        super.formStructure(context);
        Object type = context.get("GravitonCasingTieredStats");
        this.casingTier = GTLiteUtils.getOrDefault(() -> type instanceof WrappedIntTier,
                () -> ((WrappedIntTier) type).getIntTier(), 0);
    }

    @Override
    public void invalidateStructure() {
        super.invalidateStructure();
        this.casingTier = 0;
    }

    @Override
    public boolean checkRecipe(@Nonnull Recipe recipe,
                               boolean consumeIfSuccess) {
        return super.checkRecipe(recipe, consumeIfSuccess) && recipe.getProperty(GravitonCasingTierProperty.getInstance(), 0) <= casingTier;
    }

    @Nonnull
    @Override
    protected BlockPattern createStructurePattern() {
        return FactoryBlockPattern.start()
                .aisle("                                                 ", "                                                 ", "                                                 ", "                                                 ", "                                                 ", "                                                 ", "                    AAAAAAAAA                    ", "                    AAAAAAAAA                    ", "                    AAAAAAAAA                    ", "                                                 ", "                                                 ", "                                                 ", "                                                 ", "                                                 ", "                                                 ")
                .aisle("                                                 ", "                                                 ", "                                                 ", "                                                 ", "                                                 ", "                    AAAAAAAAA                    ", "                 AAABBBBBBBBBAAA                 ", "                 AAABBBBBBBBBAAA                 ", "                 AAABBBBBBBBBAAA                 ", "                    AAAAAAAAA                    ", "                                                 ", "                                                 ", "                                                 ", "                                                 ", "                                                 ")
                .aisle("                                                 ", "                                                 ", "                                                 ", "                                                 ", "                                                 ", "                 AAA         AAA                 ", "               AABBBAAAAAAAAABBBAA               ", "               AABBBAAAAAAAAABBBAA               ", "               AABBBAAAAAAAAABBBAA               ", "                 AAA         AAA                 ", "                                                 ", "                                                 ", "                                                 ", "                                                 ", "                                                 ")
                .aisle("                                                 ", "                                                 ", "                                                 ", "                                                 ", "                                                 ", "               AA               AA               ", "              ABBAAA         AAABBA              ", "              ABBAAA         AAABBA              ", "              ABBAAA         AAABBA              ", "               AA               AA               ", "                                                 ", "                                                 ", "                                                 ", "                                                 ", "                                                 ")
                .aisle("                                                 ", "                                                 ", "                                                 ", "                                                 ", "                                                 ", "                                                 ", "              AAA               AAA              ", "              AAA               AAA              ", "              AAA               AAA              ", "                                                 ", "                                                 ", "                                                 ", "                                                 ", "                                                 ", "                                                 ")
                .aisle("                                                 ", "                                                 ", "                                                 ", "                                                 ", "                                                 ", "                                                 ", "                                                 ", "                                                 ", "                                                 ", "                                                 ", "                                                 ", "                                                 ", "                                                 ", "                                                 ", "                                                 ")
                .aisle("                                                 ", "                                                 ", "                                                 ", "                                                 ", "                                                 ", "                                                 ", "                                                 ", "                    AAAAAAAAA                    ", "                                                 ", "                                                 ", "                                                 ", "                                                 ", "                                                 ", "                                                 ", "                                                 ")
                .aisle("                                                 ", "                                                 ", "                                                 ", "                                                 ", "                                                 ", "                                                 ", "                    AAAAAAAAA                    ", "                 AAABBBBBBBBBAAA                 ", "                    AAAAAAAAA                    ", "                                                 ", "                                                 ", "                                                 ", "                                                 ", "                                                 ", "                                                 ")
                .aisle("                                                 ", "                                                 ", "                                                 ", "                                                 ", "                                                 ", "                                                 ", "                 AAA         AAA                 ", "               AABBBAAAAAAAAABBBAA               ", "                 AAA         AAA                 ", "                                                 ", "                                                 ", "                                                 ", "                                                 ", "                                                 ", "                                                 ")
                .aisle("                                                 ", "                                                 ", "                                                 ", "                                                 ", "                                                 ", "                                                 ", "               AA               AA               ", "              ABBAAA   C C   AAABBA              ", "               AA               AA               ", "                                                 ", "                                                 ", "                                                 ", "                                                 ", "                                                 ", "                                                 ")
                .aisle("                                                 ", "                                                 ", "                                                 ", "                                                 ", "                                                 ", "                                                 ", "              A                   A              ", "             ABAA      C C      AABA             ", "              A                   A              ", "                                                 ", "                                                 ", "                                                 ", "                                                 ", "                                                 ", "                                                 ")
                .aisle("                                                 ", "                                                 ", "                                                 ", "                                                 ", "                                                 ", "                                                 ", "             A                     A             ", "            ABA        C C        ABA            ", "             A                     A             ", "                                                 ", "                                                 ", "                                                 ", "                                                 ", "                                                 ", "                                                 ")
                .aisle("                                                 ", "                                                 ", "                                                 ", "                                                 ", "                                                 ", "                                                 ", "            A                       A            ", "           ABA       AAAAAAA       ABA           ", "            A                       A            ", "                                                 ", "                                                 ", "                                                 ", "                                                 ", "                                                 ", "                                                 ")
                .aisle("                                                 ", "                                                 ", "                                                 ", "                                                 ", "                                                 ", "                                                 ", "           A                         A           ", "          ABA     AAADDDDDDDAAA     ABA          ", "           A                         A           ", "                                                 ", "                                                 ", "                                                 ", "                                                 ", "                                                 ", "                                                 ")
                .aisle("                                                 ", "                                                 ", "                                                 ", "                                                 ", "                                                 ", "                                                 ", "   AA     A                           A          ", "   AA    ABA    AADDDAAAAAAADDDAA    ABA    AA   ", "   AA     A                           A     AA   ", "                                                 ", "                                                 ", "                                                 ", "                                                 ", "                                                 ", "                                                 ")
                .aisle("                                                 ", "                                                 ", "                                                 ", "                                                 ", "                                                 ", "   A                                         A   ", "  ABA    A                             A     A   ", "  ABA   ABA    ADDAAAGGGGGGGAAADDA    ABA   ABA  ", "  ABA    A                             A    ABA  ", "   A                                         A   ", "                                                 ", "                                                 ", "                                                 ", "                                                 ", "                                                 ")
                .aisle("                                                 ", "                                                 ", "                                                 ", "                                                 ", "                                                 ", "   A                                         A   ", "  ABA    A                             A     A   ", "  ABA   ABA   ADDAGGG       GGGADDA   ABA   ABA  ", "  ABA    A                             A    ABA  ", "   A                                         A   ", "                                                 ", "                                                 ", "                                                 ", "                                                 ", "                                                 ")
                .aisle("                                                 ", "                                                 ", "                                                 ", "                                                 ", "                                                 ", "  A                                           A  ", " ABA    A                               A     A  ", " ABA   ABA    ADAG             GADA    ABA   ABA ", " ABA    A                               A    ABA ", "  A                                           A  ", "                                                 ", "                                                 ", "                                                 ", "                                                 ", "                                                 ")
                .aisle("                                                 ", "                                                 ", "                                                 ", "                                                 ", "                                                 ", "  A                                           A  ", " ABA    A                               A     A  ", " ABA   ABA   ADAG               GADA   ABA   ABA ", " ABA    A                               A    ABA ", "  A                                           A  ", "                                                 ", "                                                 ", "                                                 ", "                                                 ", "                                                 ")
                .aisle("                                                 ", "                                                 ", "                                                 ", "                                                 ", "                                                 ", "  A                                           A  ", " ABA    A                               A     A  ", " ABA   ABA   ADAG               GADA   ABA   ABA ", " ABA    A                               A    ABA ", "  A                                           A  ", "                                                 ", "                                                 ", "                                                 ", "                                                 ", "                                                 ")
                .aisle("                                                 ", "                                                 ", "                                                 ", "                                                 ", "                                                 ", " A                    AAAAA                    A ", "ABA    A              EEEEE              A     A ", "ABA   ABA    ADAG     FFFFF     GADA    ABA   ABA", "ABA    A              EEEEE              A    ABA", " A                    AAAAA                    A ", "                      EEEEE                      ", "                                                 ", "                                                 ", "                                                 ", "                                                 ")
                .aisle("                                                 ", "                                                 ", "                                                 ", "                      FFFFF                      ", "                      EEEEE                      ", " A                   A     A                   A ", "ABA    A             E     E             A     A ", "ABA   ABA   ADAG     F     F     GADA   ABA   ABA", "ABA    A             E     E             A    ABA", " A                   A     A                   A ", "                     E     E                     ", "                      FFFFF                      ", "                      EEEEE                      ", "                                                 ", "                                                 ")
                .aisle("                                                 ", "                      AAAAA                      ", "                      EEEEE                      ", "                     F     F                     ", "                     E     E                     ", " A                  A       A                  A ", "ABA    A            E       E            A     A ", "ABA   ABA   ADAG    F       F    GADA   ABA   ABA", "ABA    A            E       E            A    ABA", " A                  A       A                  A ", "                    E       E                    ", "                     F     F                     ", "                     E     E                     ", "                      AAAAA                      ", "                                                 ")
                .aisle("                       DDD                       ", "                      A   A                      ", "                      E   E                      ", "                     F     F                     ", "                     E     E                     ", " A                  A       A                  A ", "ABA    A            E       E            A     A ", "ABA   ABACCCADAG    F       F    GADACCCABA   ABA", "ABA    A            E       E            A    ABA", " A                  A       A                  A ", "                    E       E                    ", "                     F     F                     ", "                     E     E                     ", "                      A   A                      ", "                       DDD                       ")
                .aisle("                       DAD                       ", "                      A   A                      ", "                      E   E                      ", "                     F     F                     ", "                     E     E                     ", " A                  A       A                  A ", "ABA    A            E       E            A     A ", "ABA   ABA   ADAG    F       F    GADA   ABA   ABA", "ABA    A            E       E            A    ABA", " A                  A       A                  A ", "                    E       E                    ", "                     F     F                     ", "                     E     E                     ", "                      A   A                      ", "                       DAD                       ")
                .aisle("                       DDD                       ", "                      A   A                      ", "                      E   E                      ", "                     F     F                     ", "                     E     E                     ", " A                  A       A                  A ", "ABA    A            E       E            A     A ", "ABA   ABACCCADAG    F       F    GADACCCABA   ABA", "ABA    A            E       E            A    ABA", " A                  A       A                  A ", "                    E       E                    ", "                     F     F                     ", "                     E     E                     ", "                      A   A                      ", "                       DDD                       ")
                .aisle("                                                 ", "                      AAAAA                      ", "                      EEEEE                      ", "                     F     F                     ", "                     E     E                     ", " A                  A       A                  A ", "ABA    A            E       E            A     A ", "ABA   ABA   ADAG    F       F    GADA   ABA   ABA", "ABA    A            E       E            A    ABA", " A                  A       A                  A ", "                    E       E                    ", "                     F     F                     ", "                     E     E                     ", "                      AAAAA                      ", "                                                 ")
                .aisle("                                                 ", "                                                 ", "                                                 ", "                      FFFFF                      ", "                      EEEEE                      ", " A                   A     A                   A ", "ABA    A             E     E             A     A ", "ABA   ABA   ADAG     F     F     GADA   ABA   ABA", "ABA    A             E     E             A    ABA", " A                   A     A                   A ", "                     E     E                     ", "                      FFFFF                      ", "                      EEEEE                      ", "                                                 ", "                                                 ")
                .aisle("                                                 ", "                                                 ", "                                                 ", "                                                 ", "                                                 ", " A                    AAAAA                    A ", "ABA    A              EEEEE              A     A ", "ABA   ABA    ADAG     FFSFF     GADA    ABA   ABA", "ABA    A              EEEEE              A    ABA", " A                    AAAAA                    A ", "                      EEEEE                      ", "                                                 ", "                                                 ", "                                                 ", "                                                 ")
                .aisle("                                                 ", "                                                 ", "                                                 ", "                                                 ", "                                                 ", "  A                                           A  ", " ABA    A                               A     A  ", " ABA   ABA   ADAG               GADA   ABA   ABA ", " ABA    A                               A    ABA ", "  A                                           A  ", "                                                 ", "                                                 ", "                                                 ", "                                                 ", "                                                 ")
                .aisle("                                                 ", "                                                 ", "                                                 ", "                                                 ", "                                                 ", "  A                                           A  ", " ABA    A                               A     A  ", " ABA   ABA   ADAG               GADA   ABA   ABA ", " ABA    A                               A    ABA ", "  A                                           A  ", "                                                 ", "                                                 ", "                                                 ", "                                                 ", "                                                 ")
                .aisle("                                                 ", "                                                 ", "                                                 ", "                                                 ", "                                                 ", "  A                                           A  ", " ABA    A                               A     A  ", " ABA   ABA    ADAG             GADA    ABA   ABA ", " ABA    A                               A    ABA ", "  A                                           A  ", "                                                 ", "                                                 ", "                                                 ", "                                                 ", "                                                 ")
                .aisle("                                                 ", "                                                 ", "                                                 ", "                                                 ", "                                                 ", "   A                                         A   ", "  ABA    A                             A     A   ", "  ABA   ABA   ADDAGGG       GGGADDA   ABA   ABA  ", "  ABA    A                             A    ABA  ", "   A                                         A   ", "                                                 ", "                                                 ", "                                                 ", "                                                 ", "                                                 ")
                .aisle("                                                 ", "                                                 ", "                                                 ", "                                                 ", "                                                 ", "   A                                         A   ", "  ABA    A                             A     A   ", "  ABA   ABA    ADDAAAGGGGGGGAAADDA    ABA   ABA  ", "  ABA    A                             A    ABA  ", "   A                                         A   ", "                                                 ", "                                                 ", "                                                 ", "                                                 ", "                                                 ")
                .aisle("                                                 ", "                                                 ", "                                                 ", "                                                 ", "                                                 ", "                                                 ", "   AA     A                           A          ", "   AA    ABA    AADDDAAAAAAADDDAA    ABA    AA   ", "   AA     A                           A     AA   ", "                                                 ", "                                                 ", "                                                 ", "                                                 ", "                                                 ", "                                                 ")
                .aisle("                                                 ", "                                                 ", "                                                 ", "                                                 ", "                                                 ", "                                                 ", "           A                         A           ", "          ABA     AAADDDDDDDAAA     ABA          ", "           A                         A           ", "                                                 ", "                                                 ", "                                                 ", "                                                 ", "                                                 ", "                                                 ")
                .aisle("                                                 ", "                                                 ", "                                                 ", "                                                 ", "                                                 ", "                                                 ", "            A                       A            ", "           ABA       AAAAAAA       ABA           ", "            A                       A            ", "                                                 ", "                                                 ", "                                                 ", "                                                 ", "                                                 ", "                                                 ")
                .aisle("                                                 ", "                                                 ", "                                                 ", "                                                 ", "                                                 ", "                                                 ", "             A                     A             ", "            ABA        C C        ABA            ", "             A                     A             ", "                                                 ", "                                                 ", "                                                 ", "                                                 ", "                                                 ", "                                                 ")
                .aisle("                                                 ", "                                                 ", "                                                 ", "                                                 ", "                                                 ", "                                                 ", "              A                   A              ", "             ABAA      C C      AABA             ", "              A                   A              ", "                                                 ", "                                                 ", "                                                 ", "                                                 ", "                                                 ", "                                                 ")
                .aisle("                                                 ", "                                                 ", "                                                 ", "                                                 ", "                                                 ", "                                                 ", "               AA               AA               ", "              ABBAAA   C C   AAABBA              ", "               AA               AA               ", "                                                 ", "                                                 ", "                                                 ", "                                                 ", "                                                 ", "                                                 ")
                .aisle("                                                 ", "                                                 ", "                                                 ", "                                                 ", "                                                 ", "                                                 ", "                 AAA         AAA                 ", "               AABBBAAAAAAAAABBBAA               ", "                 AAA         AAA                 ", "                                                 ", "                                                 ", "                                                 ", "                                                 ", "                                                 ", "                                                 ")
                .aisle("                                                 ", "                                                 ", "                                                 ", "                                                 ", "                                                 ", "                                                 ", "                    AAAAAAAAA                    ", "                 AAABBBBBBBBBAAA                 ", "                    AAAAAAAAA                    ", "                                                 ", "                                                 ", "                                                 ", "                                                 ", "                                                 ", "                                                 ")
                .aisle("                                                 ", "                                                 ", "                                                 ", "                                                 ", "                                                 ", "                                                 ", "                                                 ", "                    AAAAAAAAA                    ", "                                                 ", "                                                 ", "                                                 ", "                                                 ", "                                                 ", "                                                 ", "                                                 ")
                .aisle("                                                 ", "                                                 ", "                                                 ", "                                                 ", "                                                 ", "                                                 ", "                                                 ", "                                                 ", "                                                 ", "                                                 ", "                                                 ", "                                                 ", "                                                 ", "                                                 ", "                                                 ")
                .aisle("                                                 ", "                                                 ", "                                                 ", "                                                 ", "                                                 ", "                                                 ", "              AAA               AAA              ", "              AAA               AAA              ", "              AAA               AAA              ", "                                                 ", "                                                 ", "                                                 ", "                                                 ", "                                                 ", "                                                 ")
                .aisle("                                                 ", "                                                 ", "                                                 ", "                                                 ", "                                                 ", "               AA               AA               ", "              ABBAAA         AAABBA              ", "              ABBAAA         AAABBA              ", "              ABBAAA         AAABBA              ", "               AA               AA               ", "                                                 ", "                                                 ", "                                                 ", "                                                 ", "                                                 ")
                .aisle("                                                 ", "                                                 ", "                                                 ", "                                                 ", "                                                 ", "                 AAA         AAA                 ", "               AABBBAAAAAAAAABBBAA               ", "               AABBBAAAAAAAAABBBAA               ", "               AABBBAAAAAAAAABBBAA               ", "                 AAA         AAA                 ", "                                                 ", "                                                 ", "                                                 ", "                                                 ", "                                                 ")
                .aisle("                                                 ", "                                                 ", "                                                 ", "                                                 ", "                                                 ", "                    AAAAAAAAA                    ", "                 AAABBBBBBBBBAAA                 ", "                 AAABBBBBBBBBAAA                 ", "                 AAABBBBBBBBBAAA                 ", "                    AAAAAAAAA                    ", "                                                 ", "                                                 ", "                                                 ", "                                                 ", "                                                 ")
                .aisle("                                                 ", "                                                 ", "                                                 ", "                                                 ", "                                                 ", "                                                 ", "                    AAAAAAAAA                    ", "                    AAAAAAAAA                    ", "                    AAAAAAAAA                    ", "                                                 ", "                                                 ", "                                                 ", "                                                 ", "                                                 ", "                                                 ")
                .where('S', this.selfPredicate())
                .where('A', states(getCasingState())
                        .setMinGlobalLimited(1200)
                        .or(autoAbilities()))
                .where('B', states(getSecondCasingState()))
                .where('C', states(getFrameState()))
                .where('D', states(getThirdCasingState()))
                .where('E', states(getGlassState()))
                .where('F', states(getFourthCasingState()))
                .where('G', GTLiteTraceabilityPredicate.GRAVITON_CASING.get())
                .where(' ', any())
                .build();
    }

    private static IBlockState getCasingState() {
        return GTLiteMetaBlocks.SCIENCE_CASING.getState(BlockScienceCasing.ScienceCasingType.SINGULARITY_REINFORCED_STELLAR_SHIELDING_CASING);
    }

    private static IBlockState getSecondCasingState() {
        return GTLiteMetaBlocks.SCIENCE_CASING.getState(BlockScienceCasing.ScienceCasingType.CELESTIAL_MATTER_GUIDANCE_CASING);
    }

    private static IBlockState getThirdCasingState() {
        return GTLiteMetaBlocks.SCIENCE_CASING.getState(BlockScienceCasing.ScienceCasingType.BOUNDLESS_GRAVITATIONALLY_SEVERED_STRUCTURE_CASING);
    }

    private static IBlockState getFourthCasingState() {
        return GTLiteMetaBlocks.SCIENCE_CASING.getState(BlockScienceCasing.ScienceCasingType.TRANSCENDENTALLY_AMPLIFIED_MAGNETIC_CONFINEMENT_CASING);
    }

    private static IBlockState getFrameState() {
        return MetaBlocks.FRAMES.get(GTLiteMaterials.TranscendentMetal).getBlock(GTLiteMaterials.TranscendentMetal);
    }

    private static IBlockState getGlassState() {
        return GTLiteMetaBlocks.TRANSPARENT_CASING.getState(BlockTransparentCasing.TransparentCasingType.SPATIALLY_TRANSCENDENT_GRAVITATIONAL_LENS);
    }

    @SideOnly(Side.CLIENT)
    @Override
    public ICubeRenderer getBaseTexture(IMultiblockPart iMultiblockPart) {
        return iMultiblockPart == null ? GTLiteTextures.TRANSCENDENTALLY_AMPLIFIED_MAGNETIC_CONFINEMENT_CASING : GTLiteTextures.SINGULARITY_REINFORCED_STELLAR_SHIELDING_CASING;
    }

    @SideOnly(Side.CLIENT)
    @Nonnull
    @Override
    protected ICubeRenderer getFrontOverlay() {
        return GTLiteTextures.NICOLL_DYSON_BEAMER_OVERLAY;
    }

    @Override
    public void addInformation(ItemStack stack,
                               @Nullable World player,
                               @Nonnull List<String> tooltip,
                               boolean advanced) {
        super.addInformation(stack, player, tooltip, advanced);
        tooltip.add(I18n.format("gtlitecore.machine.nicoll_dyson_beamer.tooltip.1"));
        tooltip.add(I18n.format("gtlitecore.machine.nicoll_dyson_beamer.tooltip.2"));
        tooltip.add(I18n.format("gtlitecore.machine.nicoll_dyson_beamer.tooltip.3"));
        tooltip.add(I18n.format("gtlitecore.machine.nicoll_dyson_beamer.tooltip.4"));
        tooltip.add(I18n.format("gtlitecore.machine.nicoll_dyson_beamer.tooltip.5"));
    }

    @Override
    public boolean canBeDistinct() {
        return true;
    }

    @Override
    public List<MultiblockShapeInfo> getMatchingShapes() {
        ArrayList<MultiblockShapeInfo> shapeInfo = new ArrayList<>();
        MultiblockShapeInfo.Builder builder = MultiblockShapeInfo.builder()
                .aisle("                                                 ", "                                                 ", "                                                 ", "                                                 ", "                                                 ", "                                                 ", "                    AAAAAAAAA                    ", "                    AAAAAAAAA                    ", "                    AAAAAAAAA                    ", "                                                 ", "                                                 ", "                                                 ", "                                                 ", "                                                 ", "                                                 ")
                .aisle("                                                 ", "                                                 ", "                                                 ", "                                                 ", "                                                 ", "                    AAAAAAAAA                    ", "                 AAABBBBBBBBBAAA                 ", "                 AAABBBBBBBBBAAA                 ", "                 AAABBBBBBBBBAAA                 ", "                    AAAAAAAAA                    ", "                                                 ", "                                                 ", "                                                 ", "                                                 ", "                                                 ")
                .aisle("                                                 ", "                                                 ", "                                                 ", "                                                 ", "                                                 ", "                 AAA         AAA                 ", "               AABBBAAAAAAAAABBBAA               ", "               AABBBAAAAAAAAABBBAA               ", "               AABBBAAAAAAAAABBBAA               ", "                 AAA         AAA                 ", "                                                 ", "                                                 ", "                                                 ", "                                                 ", "                                                 ")
                .aisle("                                                 ", "                                                 ", "                                                 ", "                                                 ", "                                                 ", "               AA               AA               ", "              ABBAAA         AAABBA              ", "              ABBAAA         AAABBA              ", "              ABBAAA         AAABBA              ", "               AA               AA               ", "                                                 ", "                                                 ", "                                                 ", "                                                 ", "                                                 ")
                .aisle("                                                 ", "                                                 ", "                                                 ", "                                                 ", "                                                 ", "                                                 ", "              AAA               AAA              ", "              AAA               AAA              ", "              AAA               AAA              ", "                                                 ", "                                                 ", "                                                 ", "                                                 ", "                                                 ", "                                                 ")
                .aisle("                                                 ", "                                                 ", "                                                 ", "                                                 ", "                                                 ", "                                                 ", "                                                 ", "                                                 ", "                                                 ", "                                                 ", "                                                 ", "                                                 ", "                                                 ", "                                                 ", "                                                 ")
                .aisle("                                                 ", "                                                 ", "                                                 ", "                                                 ", "                                                 ", "                                                 ", "                                                 ", "                    AAAKKKAAA                    ", "                                                 ", "                                                 ", "                                                 ", "                                                 ", "                                                 ", "                                                 ", "                                                 ")
                .aisle("                                                 ", "                                                 ", "                                                 ", "                                                 ", "                                                 ", "                                                 ", "                    AAAAAAAAA                    ", "                 AAABBBBBBBBBAAA                 ", "                    AAAAAAAAA                    ", "                                                 ", "                                                 ", "                                                 ", "                                                 ", "                                                 ", "                                                 ")
                .aisle("                                                 ", "                                                 ", "                                                 ", "                                                 ", "                                                 ", "                                                 ", "                 AAA         AAA                 ", "               AABBBAAAAAAAAABBBAA               ", "                 AAA         AAA                 ", "                                                 ", "                                                 ", "                                                 ", "                                                 ", "                                                 ", "                                                 ")
                .aisle("                                                 ", "                                                 ", "                                                 ", "                                                 ", "                                                 ", "                                                 ", "               AA               AA               ", "              ABBAAA   C C   AAABBA              ", "               AA               AA               ", "                                                 ", "                                                 ", "                                                 ", "                                                 ", "                                                 ", "                                                 ")
                .aisle("                                                 ", "                                                 ", "                                                 ", "                                                 ", "                                                 ", "                                                 ", "              A                   A              ", "             ABAA      C C      AABA             ", "              A                   A              ", "                                                 ", "                                                 ", "                                                 ", "                                                 ", "                                                 ", "                                                 ")
                .aisle("                                                 ", "                                                 ", "                                                 ", "                                                 ", "                                                 ", "                                                 ", "             A                     A             ", "            ABA        C C        ABA            ", "             A                     A             ", "                                                 ", "                                                 ", "                                                 ", "                                                 ", "                                                 ", "                                                 ")
                .aisle("                                                 ", "                                                 ", "                                                 ", "                                                 ", "                                                 ", "                                                 ", "            A                       A            ", "           ABA       AAAAAAA       ABA           ", "            A                       A            ", "                                                 ", "                                                 ", "                                                 ", "                                                 ", "                                                 ", "                                                 ")
                .aisle("                                                 ", "                                                 ", "                                                 ", "                                                 ", "                                                 ", "                                                 ", "           A                         A           ", "          ABA     AAADDDDDDDAAA     ABA          ", "           A                         A           ", "                                                 ", "                                                 ", "                                                 ", "                                                 ", "                                                 ", "                                                 ")
                .aisle("                                                 ", "                                                 ", "                                                 ", "                                                 ", "                                                 ", "                                                 ", "   AA     A                           A          ", "   AA    ABA    AADDDAAAAAAADDDAA    ABA    AA   ", "   AA     A                           A     AA   ", "                                                 ", "                                                 ", "                                                 ", "                                                 ", "                                                 ", "                                                 ")
                .aisle("                                                 ", "                                                 ", "                                                 ", "                                                 ", "                                                 ", "   A                                         A   ", "  ABA    A                             A     A   ", "  ABA   ABA    ADDAAAGGGGGGGAAADDA    ABA   ABA  ", "  ABA    A                             A    ABA  ", "   A                                         A   ", "                                                 ", "                                                 ", "                                                 ", "                                                 ", "                                                 ")
                .aisle("                                                 ", "                                                 ", "                                                 ", "                                                 ", "                                                 ", "   A                                         A   ", "  ABA    A                             A     A   ", "  ABA   ABA   ADDAGGG       GGGADDA   ABA   ABA  ", "  ABA    A                             A    ABA  ", "   A                                         A   ", "                                                 ", "                                                 ", "                                                 ", "                                                 ", "                                                 ")
                .aisle("                                                 ", "                                                 ", "                                                 ", "                                                 ", "                                                 ", "  A                                           A  ", " ABA    A                               A     A  ", " ABA   ABA    ADAG             GADA    ABA   ABA ", " ABA    A                               A    ABA ", "  A                                           A  ", "                                                 ", "                                                 ", "                                                 ", "                                                 ", "                                                 ")
                .aisle("                                                 ", "                                                 ", "                                                 ", "                                                 ", "                                                 ", "  A                                           A  ", " ABA    A                               A     A  ", " ABA   ABA   ADAG               GADA   ABA   ABA ", " ABA    A                               A    ABA ", "  A                                           A  ", "                                                 ", "                                                 ", "                                                 ", "                                                 ", "                                                 ")
                .aisle("                                                 ", "                                                 ", "                                                 ", "                                                 ", "                                                 ", "  A                                           A  ", " ABA    A                               A     A  ", " ABA   ABA   ADAG               GADA   ABA   ABA ", " ABA    A                               A    ABA ", "  A                                           A  ", "                                                 ", "                                                 ", "                                                 ", "                                                 ", "                                                 ")
                .aisle("                                                 ", "                                                 ", "                                                 ", "                                                 ", "                                                 ", " A                    AAAAA                    A ", "ABA    A              EEEEE              A     A ", "ABA   ABA    ADAG     FFFFF     GADA    ABA   ABA", "ABA    A              EEEEE              A    ABA", " A                    AAAAA                    A ", "                      EEEEE                      ", "                                                 ", "                                                 ", "                                                 ", "                                                 ")
                .aisle("                                                 ", "                                                 ", "                                                 ", "                      FFFFF                      ", "                      EEEEE                      ", " A                   A     A                   A ", "ABA    A             E     E             A     A ", "ABA   ABA   ADAG     F     F     GADA   ABA   ABA", "ABA    A             E     E             A    ABA", " A                   A     A                   A ", "                     E     E                     ", "                      FFFFF                      ", "                      EEEEE                      ", "                                                 ", "                                                 ")
                .aisle("                                                 ", "                      AAAAA                      ", "                      EEEEE                      ", "                     F     F                     ", "                     E     E                     ", " A                  A       A                  A ", "ABA    A            E       E            A     A ", "ABA   ABA   ADAG    F       F    GADA   ABA   ABA", "ABA    A            E       E            A    ABA", " A                  A       A                  A ", "                    E       E                    ", "                     F     F                     ", "                     E     E                     ", "                      AAAAA                      ", "                                                 ")
                .aisle("                       DDD                       ", "                      A   A                      ", "                      E   E                      ", "                     F     F                     ", "                     E     E                     ", " A                  A       A                  A ", "ABA    A            E       E            A     A ", "ABA   ABACCCADAG    F       F    GADACCCABA   ABA", "ABA    A            E       E            A    ABA", " A                  A       A                  A ", "                    E       E                    ", "                     F     F                     ", "                     E     E                     ", "                      A   A                      ", "                       DDD                       ")
                .aisle("                       DAD                       ", "                      A   A                      ", "                      E   E                      ", "                     F     F                     ", "                     E     E                     ", " A                  A       A                  A ", "ABA    A            E       E            A     A ", "ABA   ABA   ADAG    F       F    GADA   ABA   ABA", "ABA    A            E       E            A    ABA", " A                  A       A                  A ", "                    E       E                    ", "                     F     F                     ", "                     E     E                     ", "                      A   A                      ", "                       DAD                       ")
                .aisle("                       DDD                       ", "                      A   A                      ", "                      E   E                      ", "                     F     F                     ", "                     E     E                     ", " A                  A       A                  A ", "ABA    A            E       E            A     A ", "ABA   ABACCCADAG    F       F    GADACCCABA   ABA", "ABA    A            E       E            A    ABA", " A                  A       A                  A ", "                    E       E                    ", "                     F     F                     ", "                     E     E                     ", "                      A   A                      ", "                       DDD                       ")
                .aisle("                                                 ", "                      AAAAA                      ", "                      EEEEE                      ", "                     F     F                     ", "                     E     E                     ", " A                  A       A                  A ", "ABA    A            E       E            A     A ", "ABA   ABA   ADAG    F       F    GADA   ABA   ABA", "ABA    A            E       E            A    ABA", " A                  A       A                  A ", "                    E       E                    ", "                     F     F                     ", "                     E     E                     ", "                      AAAAA                      ", "                                                 ")
                .aisle("                                                 ", "                                                 ", "                                                 ", "                      FFFFF                      ", "                      EEEEE                      ", " A                   A     A                   A ", "ABA    A             E     E             A     A ", "ABA   ABA   ADAG     F     F     GADA   ABA   ABA", "ABA    A             E     E             A    ABA", " A                   A     A                   A ", "                     E     E                     ", "                      FFFFF                      ", "                      EEEEE                      ", "                                                 ", "                                                 ")
                .aisle("                                                 ", "                                                 ", "                                                 ", "                                                 ", "                                                 ", " A                    AAAAA                    A ", "ABA    A              EEEEE              A     A ", "ABA   ABA    ADAG     FFSFF     GADA    ABA   ABA", "ABA    A              EEEEE              A    ABA", " A                    AAAAA                    A ", "                      EEEEE                      ", "                                                 ", "                                                 ", "                                                 ", "                                                 ")
                .aisle("                                                 ", "                                                 ", "                                                 ", "                                                 ", "                                                 ", "  A                                           A  ", " ABA    A                               A     A  ", " ABA   ABA   ADAG               GADA   ABA   ABA ", " ABA    A                               A    ABA ", "  A                                           A  ", "                                                 ", "                                                 ", "                                                 ", "                                                 ", "                                                 ")
                .aisle("                                                 ", "                                                 ", "                                                 ", "                                                 ", "                                                 ", "  A                                           A  ", " ABA    A                               A     A  ", " ABA   ABA   ADAG               GADA   ABA   ABA ", " ABA    A                               A    ABA ", "  A                                           A  ", "                                                 ", "                                                 ", "                                                 ", "                                                 ", "                                                 ")
                .aisle("                                                 ", "                                                 ", "                                                 ", "                                                 ", "                                                 ", "  A                                           A  ", " ABA    A                               A     A  ", " ABA   ABA    ADAG             GADA    ABA   ABA ", " ABA    A                               A    ABA ", "  A                                           A  ", "                                                 ", "                                                 ", "                                                 ", "                                                 ", "                                                 ")
                .aisle("                                                 ", "                                                 ", "                                                 ", "                                                 ", "                                                 ", "   A                                         A   ", "  ABA    A                             A     A   ", "  ABA   ABA   ADDAGGG       GGGADDA   ABA   ABA  ", "  ABA    A                             A    ABA  ", "   A                                         A   ", "                                                 ", "                                                 ", "                                                 ", "                                                 ", "                                                 ")
                .aisle("                                                 ", "                                                 ", "                                                 ", "                                                 ", "                                                 ", "   A                                         A   ", "  ABA    A                             A     A   ", "  ABA   ABA    ADDAAAGGGGGGGAAADDA    ABA   ABA  ", "  ABA    A                             A    ABA  ", "   A                                         A   ", "                                                 ", "                                                 ", "                                                 ", "                                                 ", "                                                 ")
                .aisle("                                                 ", "                                                 ", "                                                 ", "                                                 ", "                                                 ", "                                                 ", "   AA     A                           A          ", "   AA    ABA    AADDDAAAAAAADDDAA    ABA    AA   ", "   AA     A                           A     AA   ", "                                                 ", "                                                 ", "                                                 ", "                                                 ", "                                                 ", "                                                 ")
                .aisle("                                                 ", "                                                 ", "                                                 ", "                                                 ", "                                                 ", "                                                 ", "           A                         A           ", "          ABA     AAADDDDDDDAAA     ABA          ", "           A                         A           ", "                                                 ", "                                                 ", "                                                 ", "                                                 ", "                                                 ", "                                                 ")
                .aisle("                                                 ", "                                                 ", "                                                 ", "                                                 ", "                                                 ", "                                                 ", "            A                       A            ", "           ABA       AAAAAAA       ABA           ", "            A                       A            ", "                                                 ", "                                                 ", "                                                 ", "                                                 ", "                                                 ", "                                                 ")
                .aisle("                                                 ", "                                                 ", "                                                 ", "                                                 ", "                                                 ", "                                                 ", "             A                     A             ", "            ABA        C C        ABA            ", "             A                     A             ", "                                                 ", "                                                 ", "                                                 ", "                                                 ", "                                                 ", "                                                 ")
                .aisle("                                                 ", "                                                 ", "                                                 ", "                                                 ", "                                                 ", "                                                 ", "              A                   A              ", "             ABAA      C C      AABA             ", "              A                   A              ", "                                                 ", "                                                 ", "                                                 ", "                                                 ", "                                                 ", "                                                 ")
                .aisle("                                                 ", "                                                 ", "                                                 ", "                                                 ", "                                                 ", "                                                 ", "               AA               AA               ", "              ABBAAA   C C   AAABBA              ", "               AA               AA               ", "                                                 ", "                                                 ", "                                                 ", "                                                 ", "                                                 ", "                                                 ")
                .aisle("                                                 ", "                                                 ", "                                                 ", "                                                 ", "                                                 ", "                                                 ", "                 AAA         AAA                 ", "               AABBBAAAAAAAAABBBAA               ", "                 AAA         AAA                 ", "                                                 ", "                                                 ", "                                                 ", "                                                 ", "                                                 ", "                                                 ")
                .aisle("                                                 ", "                                                 ", "                                                 ", "                                                 ", "                                                 ", "                                                 ", "                    AAAAAAAAA                    ", "                 AAABBBBBBBBBAAA                 ", "                    AAAAAAAAA                    ", "                                                 ", "                                                 ", "                                                 ", "                                                 ", "                                                 ", "                                                 ")
                .aisle("                                                 ", "                                                 ", "                                                 ", "                                                 ", "                                                 ", "                                                 ", "                                                 ", "                    AAAAAAAAA                    ", "                                                 ", "                                                 ", "                                                 ", "                                                 ", "                                                 ", "                                                 ", "                                                 ")
                .aisle("                                                 ", "                                                 ", "                                                 ", "                                                 ", "                                                 ", "                                                 ", "                                                 ", "                                                 ", "                                                 ", "                                                 ", "                                                 ", "                                                 ", "                                                 ", "                                                 ", "                                                 ")
                .aisle("                                                 ", "                                                 ", "                                                 ", "                                                 ", "                                                 ", "                                                 ", "              AAA               AAA              ", "              AAA               AAA              ", "              AAA               AAA              ", "                                                 ", "                                                 ", "                                                 ", "                                                 ", "                                                 ", "                                                 ")
                .aisle("                                                 ", "                                                 ", "                                                 ", "                                                 ", "                                                 ", "               AA               AA               ", "              ABBAAA         AAABBA              ", "              ABBAAA         AAABBA              ", "              ABBAAA         AAABBA              ", "               AA               AA               ", "                                                 ", "                                                 ", "                                                 ", "                                                 ", "                                                 ")
                .aisle("                                                 ", "                                                 ", "                                                 ", "                                                 ", "                                                 ", "                 AAA         AAA                 ", "               AABBBAAAAAAAAABBBAA               ", "               AABBBAAAAAAAAABBBAA               ", "               AABBBAAAAAAAAABBBAA               ", "                 AAA         AAA                 ", "                                                 ", "                                                 ", "                                                 ", "                                                 ", "                                                 ")
                .aisle("                                                 ", "                                                 ", "                                                 ", "                                                 ", "                                                 ", "                    AAAAAAAAA                    ", "                 AAABBBBBBBBBAAA                 ", "                 AAABBBBBBBBBAAA                 ", "                 AAABBBBBBBBBAAA                 ", "                    AAAAAAAAA                    ", "                                                 ", "                                                 ", "                                                 ", "                                                 ", "                                                 ")
                .aisle("                                                 ", "                                                 ", "                                                 ", "                                                 ", "                                                 ", "                                                 ", "                    AAAAAAAAA                    ", "                    AAXYMIJAA                    ", "                    AAAAAAAAA                    ", "                                                 ", "                                                 ", "                                                 ", "                                                 ", "                                                 ", "                                                 ")
                .where('S', GTLiteMetaTileEntities.NICOLL_DYSON_BEAMER, EnumFacing.SOUTH)
                .where('A', getCasingState())
                .where('B', getSecondCasingState())
                .where('C', getFrameState())
                .where('D', getThirdCasingState())
                .where('E', getGlassState())
                .where('F', getFourthCasingState())
                .where('X', MetaTileEntities.ITEM_IMPORT_BUS_ME, EnumFacing.SOUTH)
                .where('Y', MetaTileEntities.ITEM_EXPORT_BUS_ME, EnumFacing.SOUTH)
                .where('I', MetaTileEntities.FLUID_IMPORT_HATCH_ME, EnumFacing.SOUTH)
                .where('J', MetaTileEntities.FLUID_EXPORT_HATCH_ME, EnumFacing.SOUTH)
                .where('K', MetaTileEntities.ENERGY_INPUT_HATCH[OpV], EnumFacing.NORTH)
                .where('M', () -> ConfigHolder.machines.enableMaintenance ? MetaTileEntities.MAINTENANCE_HATCH : getCasingState(), EnumFacing.SOUTH);
        GTLiteAPI.MAP_GRAVITON_CASING.entrySet().stream()
                .sorted(Comparator.comparingInt(entry -> ((WrappedIntTier) entry.getValue()).getIntTier()))
                .forEach(entry -> shapeInfo.add(builder.where('G', entry.getKey()).build()));
        return shapeInfo;
    }
}
