package magicbook.gtlitecore.common.metatileentities.multi.electric.adv;

import gregtech.api.GTValues;
import gregtech.api.capability.GregtechDataCodes;
import gregtech.api.capability.IEnergyContainer;
import gregtech.api.capability.impl.*;
import gregtech.api.metatileentity.MetaTileEntity;
import gregtech.api.metatileentity.interfaces.IGregTechTileEntity;
import gregtech.api.metatileentity.multiblock.IMultiblockPart;
import gregtech.api.metatileentity.multiblock.MultiblockAbility;
import gregtech.api.metatileentity.multiblock.RecipeMapMultiblockController;
import gregtech.api.pattern.BlockPattern;
import gregtech.api.pattern.FactoryBlockPattern;
import gregtech.api.pattern.PatternMatchContext;
import gregtech.api.recipes.Recipe;
import gregtech.api.recipes.RecipeMaps;
import gregtech.api.recipes.recipeproperties.FusionEUToStartProperty;
import gregtech.client.renderer.ICubeRenderer;
import gregtech.client.renderer.texture.Textures;
import gregtech.common.blocks.BlockGlassCasing;
import gregtech.common.blocks.MetaBlocks;
import gregtech.common.metatileentities.MetaTileEntities;
import net.minecraft.block.state.IBlockState;
import net.minecraft.client.resources.I18n;
import net.minecraft.item.ItemStack;
import net.minecraft.nbt.NBTTagCompound;
import net.minecraft.network.PacketBuffer;
import net.minecraft.util.ResourceLocation;
import net.minecraft.util.text.ITextComponent;
import net.minecraft.util.text.TextComponentTranslation;
import net.minecraft.world.World;
import net.minecraftforge.fml.relauncher.Side;
import net.minecraftforge.fml.relauncher.SideOnly;

import javax.annotation.Nonnull;
import javax.annotation.Nullable;
import java.util.Arrays;
import java.util.List;
import java.util.Objects;

import static gregtech.api.GTValues.*;

public class MetaTileEntityCompressedFusionReactor extends RecipeMapMultiblockController {

    private final int tier;
    public final IBlockState casingState;
    public final IBlockState coilState;
    public final IBlockState frameState;
    private EnergyContainerList inputEnergyContainers;
    private long heat = 0;
    private Integer color;

    public MetaTileEntityCompressedFusionReactor(ResourceLocation metaTileEntityId,
                                                 int tier,
                                                 IBlockState casingState,
                                                 IBlockState coilState,
                                                 IBlockState frameState) {
        super(metaTileEntityId, RecipeMaps.FUSION_RECIPES);
        this.recipeMapWorkable = new CompressedFusionReactorRecipeLogic(this);
        this.tier = tier;
        this.casingState = casingState;
        this.coilState = coilState;
        this.frameState = frameState;
        this.energyContainer = new EnergyContainerHandler(this, Integer.MAX_VALUE, 0, 0, 0, 0) {
            @Nonnull
            @Override
            public String getName() {
                return GregtechDataCodes.FUSION_REACTOR_ENERGY_CONTAINER_TRAIT;
            }
        };
    }

    @Override
    public MetaTileEntity createMetaTileEntity(IGregTechTileEntity tileEntity) {
        return new MetaTileEntityCompressedFusionReactor(metaTileEntityId, tier, casingState, coilState, frameState);
    }

    @Nonnull
    @Override
    protected BlockPattern createStructurePattern() {
        return FactoryBlockPattern.start()
                .aisle("                                               ", "                                               ", "                    FCCCCCF                    ", "                    FCIBICF                    ", "                    FCCCCCF                    ", "                                               ", "                                               ")
                .aisle("                                               ", "                    FCBBBCF                    ", "                   CC#####CC                   ", "                   CC#####CC                   ", "                   CC#####CC                   ", "                    FCBBBCF                    ", "                                               ")
                .aisle("                    FCBBBCF                    ", "                   CC#####CC                   ", "                CCCCC#####CCCCC                ", "                CCCHHHHHHHHHCCC                ", "                CCCCC#####CCCCC                ", "                   CC#####CC                   ", "                    FCBBBCF                    ")
                .aisle("                    FCIBICF                    ", "                CCCCC#####CCCCC                ", "              CCCCCHHHHHHHHHCCCCC              ", "              CCHHHHHHHHHHHHHHHCC              ", "              CCCCCHHHHHHHHHCCCCC              ", "                CCCCC#####CCCCC                ", "                    FCIBICF                    ")
                .aisle("                    FCBBBCF                    ", "              CCCCCCC#####CCCCCCC              ", "            CCCCHHHCC#####CCHHHCCCC            ", "            CCHHHHHHHHHHHHHHHHHHHCC            ", "            CCCCHHHCC#####CCHHHCCCC            ", "              CCCCCCC#####CCCCCCC              ", "                    FCBBBCF                    ")
                .aisle("                                               ", "            CCCCCCC FCBBBCF CCCCCCC            ", "           CCCHHCCCCC#####CCCCCHHCCC           ", "           CHHHHHHHCC#####CCHHHHHHHC           ", "           CCCHHCCCCC#####CCCCCHHCCC           ", "            CCCCCCC FCBBBCF CCCCCCC            ", "                                               ")
                .aisle("                                               ", "           CCCCC               CCCCC           ", "          ECHHCCCCC FCCCCCF CCCCCHHCE          ", "          CHHHHHCCC FCIBICF CCCHHHHHC          ", "          ECHHCCCCC FCCCCCF CCCCCHHCE          ", "           CCCCC               CCCCC           ", "                                               ")
                .aisle("                                               ", "          CCCC                   CCCC          ", "         CCHCCCC               CCCCHCC         ", "         CHHHHCC               CCHHHHC         ", "         CCHCCCC               CCCCHCC         ", "          CCCC                   CCCC          ", "                                               ")
                .aisle("                                               ", "         CCC                       CCC         ", "        CCHCCC                   CCCHCC        ", "        CHHHCC                   CCHHHC        ", "        CCHCCC                   CCCHCC        ", "         CCC                       CCC         ", "                                               ")
                .aisle("                                               ", "        CCC                         CCC        ", "       CCHCE                       ECHCC       ", "       CHHHC                       CHHHC       ", "       CCHCE                       ECHCC       ", "        CCC                         CCC        ", "                                               ")
                .aisle("                                               ", "       CCC                           CCC       ", "      ECHCC                         CCHCE      ", "      CHHHC                         CHHHC      ", "      ECHCC                         CCHCE      ", "       CCC                           CCC       ", "                                               ")
                .aisle("                                               ", "      CCC                             CCC      ", "     CCHCE                           ECHCC     ", "     CHHHC                           CHHHC     ", "     CCHCE                           ECHCC     ", "      CCC                             CCC      ", "                                               ")
                .aisle("                                               ", "     CCC                               CCC     ", "    CCHCC                             CCHCC    ", "    CHHHC                             CHHHC    ", "    CCHCC                             CCHCC    ", "     CCC                               CCC     ", "                                               ")
                .aisle("                                               ", "     CCC                               CCC     ", "    CCHCC                             CCHCC    ", "    CHHHC                             CHHHC    ", "    CCHCC                             CCHCC    ", "     CCC                               CCC     ", "                                               ")
                .aisle("                                               ", "    CCC                                 CCC    ", "   CCHCC                               CCHCC   ", "   CHHHC                               CHHHC   ", "   CCHCC                               CCHCC   ", "    CCC                                 CCC    ", "                                               ")
                .aisle("                                               ", "    CCC                                 CCC    ", "   CCHCC                               CCHCC   ", "   CHHHC                               CHHHC   ", "   CCHCC                               CCHCC   ", "    CCC                                 CCC    ", "                                               ")
                .aisle("                                               ", "   CCC                                   CCC   ", "  CCHCC                                 CCHCC  ", "  CHHHC                                 CHHHC  ", "  CCHCC                                 CCHCC  ", "   CCC                                   CCC   ", "                                               ")
                .aisle("                                               ", "   CCC                                   CCC   ", "  CCHCC                                 CCHCC  ", "  CHHHC                                 CHHHC  ", "  CCHCC                                 CCHCC  ", "   CCC                                   CCC   ", "                                               ")
                .aisle("                                               ", "   CCC                                   CCC   ", "  CCHCC                                 CCHCC  ", "  CHHHC                                 CHHHC  ", "  CCHCC                                 CCHCC  ", "   CCC                                   CCC   ", "                                               ")
                .aisle("                                               ", "  CCC                                     CCC  ", " CCHCC                                   CCHCC ", " CHHHC                                   CHHHC ", " CCHCC                                   CCHCC ", "  CCC                                     CCC  ", "                                               ")
                .aisle("  FFF                                     FFF  ", " FCCCF                                   FCCCF ", "FCCHCCF                                 FCCHCCF", "FCHHHCF                                 FCHHHCF", "FCCHCCF                                 FCCHCCF", " FCCCF                                   FCCCF ", "  FFF                                     FFF  ")
                .aisle("  CCC                                     CCC  ", " C###C                                   C###C ", "C##H##C                                 C##H##C", "C#HHH#C                                 C#HHH#C", "C##H##C                                 C##H##C", " C###C                                   C###C ", "  CCC                                     CCC  ")
                .aisle("  CIC                                     CIC  ", " B###B                                   B###B ", "C##H##C                                 C##H##C", "I#HHH#I                                 I#HHH#I", "C##H##C                                 C##H##C", " B###B                                   B###B ", "  CIC                                     CIC  ")
                .aisle("  CBC                                     CBC  ", " B###B                                   B###B ", "C##H##C                                 C##H##C", "B#HHH#B                                 B#HHH#B", "C##H##C                                 C##H##C", " B###B                                   B###B ", "  CBC                                     CBC  ")
                .aisle("  CIC                                     CIC  ", " B###B                                   B###B ", "C##H##C                                 C##H##C", "I#HHH#I                                 I#HHH#I", "C##H##C                                 C##H##C", " B###B                                   B###B ", "  CIC                                     CIC  ")
                .aisle("  CCC                                     CCC  ", " C###C                                   C###C ", "C##H##C                                 C##H##C", "C#HHH#C                                 C#HHH#C", "C##H##C                                 C##H##C", " C###C                                   C###C ", "  CCC                                     CCC  ")
                .aisle("  FFF                                     FFF  ", " FCCCF                                   FCCCF ", "FCCHCCF                                 FCCHCCF", "FCHHHCF                                 FCHHHCF", "FCCHCCF                                 FCCHCCF", " FCCCF                                   FCCCF ", "  FFF                                     FFF  ")
                .aisle("                                               ", "  CCC                                     CCC  ", " CCHCC                                   CCHCC ", " CHHHC                                   CHHHC ", " CCHCC                                   CCHCC ", "  CCC                                     CCC  ", "                                               ")
                .aisle("                                               ", "   CCC                                   CCC   ", "  CCHCC                                 CCHCC  ", "  CHHHC                                 CHHHC  ", "  CCHCC                                 CCHCC  ", "   CCC                                   CCC   ", "                                               ")
                .aisle("                                               ", "   CCC                                   CCC   ", "  CCHCC                                 CCHCC  ", "  CHHHC                                 CHHHC  ", "  CCHCC                                 CCHCC  ", "   CCC                                   CCC   ", "                                               ")
                .aisle("                                               ", "   CCC                                   CCC   ", "  CCHCC                                 CCHCC  ", "  CHHHC                                 CHHHC  ", "  CCHCC                                 CCHCC  ", "   CCC                                   CCC   ", "                                               ")
                .aisle("                                               ", "    CCC                                 CCC    ", "   CCHCC                               CCHCC   ", "   CHHHC                               CHHHC   ", "   CCHCC                               CCHCC   ", "    CCC                                 CCC    ", "                                               ")
                .aisle("                                               ", "    CCC                                 CCC    ", "   CCHCC                               CCHCC   ", "   CHHHC                               CHHHC   ", "   CCHCC                               CCHCC   ", "    CCC                                 CCC    ", "                                               ")
                .aisle("                                               ", "     CCC                               CCC     ", "    CCHCC                             CCHCC    ", "    CHHHC                             CHHHC    ", "    CCHCC                             CCHCC    ", "     CCC                               CCC     ", "                                               ")
                .aisle("                                               ", "     CCC                               CCC     ", "    CCHCC                             CCHCC    ", "    CHHHC                             CHHHC    ", "    CCHCC                             CCHCC    ", "     CCC                               CCC     ", "                                               ")
                .aisle("                                               ", "      CCC                             CCC      ", "     CCHCE                           ECHCC     ", "     CHHHC                           CHHHC     ", "     CCHCE                           ECHCC     ", "      CCC                             CCC      ", "                                               ")
                .aisle("                                               ", "       CCC                           CCC       ", "      ECHCC                         CCHCE      ", "      CHHHC                         CHHHC      ", "      ECHCC                         CCHCE      ", "       CCC                           CCC       ", "                                               ")
                .aisle("                                               ", "        CCC                         CCC        ", "       CCHCE                       ECHCC       ", "       CHHHC                       CHHHC       ", "       CCHCE                       ECHCC       ", "        CCC                         CCC        ", "                                               ")
                .aisle("                                               ", "         CCC                       CCC         ", "        CCHCCC                   CCCHCC        ", "        CHHHCC                   CCHHHC        ", "        CCHCCC                   CCCHCC        ", "         CCC                       CCC         ", "                                               ")
                .aisle("                                               ", "          CCCC                   CCCC          ", "         CCHCCCC               CCCCHCC         ", "         CHHHHCC               CCHHHHC         ", "         CCHCCCC               CCCCHCC         ", "          CCCC                   CCCC          ", "                                               ")
                .aisle("                                               ", "           CCCCC               CCCCC           ", "          ECHHCCCCC FCCCCCF CCCCCHHCE          ", "          CHHHHHCCC FCIBICF CCCHHHHHC          ", "          ECHHCCCCC FCCCCCF CCCCCHHCE          ", "           CCCCC               CCCCC           ", "                                               ")
                .aisle("                                               ", "            CCCCCCC FCBBBCF CCCCCCC            ", "           CCCHHCCCCC#####CCCCCHHCCC           ", "           CHHHHHHHCC#####CCHHHHHHHC           ", "           CCCHHCCCCC#####CCCCCHHCCC           ", "            CCCCCCC FCBBBCF CCCCCCC            ", "                                               ")
                .aisle("                    FCBBBCF                    ", "              CCCCCCC#####CCCCCCC              ", "            CCCCHHHCC#####CCHHHCCCC            ", "            CCHHHHHHHHHHHHHHHHHHHCC            ", "            CCCCHHHCC#####CCHHHCCCC            ", "              CCCCCCC#####CCCCCCC              ", "                    FCBBBCF                    ")
                .aisle("                    FCIBICF                    ", "                CCCCC#####CCCCC                ", "              CCCCCHHHHHHHHHCCCCC              ", "              CCHHHHHHHHHHHHHHHCC              ", "              CCCCCHHHHHHHHHCCCCC              ", "                CCCCC#####CCCCC                ", "                    FCIBICF                    ")
                .aisle("                    FCBBBCF                    ", "                   CC#####CC                   ", "                CCCCC#####CCCCC                ", "                CCCHHHHHHHHHCCC                ", "                CCCCC#####CCCCC                ", "                   CC#####CC                   ", "                    FCBBBCF                    ")
                .aisle("                                               ", "                    FCBBBCF                    ", "                   CC#####CC                   ", "                   CC#####CC                   ", "                   CC#####CC                   ", "                    FCBBBCF                    ", "                                               ")
                .aisle("                                               ", "                                               ", "                    FCCCCCF                    ", "                    FCISICF                    ", "                    FCCCCCF                    ", "                                               ", "                                               ")
                .where('S', this.selfPredicate())
                .where('B', states(getGlassState()))
                .where('C', states(getCasingState()))
                .where('I', states(getCasingState())
                        .or(abilities(MultiblockAbility.IMPORT_FLUIDS)
                                .setMinGlobalLimited(2)
                                .setPreviewCount(16))
                        .or(abilities(MultiblockAbility.EXPORT_FLUIDS)
                                .setMinGlobalLimited(2)
                                .setPreviewCount(16)))
                .where('F', states(getFrameState()))
                .where('H', states(getCoilState()))
                .where('E', states(getCasingState())
                        .or(metaTileEntities(Arrays.stream(MetaTileEntities.ENERGY_INPUT_HATCH)
                                .filter(mte -> mte != null && tier <= mte.getTier() && mte.getTier() <= GTValues.UEV)
                                .toArray(MetaTileEntity[]::new))
                                .setMinGlobalLimited(1)
                                .setPreviewCount(32)))
                .where('#', air())
                .where(' ', any())
                .build();
    }

    private IBlockState getCasingState() {
        return casingState;
    }

    private IBlockState getCoilState() {
        return coilState;
    }

    private IBlockState getFrameState() {
        return frameState;
    }

    private static IBlockState getGlassState() {
        return MetaBlocks.TRANSPARENT_CASING.getState(BlockGlassCasing.CasingType.FUSION_GLASS);
    }

    @SideOnly(Side.CLIENT)
    @Override
    public ICubeRenderer getBaseTexture(IMultiblockPart sourcePart) {
        if (this.recipeMapWorkable.isActive()) {
            return Textures.ACTIVE_FUSION_TEXTURE;
        } else {
            return Textures.FUSION_TEXTURE;
        }
    }

    @SideOnly(Side.CLIENT)
    @Nonnull
    @Override
    protected ICubeRenderer getFrontOverlay() {
        return Textures.FUSION_REACTOR_OVERLAY;
    }

    @Override
    protected void formStructure(PatternMatchContext context) {
        long energyStored = this.energyContainer.getEnergyStored();
        super.formStructure(context);
        this.initializeAbilities();
        ((EnergyContainerHandler) this.energyContainer).setEnergyStored(energyStored);
    }

    @Override
    protected void initializeAbilities() {
        this.inputInventory = new ItemHandlerList(getAbilities(MultiblockAbility.IMPORT_ITEMS));
        this.inputFluidInventory = new FluidTankList(true, getAbilities(MultiblockAbility.IMPORT_FLUIDS));
        this.outputInventory = new ItemHandlerList(getAbilities(MultiblockAbility.EXPORT_ITEMS));
        this.outputFluidInventory = new FluidTankList(true, getAbilities(MultiblockAbility.EXPORT_FLUIDS));
        List<IEnergyContainer> energyInputs = getAbilities(MultiblockAbility.INPUT_ENERGY);
        this.inputEnergyContainers = new EnergyContainerList(energyInputs);
        long euCapacity = calculateEnergyStorageFactor(energyInputs.size());
        this.energyContainer = new EnergyContainerHandler(this, euCapacity, GTValues.V[tier], 0, 0, 0) {
            @Nonnull
            @Override
            public String getName() {
                return GregtechDataCodes.FUSION_REACTOR_ENERGY_CONTAINER_TRAIT;
            }
        };
    }

    private long calculateEnergyStorageFactor(int energyInputAmount) {
        return energyInputAmount * (long) Math.pow(2, tier - 6) * 10000000L;
    }

    @Override
    protected void updateFormedValid() {
        if (this.inputEnergyContainers.getEnergyStored() > 0) {
            long energyAdded = this.energyContainer.addEnergy(this.inputEnergyContainers.getEnergyStored());
            if (energyAdded > 0) this.inputEnergyContainers.removeEnergy(energyAdded);
        }
        super.updateFormedValid();
        if (recipeMapWorkable.isWorking() && color == null) {
            if (recipeMapWorkable.getPreviousRecipe() != null && recipeMapWorkable.getPreviousRecipe().getFluidOutputs().size() > 0) {
                int newColor = 0xFF000000 | recipeMapWorkable.getPreviousRecipe().getFluidOutputs().get(0).getFluid().getColor();
                if (!Objects.equals(color, newColor)) {
                    color = newColor;
                    writeCustomData(GregtechDataCodes.UPDATE_COLOR, this::writeColor);
                }
            }
        } else if (!recipeMapWorkable.isWorking() && isStructureFormed() && color != null) {
            color = null;
            writeCustomData(GregtechDataCodes.UPDATE_COLOR, this::writeColor);
        }
    }

    @Override
    public void writeInitialSyncData(PacketBuffer buf) {
        super.writeInitialSyncData(buf);
        writeColor(buf);
    }

    @Override
    public void receiveInitialSyncData(PacketBuffer buf) {
        super.receiveInitialSyncData(buf);
        readColor(buf);
    }

    @Override
    public void receiveCustomData(int dataId, PacketBuffer buf) {
        super.receiveCustomData(dataId, buf);
        if (dataId == GregtechDataCodes.UPDATE_COLOR) {
            readColor(buf);
        }
    }

    private void readColor(PacketBuffer buf) {
        color = buf.readBoolean() ? buf.readVarInt() : null;
    }

    private void writeColor(PacketBuffer buf) {
        buf.writeBoolean(color != null);
        if (color != null) {
            buf.writeVarInt(color);
        }
    }

    @Override
    protected void addDisplayText(List<ITextComponent> textList) {
        super.addDisplayText(textList);
        if (isStructureFormed()) {
            textList.add(new TextComponentTranslation("gregtech.multiblock.fusion_reactor.energy", this.energyContainer.getEnergyStored(), this.energyContainer.getEnergyCapacity()));
            textList.add(new TextComponentTranslation("gregtech.multiblock.fusion_reactor.heat", heat));
        }
    }

    @Override
    public void addInformation(ItemStack stack,
                               @Nullable World player,
                               @Nonnull List<String> tooltip,
                               boolean advanced) {
        super.addInformation(stack, player, tooltip, advanced);

        switch (this.tier) {
            case (LuV) -> tooltip.add(I18n.format("gtlitecore.machine.compressed_fusion_reactor.tooltip.luv"));
            case (ZPM) -> tooltip.add(I18n.format("gtlitecore.machine.compressed_fusion_reactor.tooltip.zpm"));
            case (UV) -> tooltip.add(I18n.format("gtlitecore.machine.compressed_fusion_reactor.tooltip.uv"));
            case (UHV) -> tooltip.add(I18n.format("gtlitecore.machine.compressed_fusion_reactor.tooltip.uhv"));
            case (UEV) -> tooltip.add(I18n.format("gtlitecore.machine.compressed_fusion_reactor.tooltip.uev"));
        }

        tooltip.add(I18n.format("gregtech.machine.fusion_reactor.capacity", calculateEnergyStorageFactor(16) / 1000000L));
        tooltip.add(I18n.format("gregtech.machine.fusion_reactor.overclocking"));

        tooltip.add(I18n.format("gtlitecore.machine.compressed_fusion_reactor.tooltip.1"));

        switch (this.tier) {
            case (LuV) -> tooltip.add(I18n.format("gtlitecore.machine.compressed_fusion_reactor.tooltip.parallel.luv"));
            case (ZPM) -> tooltip.add(I18n.format("gtlitecore.machine.compressed_fusion_reactor.tooltip.parallel.zpm"));
            case (UV) -> tooltip.add(I18n.format("gtlitecore.machine.compressed_fusion_reactor.tooltip.parallel.uv"));
            case (UHV) -> tooltip.add(I18n.format("gtlitecore.machine.compressed_fusion_reactor.tooltip.parallel.uhv"));
            case (UEV) -> tooltip.add(I18n.format("gtlitecore.machine.compressed_fusion_reactor.tooltip.parallel.uev"));
        }
    }

    @Override
    public boolean hasMaintenanceMechanics() {
        return false;
    }

    public long getHeat() {
        return heat;
    }

    private class CompressedFusionReactorRecipeLogic extends MultiblockRecipeLogic {

        public CompressedFusionReactorRecipeLogic(MetaTileEntityCompressedFusionReactor tileEntity) {
            super(tileEntity);
        }

        @Override
        protected double getOverclockingDurationDivisor() {
            return 2.0D;
        }

        @Override
        protected double getOverclockingVoltageMultiplier() {
            return 2.0D;
        }

        @Override
        public long getMaxVoltage() {
            return Math.min(GTValues.V[tier], super.getMaxVoltage());
        }

        @Override
        public void updateWorkable() {
            super.updateWorkable();
            // Drain heat when the reactor is not active, is paused via soft mallet, or does not have enough energy and has fully wiped recipe progress
            // Don't drain heat when there is not enough energy and there is still some recipe progress, as that makes it doubly hard to complete the recipe
            // (Will have to recover heat and recipe progress)
            if (heat > 0) {
                if (!isActive || !workingEnabled || (hasNotEnoughEnergy && progressTime == 0)) {
                    heat = heat <= 10000 ? 0 : (heat - 10000);
                }
            }
        }

        @Override
        public boolean checkRecipe(@Nonnull Recipe recipe) {
            if (!super.checkRecipe(recipe))
                return false;

            // if the reactor is not able to hold enough energy for it, do not run the recipe
            if (recipe.getProperty(FusionEUToStartProperty.getInstance(), 0L) > energyContainer.getEnergyCapacity())
                return false;

            long heatDiff = recipe.getProperty(FusionEUToStartProperty.getInstance(), 0L) - heat;
            // if the stored heat is >= required energy, recipe is okay to run
            if (heatDiff <= 0)
                return true;

            // if the remaining energy needed is more than stored, do not run
            if (energyContainer.getEnergyStored() < heatDiff)
                return false;

            // remove the energy needed
            energyContainer.removeEnergy(heatDiff);
            // increase the stored heat
            heat += heatDiff;
            return true;
        }

        @Nonnull
        @Override
        public NBTTagCompound serializeNBT() {
            NBTTagCompound tag = super.serializeNBT();
            tag.setLong("Heat", heat);
            return tag;
        }

        @Override
        public void deserializeNBT(@Nonnull NBTTagCompound compound) {
            super.deserializeNBT(compound);
            heat = compound.getLong("Heat");
        }

        @Override
        public int getParallelLimit() {
            if (tier == LuV) {
                return 64;
            } else if (tier == ZPM) {
                return 128;
            } else if (tier == UV) {
                return 256;
            } else if (tier == UHV) {
                return 512;
            } else {
                return 1024;
            }
        }
    }
}